22-01-27 18:37:33-08  |Portal| Loading c:\muddev\evennia\evennia\server\portal\portal.py...
22-01-27 18:37:34-08  |Portal| Loaded.
22-01-27 18:37:34-08  |Portal| twistd 21.7.0 (c:\muddev\evenv\scripts\python.exe 3.7.0) starting up.
22-01-27 18:37:34-08  |Portal| reactor class: twisted.internet.selectreactor.SelectReactor.
22-01-27 18:37:34-08  |Portal| AMP starting on 4006
22-01-27 18:37:34-08  |Portal| Telnet starting on 4000
22-01-27 18:37:34-08  |Portal| Websocket starting on 4002
22-01-27 18:37:34-08  |Portal| Webserver-proxy starting on 4001
22-01-27 18:37:34-08  |Portal| Portal starting server ... 
22-01-27 18:40:05-08  |Portal| (TCP Port 4001 Closed)
22-01-27 18:40:05-08  |Portal| (TCP Port 4000 Closed)
22-01-27 18:40:05-08  |Portal| (TCP Port 4006 Closed)
22-01-27 18:40:05-08  |Portal| (TCP Port 4002 Closed)
22-01-27 18:40:05-08  |Portal| Main loop terminated.
22-01-27 18:40:05-08  |Portal| Server Shut Down.
22-01-27 18:40:05-08  |Portal| Server Shut Down.
22-01-27 18:40:32-08  |Portal| Loading c:\muddev\evennia\evennia\server\portal\portal.py...
22-01-27 18:40:33-08  |Portal| Loaded.
22-01-27 18:40:33-08  |Portal| twistd 21.7.0 (c:\muddev\evenv\scripts\python.exe 3.7.0) starting up.
22-01-27 18:40:33-08  |Portal| reactor class: twisted.internet.selectreactor.SelectReactor.
22-01-27 18:40:33-08  |Portal| AMP starting on 4006
22-01-27 18:40:33-08  |Portal| Telnet starting on 4000
22-01-27 18:40:33-08  |Portal| Websocket starting on 4002
22-01-27 18:40:33-08  |Portal| Webserver-proxy starting on 4001
22-01-27 18:40:33-08  |Portal| Portal starting server ... 
22-01-27 18:42:34-08  |Portal| Timing out client: IPv4Address(type='TCP', host='127.0.0.1', port=52442)
22-01-27 18:42:34-08  |Portal| Timing out client: IPv4Address(type='TCP', host='127.0.0.1', port=52444)
22-01-27 18:42:34-08  |Portal| Timing out client: IPv4Address(type='TCP', host='127.0.0.1', port=52446)
22-01-27 18:42:34-08  |Portal| Timing out client: IPv4Address(type='TCP', host='127.0.0.1', port=52449)
22-01-27 18:42:34-08  |Portal| Timing out client: IPv4Address(type='TCP', host='127.0.0.1', port=52451)
22-01-27 18:42:35-08  |Portal| Timing out client: IPv4Address(type='TCP', host='127.0.0.1', port=52448)
22-01-27 18:52:45-08  |Portal| Unhandled Error
	Traceback (most recent call last):
	  File "C:\muddev\evenv\Lib\site-packages\twisted\python\log.py", line 101, in callWithLogger
	    return callWithContext({"system": lp}, func, *args, **kw)
	  File "C:\muddev\evenv\Lib\site-packages\twisted\python\log.py", line 85, in callWithContext
	    return context.call({ILogContext: newCtx}, func, *args, **kw)
	  File "C:\muddev\evenv\Lib\site-packages\twisted\python\context.py", line 118, in callWithContext
	    return self.currentContext().callWithContext(ctx, func, *args, **kw)
	  File "C:\muddev\evenv\Lib\site-packages\twisted\python\context.py", line 83, in callWithContext
	    return func(*args, **kw)
	--- <exception caught here> ---
	  File "C:\muddev\evenv\Lib\site-packages\twisted\internet\selectreactor.py", line 149, in _doReadOrWrite
	    why = getattr(selectable, method)()
	  File "C:\muddev\evenv\Lib\site-packages\twisted\internet\tcp.py", line 247, in doRead
	    return self._dataReceived(data)
	  File "C:\muddev\evenv\Lib\site-packages\twisted\internet\tcp.py", line 252, in _dataReceived
	    rval = self.protocol.dataReceived(data)
	  File "C:\muddev\evenv\Lib\site-packages\twisted\protocols\basic.py", line 554, in dataReceived
	    why = self.rawDataReceived(data)
	  File "C:\muddev\evenv\Lib\site-packages\twisted\web\http.py", line 706, in rawDataReceived
	    self.handleResponseEnd()
	  File "C:\muddev\evenv\Lib\site-packages\twisted\web\proxy.py", line 82, in handleResponseEnd
	    self.father.finish()
	  File "C:\muddev\evenv\Lib\site-packages\twisted\web\server.py", line 279, in finish
	    return http.Request.finish(self)
	  File "C:\muddev\evenv\Lib\site-packages\twisted\web\http.py", line 1132, in finish
	    "Request.finish called on a request after its connection was lost; "
	builtins.RuntimeError: Request.finish called on a request after its connection was lost; use Request.notifyFinish to keep track of this.
	
22-01-27 18:52:45-08  |Portal| Unhandled Error
	Traceback (most recent call last):
	  File "C:\muddev\evenv\Lib\site-packages\twisted\python\log.py", line 101, in callWithLogger
	    return callWithContext({"system": lp}, func, *args, **kw)
	  File "C:\muddev\evenv\Lib\site-packages\twisted\python\log.py", line 85, in callWithContext
	    return context.call({ILogContext: newCtx}, func, *args, **kw)
	  File "C:\muddev\evenv\Lib\site-packages\twisted\python\context.py", line 118, in callWithContext
	    return self.currentContext().callWithContext(ctx, func, *args, **kw)
	  File "C:\muddev\evenv\Lib\site-packages\twisted\python\context.py", line 83, in callWithContext
	    return func(*args, **kw)
	--- <exception caught here> ---
	  File "C:\muddev\evenv\Lib\site-packages\twisted\internet\selectreactor.py", line 149, in _doReadOrWrite
	    why = getattr(selectable, method)()
	  File "C:\muddev\evenv\Lib\site-packages\twisted\internet\tcp.py", line 247, in doRead
	    return self._dataReceived(data)
	  File "C:\muddev\evenv\Lib\site-packages\twisted\internet\tcp.py", line 252, in _dataReceived
	    rval = self.protocol.dataReceived(data)
	  File "C:\muddev\evenv\Lib\site-packages\twisted\protocols\basic.py", line 554, in dataReceived
	    why = self.rawDataReceived(data)
	  File "C:\muddev\evenv\Lib\site-packages\twisted\web\http.py", line 706, in rawDataReceived
	    self.handleResponseEnd()
	  File "C:\muddev\evenv\Lib\site-packages\twisted\web\proxy.py", line 82, in handleResponseEnd
	    self.father.finish()
	  File "C:\muddev\evenv\Lib\site-packages\twisted\web\server.py", line 279, in finish
	    return http.Request.finish(self)
	  File "C:\muddev\evenv\Lib\site-packages\twisted\web\http.py", line 1132, in finish
	    "Request.finish called on a request after its connection was lost; "
	builtins.RuntimeError: Request.finish called on a request after its connection was lost; use Request.notifyFinish to keep track of this.
	
22-01-27 18:52:45-08  |Portal| Unhandled Error
	Traceback (most recent call last):
	  File "C:\muddev\evenv\Lib\site-packages\twisted\python\log.py", line 101, in callWithLogger
	    return callWithContext({"system": lp}, func, *args, **kw)
	  File "C:\muddev\evenv\Lib\site-packages\twisted\python\log.py", line 85, in callWithContext
	    return context.call({ILogContext: newCtx}, func, *args, **kw)
	  File "C:\muddev\evenv\Lib\site-packages\twisted\python\context.py", line 118, in callWithContext
	    return self.currentContext().callWithContext(ctx, func, *args, **kw)
	  File "C:\muddev\evenv\Lib\site-packages\twisted\python\context.py", line 83, in callWithContext
	    return func(*args, **kw)
	--- <exception caught here> ---
	  File "C:\muddev\evenv\Lib\site-packages\twisted\internet\selectreactor.py", line 149, in _doReadOrWrite
	    why = getattr(selectable, method)()
	  File "C:\muddev\evenv\Lib\site-packages\twisted\internet\tcp.py", line 247, in doRead
	    return self._dataReceived(data)
	  File "C:\muddev\evenv\Lib\site-packages\twisted\internet\tcp.py", line 252, in _dataReceived
	    rval = self.protocol.dataReceived(data)
	  File "C:\muddev\evenv\Lib\site-packages\twisted\protocols\basic.py", line 554, in dataReceived
	    why = self.rawDataReceived(data)
	  File "C:\muddev\evenv\Lib\site-packages\twisted\web\http.py", line 706, in rawDataReceived
	    self.handleResponseEnd()
	  File "C:\muddev\evenv\Lib\site-packages\twisted\web\proxy.py", line 82, in handleResponseEnd
	    self.father.finish()
	  File "C:\muddev\evenv\Lib\site-packages\twisted\web\server.py", line 279, in finish
	    return http.Request.finish(self)
	  File "C:\muddev\evenv\Lib\site-packages\twisted\web\http.py", line 1132, in finish
	    "Request.finish called on a request after its connection was lost; "
	builtins.RuntimeError: Request.finish called on a request after its connection was lost; use Request.notifyFinish to keep track of this.
	
22-01-27 18:52:45-08  |Portal| Unhandled Error
	Traceback (most recent call last):
	  File "C:\muddev\evenv\Lib\site-packages\twisted\python\log.py", line 101, in callWithLogger
	    return callWithContext({"system": lp}, func, *args, **kw)
	  File "C:\muddev\evenv\Lib\site-packages\twisted\python\log.py", line 85, in callWithContext
	    return context.call({ILogContext: newCtx}, func, *args, **kw)
	  File "C:\muddev\evenv\Lib\site-packages\twisted\python\context.py", line 118, in callWithContext
	    return self.currentContext().callWithContext(ctx, func, *args, **kw)
	  File "C:\muddev\evenv\Lib\site-packages\twisted\python\context.py", line 83, in callWithContext
	    return func(*args, **kw)
	--- <exception caught here> ---
	  File "C:\muddev\evenv\Lib\site-packages\twisted\internet\selectreactor.py", line 149, in _doReadOrWrite
	    why = getattr(selectable, method)()
	  File "C:\muddev\evenv\Lib\site-packages\twisted\internet\tcp.py", line 247, in doRead
	    return self._dataReceived(data)
	  File "C:\muddev\evenv\Lib\site-packages\twisted\internet\tcp.py", line 252, in _dataReceived
	    rval = self.protocol.dataReceived(data)
	  File "C:\muddev\evenv\Lib\site-packages\twisted\protocols\basic.py", line 554, in dataReceived
	    why = self.rawDataReceived(data)
	  File "C:\muddev\evenv\Lib\site-packages\twisted\web\http.py", line 706, in rawDataReceived
	    self.handleResponseEnd()
	  File "C:\muddev\evenv\Lib\site-packages\twisted\web\proxy.py", line 82, in handleResponseEnd
	    self.father.finish()
	  File "C:\muddev\evenv\Lib\site-packages\twisted\web\server.py", line 279, in finish
	    return http.Request.finish(self)
	  File "C:\muddev\evenv\Lib\site-packages\twisted\web\http.py", line 1132, in finish
	    "Request.finish called on a request after its connection was lost; "
	builtins.RuntimeError: Request.finish called on a request after its connection was lost; use Request.notifyFinish to keep track of this.
	
22-01-27 18:52:45-08  |Portal| Unhandled Error
	Traceback (most recent call last):
	  File "C:\muddev\evenv\Lib\site-packages\twisted\python\log.py", line 101, in callWithLogger
	    return callWithContext({"system": lp}, func, *args, **kw)
	  File "C:\muddev\evenv\Lib\site-packages\twisted\python\log.py", line 85, in callWithContext
	    return context.call({ILogContext: newCtx}, func, *args, **kw)
	  File "C:\muddev\evenv\Lib\site-packages\twisted\python\context.py", line 118, in callWithContext
	    return self.currentContext().callWithContext(ctx, func, *args, **kw)
	  File "C:\muddev\evenv\Lib\site-packages\twisted\python\context.py", line 83, in callWithContext
	    return func(*args, **kw)
	--- <exception caught here> ---
	  File "C:\muddev\evenv\Lib\site-packages\twisted\internet\selectreactor.py", line 149, in _doReadOrWrite
	    why = getattr(selectable, method)()
	  File "C:\muddev\evenv\Lib\site-packages\twisted\internet\tcp.py", line 247, in doRead
	    return self._dataReceived(data)
	  File "C:\muddev\evenv\Lib\site-packages\twisted\internet\tcp.py", line 252, in _dataReceived
	    rval = self.protocol.dataReceived(data)
	  File "C:\muddev\evenv\Lib\site-packages\twisted\protocols\basic.py", line 554, in dataReceived
	    why = self.rawDataReceived(data)
	  File "C:\muddev\evenv\Lib\site-packages\twisted\web\http.py", line 706, in rawDataReceived
	    self.handleResponseEnd()
	  File "C:\muddev\evenv\Lib\site-packages\twisted\web\proxy.py", line 82, in handleResponseEnd
	    self.father.finish()
	  File "C:\muddev\evenv\Lib\site-packages\twisted\web\server.py", line 279, in finish
	    return http.Request.finish(self)
	  File "C:\muddev\evenv\Lib\site-packages\twisted\web\http.py", line 1132, in finish
	    "Request.finish called on a request after its connection was lost; "
	builtins.RuntimeError: Request.finish called on a request after its connection was lost; use Request.notifyFinish to keep track of this.
	
22-01-27 18:52:45-08  |Portal| Unhandled Error
	Traceback (most recent call last):
	  File "C:\muddev\evenv\Lib\site-packages\twisted\python\log.py", line 101, in callWithLogger
	    return callWithContext({"system": lp}, func, *args, **kw)
	  File "C:\muddev\evenv\Lib\site-packages\twisted\python\log.py", line 85, in callWithContext
	    return context.call({ILogContext: newCtx}, func, *args, **kw)
	  File "C:\muddev\evenv\Lib\site-packages\twisted\python\context.py", line 118, in callWithContext
	    return self.currentContext().callWithContext(ctx, func, *args, **kw)
	  File "C:\muddev\evenv\Lib\site-packages\twisted\python\context.py", line 83, in callWithContext
	    return func(*args, **kw)
	--- <exception caught here> ---
	  File "C:\muddev\evenv\Lib\site-packages\twisted\internet\selectreactor.py", line 149, in _doReadOrWrite
	    why = getattr(selectable, method)()
	  File "C:\muddev\evenv\Lib\site-packages\twisted\internet\tcp.py", line 247, in doRead
	    return self._dataReceived(data)
	  File "C:\muddev\evenv\Lib\site-packages\twisted\internet\tcp.py", line 252, in _dataReceived
	    rval = self.protocol.dataReceived(data)
	  File "C:\muddev\evenv\Lib\site-packages\twisted\protocols\basic.py", line 554, in dataReceived
	    why = self.rawDataReceived(data)
	  File "C:\muddev\evenv\Lib\site-packages\twisted\web\http.py", line 706, in rawDataReceived
	    self.handleResponseEnd()
	  File "C:\muddev\evenv\Lib\site-packages\twisted\web\proxy.py", line 82, in handleResponseEnd
	    self.father.finish()
	  File "C:\muddev\evenv\Lib\site-packages\twisted\web\server.py", line 279, in finish
	    return http.Request.finish(self)
	  File "C:\muddev\evenv\Lib\site-packages\twisted\web\http.py", line 1132, in finish
	    "Request.finish called on a request after its connection was lost; "
	builtins.RuntimeError: Request.finish called on a request after its connection was lost; use Request.notifyFinish to keep track of this.
	
22-01-27 18:52:45-08  |Portal| Unhandled Error
	Traceback (most recent call last):
	  File "C:\muddev\evenv\Lib\site-packages\twisted\python\log.py", line 101, in callWithLogger
	    return callWithContext({"system": lp}, func, *args, **kw)
	  File "C:\muddev\evenv\Lib\site-packages\twisted\python\log.py", line 85, in callWithContext
	    return context.call({ILogContext: newCtx}, func, *args, **kw)
	  File "C:\muddev\evenv\Lib\site-packages\twisted\python\context.py", line 118, in callWithContext
	    return self.currentContext().callWithContext(ctx, func, *args, **kw)
	  File "C:\muddev\evenv\Lib\site-packages\twisted\python\context.py", line 83, in callWithContext
	    return func(*args, **kw)
	--- <exception caught here> ---
	  File "C:\muddev\evenv\Lib\site-packages\twisted\internet\selectreactor.py", line 149, in _doReadOrWrite
	    why = getattr(selectable, method)()
	  File "C:\muddev\evenv\Lib\site-packages\twisted\internet\tcp.py", line 247, in doRead
	    return self._dataReceived(data)
	  File "C:\muddev\evenv\Lib\site-packages\twisted\internet\tcp.py", line 252, in _dataReceived
	    rval = self.protocol.dataReceived(data)
	  File "C:\muddev\evenv\Lib\site-packages\twisted\protocols\basic.py", line 554, in dataReceived
	    why = self.rawDataReceived(data)
	  File "C:\muddev\evenv\Lib\site-packages\twisted\web\http.py", line 706, in rawDataReceived
	    self.handleResponseEnd()
	  File "C:\muddev\evenv\Lib\site-packages\twisted\web\proxy.py", line 82, in handleResponseEnd
	    self.father.finish()
	  File "C:\muddev\evenv\Lib\site-packages\twisted\web\server.py", line 279, in finish
	    return http.Request.finish(self)
	  File "C:\muddev\evenv\Lib\site-packages\twisted\web\http.py", line 1132, in finish
	    "Request.finish called on a request after its connection was lost; "
	builtins.RuntimeError: Request.finish called on a request after its connection was lost; use Request.notifyFinish to keep track of this.
	
22-01-27 18:52:45-08  |Portal| Unhandled Error
	Traceback (most recent call last):
	  File "C:\muddev\evenv\Lib\site-packages\twisted\python\log.py", line 101, in callWithLogger
	    return callWithContext({"system": lp}, func, *args, **kw)
	  File "C:\muddev\evenv\Lib\site-packages\twisted\python\log.py", line 85, in callWithContext
	    return context.call({ILogContext: newCtx}, func, *args, **kw)
	  File "C:\muddev\evenv\Lib\site-packages\twisted\python\context.py", line 118, in callWithContext
	    return self.currentContext().callWithContext(ctx, func, *args, **kw)
	  File "C:\muddev\evenv\Lib\site-packages\twisted\python\context.py", line 83, in callWithContext
	    return func(*args, **kw)
	--- <exception caught here> ---
	  File "C:\muddev\evenv\Lib\site-packages\twisted\internet\selectreactor.py", line 149, in _doReadOrWrite
	    why = getattr(selectable, method)()
	  File "C:\muddev\evenv\Lib\site-packages\twisted\internet\tcp.py", line 247, in doRead
	    return self._dataReceived(data)
	  File "C:\muddev\evenv\Lib\site-packages\twisted\internet\tcp.py", line 252, in _dataReceived
	    rval = self.protocol.dataReceived(data)
	  File "C:\muddev\evenv\Lib\site-packages\twisted\protocols\basic.py", line 554, in dataReceived
	    why = self.rawDataReceived(data)
	  File "C:\muddev\evenv\Lib\site-packages\twisted\web\http.py", line 706, in rawDataReceived
	    self.handleResponseEnd()
	  File "C:\muddev\evenv\Lib\site-packages\twisted\web\proxy.py", line 82, in handleResponseEnd
	    self.father.finish()
	  File "C:\muddev\evenv\Lib\site-packages\twisted\web\server.py", line 279, in finish
	    return http.Request.finish(self)
	  File "C:\muddev\evenv\Lib\site-packages\twisted\web\http.py", line 1132, in finish
	    "Request.finish called on a request after its connection was lost; "
	builtins.RuntimeError: Request.finish called on a request after its connection was lost; use Request.notifyFinish to keep track of this.
	
22-01-27 18:52:45-08  |Portal| Unhandled Error
	Traceback (most recent call last):
	  File "C:\muddev\evenv\Lib\site-packages\twisted\python\log.py", line 101, in callWithLogger
	    return callWithContext({"system": lp}, func, *args, **kw)
	  File "C:\muddev\evenv\Lib\site-packages\twisted\python\log.py", line 85, in callWithContext
	    return context.call({ILogContext: newCtx}, func, *args, **kw)
	  File "C:\muddev\evenv\Lib\site-packages\twisted\python\context.py", line 118, in callWithContext
	    return self.currentContext().callWithContext(ctx, func, *args, **kw)
	  File "C:\muddev\evenv\Lib\site-packages\twisted\python\context.py", line 83, in callWithContext
	    return func(*args, **kw)
	--- <exception caught here> ---
	  File "C:\muddev\evenv\Lib\site-packages\twisted\internet\selectreactor.py", line 149, in _doReadOrWrite
	    why = getattr(selectable, method)()
	  File "C:\muddev\evenv\Lib\site-packages\twisted\internet\tcp.py", line 247, in doRead
	    return self._dataReceived(data)
	  File "C:\muddev\evenv\Lib\site-packages\twisted\internet\tcp.py", line 252, in _dataReceived
	    rval = self.protocol.dataReceived(data)
	  File "C:\muddev\evenv\Lib\site-packages\twisted\protocols\basic.py", line 554, in dataReceived
	    why = self.rawDataReceived(data)
	  File "C:\muddev\evenv\Lib\site-packages\twisted\web\http.py", line 706, in rawDataReceived
	    self.handleResponseEnd()
	  File "C:\muddev\evenv\Lib\site-packages\twisted\web\proxy.py", line 82, in handleResponseEnd
	    self.father.finish()
	  File "C:\muddev\evenv\Lib\site-packages\twisted\web\server.py", line 279, in finish
	    return http.Request.finish(self)
	  File "C:\muddev\evenv\Lib\site-packages\twisted\web\http.py", line 1132, in finish
	    "Request.finish called on a request after its connection was lost; "
	builtins.RuntimeError: Request.finish called on a request after its connection was lost; use Request.notifyFinish to keep track of this.
	
22-01-27 18:52:45-08  |Portal| Unhandled Error
	Traceback (most recent call last):
	  File "C:\muddev\evenv\Lib\site-packages\twisted\python\log.py", line 101, in callWithLogger
	    return callWithContext({"system": lp}, func, *args, **kw)
	  File "C:\muddev\evenv\Lib\site-packages\twisted\python\log.py", line 85, in callWithContext
	    return context.call({ILogContext: newCtx}, func, *args, **kw)
	  File "C:\muddev\evenv\Lib\site-packages\twisted\python\context.py", line 118, in callWithContext
	    return self.currentContext().callWithContext(ctx, func, *args, **kw)
	  File "C:\muddev\evenv\Lib\site-packages\twisted\python\context.py", line 83, in callWithContext
	    return func(*args, **kw)
	--- <exception caught here> ---
	  File "C:\muddev\evenv\Lib\site-packages\twisted\internet\selectreactor.py", line 149, in _doReadOrWrite
	    why = getattr(selectable, method)()
	  File "C:\muddev\evenv\Lib\site-packages\twisted\internet\tcp.py", line 247, in doRead
	    return self._dataReceived(data)
	  File "C:\muddev\evenv\Lib\site-packages\twisted\internet\tcp.py", line 252, in _dataReceived
	    rval = self.protocol.dataReceived(data)
	  File "C:\muddev\evenv\Lib\site-packages\twisted\protocols\basic.py", line 554, in dataReceived
	    why = self.rawDataReceived(data)
	  File "C:\muddev\evenv\Lib\site-packages\twisted\web\http.py", line 706, in rawDataReceived
	    self.handleResponseEnd()
	  File "C:\muddev\evenv\Lib\site-packages\twisted\web\proxy.py", line 82, in handleResponseEnd
	    self.father.finish()
	  File "C:\muddev\evenv\Lib\site-packages\twisted\web\server.py", line 279, in finish
	    return http.Request.finish(self)
	  File "C:\muddev\evenv\Lib\site-packages\twisted\web\http.py", line 1132, in finish
	    "Request.finish called on a request after its connection was lost; "
	builtins.RuntimeError: Request.finish called on a request after its connection was lost; use Request.notifyFinish to keep track of this.
	
22-01-27 18:52:45-08  |Portal| Unhandled Error
	Traceback (most recent call last):
	  File "C:\muddev\evenv\Lib\site-packages\twisted\python\log.py", line 101, in callWithLogger
	    return callWithContext({"system": lp}, func, *args, **kw)
	  File "C:\muddev\evenv\Lib\site-packages\twisted\python\log.py", line 85, in callWithContext
	    return context.call({ILogContext: newCtx}, func, *args, **kw)
	  File "C:\muddev\evenv\Lib\site-packages\twisted\python\context.py", line 118, in callWithContext
	    return self.currentContext().callWithContext(ctx, func, *args, **kw)
	  File "C:\muddev\evenv\Lib\site-packages\twisted\python\context.py", line 83, in callWithContext
	    return func(*args, **kw)
	--- <exception caught here> ---
	  File "C:\muddev\evenv\Lib\site-packages\twisted\internet\selectreactor.py", line 149, in _doReadOrWrite
	    why = getattr(selectable, method)()
	  File "C:\muddev\evenv\Lib\site-packages\twisted\internet\tcp.py", line 247, in doRead
	    return self._dataReceived(data)
	  File "C:\muddev\evenv\Lib\site-packages\twisted\internet\tcp.py", line 252, in _dataReceived
	    rval = self.protocol.dataReceived(data)
	  File "C:\muddev\evenv\Lib\site-packages\twisted\protocols\basic.py", line 554, in dataReceived
	    why = self.rawDataReceived(data)
	  File "C:\muddev\evenv\Lib\site-packages\twisted\web\http.py", line 706, in rawDataReceived
	    self.handleResponseEnd()
	  File "C:\muddev\evenv\Lib\site-packages\twisted\web\proxy.py", line 82, in handleResponseEnd
	    self.father.finish()
	  File "C:\muddev\evenv\Lib\site-packages\twisted\web\server.py", line 279, in finish
	    return http.Request.finish(self)
	  File "C:\muddev\evenv\Lib\site-packages\twisted\web\http.py", line 1132, in finish
	    "Request.finish called on a request after its connection was lost; "
	builtins.RuntimeError: Request.finish called on a request after its connection was lost; use Request.notifyFinish to keep track of this.
	
22-01-27 18:52:45-08  |Portal| Unhandled Error
	Traceback (most recent call last):
	  File "C:\muddev\evenv\Lib\site-packages\twisted\python\log.py", line 101, in callWithLogger
	    return callWithContext({"system": lp}, func, *args, **kw)
	  File "C:\muddev\evenv\Lib\site-packages\twisted\python\log.py", line 85, in callWithContext
	    return context.call({ILogContext: newCtx}, func, *args, **kw)
	  File "C:\muddev\evenv\Lib\site-packages\twisted\python\context.py", line 118, in callWithContext
	    return self.currentContext().callWithContext(ctx, func, *args, **kw)
	  File "C:\muddev\evenv\Lib\site-packages\twisted\python\context.py", line 83, in callWithContext
	    return func(*args, **kw)
	--- <exception caught here> ---
	  File "C:\muddev\evenv\Lib\site-packages\twisted\internet\selectreactor.py", line 149, in _doReadOrWrite
	    why = getattr(selectable, method)()
	  File "C:\muddev\evenv\Lib\site-packages\twisted\internet\tcp.py", line 247, in doRead
	    return self._dataReceived(data)
	  File "C:\muddev\evenv\Lib\site-packages\twisted\internet\tcp.py", line 252, in _dataReceived
	    rval = self.protocol.dataReceived(data)
	  File "C:\muddev\evenv\Lib\site-packages\twisted\protocols\basic.py", line 554, in dataReceived
	    why = self.rawDataReceived(data)
	  File "C:\muddev\evenv\Lib\site-packages\twisted\web\http.py", line 706, in rawDataReceived
	    self.handleResponseEnd()
	  File "C:\muddev\evenv\Lib\site-packages\twisted\web\proxy.py", line 82, in handleResponseEnd
	    self.father.finish()
	  File "C:\muddev\evenv\Lib\site-packages\twisted\web\server.py", line 279, in finish
	    return http.Request.finish(self)
	  File "C:\muddev\evenv\Lib\site-packages\twisted\web\http.py", line 1132, in finish
	    "Request.finish called on a request after its connection was lost; "
	builtins.RuntimeError: Request.finish called on a request after its connection was lost; use Request.notifyFinish to keep track of this.
	
22-01-27 18:52:45-08  |Portal| Unhandled Error
	Traceback (most recent call last):
	  File "C:\muddev\evenv\Lib\site-packages\twisted\python\log.py", line 101, in callWithLogger
	    return callWithContext({"system": lp}, func, *args, **kw)
	  File "C:\muddev\evenv\Lib\site-packages\twisted\python\log.py", line 85, in callWithContext
	    return context.call({ILogContext: newCtx}, func, *args, **kw)
	  File "C:\muddev\evenv\Lib\site-packages\twisted\python\context.py", line 118, in callWithContext
	    return self.currentContext().callWithContext(ctx, func, *args, **kw)
	  File "C:\muddev\evenv\Lib\site-packages\twisted\python\context.py", line 83, in callWithContext
	    return func(*args, **kw)
	--- <exception caught here> ---
	  File "C:\muddev\evenv\Lib\site-packages\twisted\internet\selectreactor.py", line 149, in _doReadOrWrite
	    why = getattr(selectable, method)()
	  File "C:\muddev\evenv\Lib\site-packages\twisted\internet\tcp.py", line 247, in doRead
	    return self._dataReceived(data)
	  File "C:\muddev\evenv\Lib\site-packages\twisted\internet\tcp.py", line 252, in _dataReceived
	    rval = self.protocol.dataReceived(data)
	  File "C:\muddev\evenv\Lib\site-packages\twisted\protocols\basic.py", line 554, in dataReceived
	    why = self.rawDataReceived(data)
	  File "C:\muddev\evenv\Lib\site-packages\twisted\web\http.py", line 706, in rawDataReceived
	    self.handleResponseEnd()
	  File "C:\muddev\evenv\Lib\site-packages\twisted\web\proxy.py", line 82, in handleResponseEnd
	    self.father.finish()
	  File "C:\muddev\evenv\Lib\site-packages\twisted\web\server.py", line 279, in finish
	    return http.Request.finish(self)
	  File "C:\muddev\evenv\Lib\site-packages\twisted\web\http.py", line 1132, in finish
	    "Request.finish called on a request after its connection was lost; "
	builtins.RuntimeError: Request.finish called on a request after its connection was lost; use Request.notifyFinish to keep track of this.
	
22-01-27 18:52:45-08  |Portal| Unhandled Error
	Traceback (most recent call last):
	  File "C:\muddev\evenv\Lib\site-packages\twisted\python\log.py", line 101, in callWithLogger
	    return callWithContext({"system": lp}, func, *args, **kw)
	  File "C:\muddev\evenv\Lib\site-packages\twisted\python\log.py", line 85, in callWithContext
	    return context.call({ILogContext: newCtx}, func, *args, **kw)
	  File "C:\muddev\evenv\Lib\site-packages\twisted\python\context.py", line 118, in callWithContext
	    return self.currentContext().callWithContext(ctx, func, *args, **kw)
	  File "C:\muddev\evenv\Lib\site-packages\twisted\python\context.py", line 83, in callWithContext
	    return func(*args, **kw)
	--- <exception caught here> ---
	  File "C:\muddev\evenv\Lib\site-packages\twisted\internet\selectreactor.py", line 149, in _doReadOrWrite
	    why = getattr(selectable, method)()
	  File "C:\muddev\evenv\Lib\site-packages\twisted\internet\tcp.py", line 247, in doRead
	    return self._dataReceived(data)
	  File "C:\muddev\evenv\Lib\site-packages\twisted\internet\tcp.py", line 252, in _dataReceived
	    rval = self.protocol.dataReceived(data)
	  File "C:\muddev\evenv\Lib\site-packages\twisted\protocols\basic.py", line 554, in dataReceived
	    why = self.rawDataReceived(data)
	  File "C:\muddev\evenv\Lib\site-packages\twisted\web\http.py", line 706, in rawDataReceived
	    self.handleResponseEnd()
	  File "C:\muddev\evenv\Lib\site-packages\twisted\web\proxy.py", line 82, in handleResponseEnd
	    self.father.finish()
	  File "C:\muddev\evenv\Lib\site-packages\twisted\web\server.py", line 279, in finish
	    return http.Request.finish(self)
	  File "C:\muddev\evenv\Lib\site-packages\twisted\web\http.py", line 1132, in finish
	    "Request.finish called on a request after its connection was lost; "
	builtins.RuntimeError: Request.finish called on a request after its connection was lost; use Request.notifyFinish to keep track of this.
	
22-01-27 18:53:45-08  |Portal| Timing out client: IPv4Address(type='TCP', host='127.0.0.1', port=51018)
22-01-27 19:48:41-08  |Portal| Portal starting server ... 
22-01-27 19:49:18-08  |Portal| Portal starting server ... 
22-01-27 19:50:59-08  |Portal| Portal starting server ... 
22-01-27 19:54:54-08  |Portal| Portal starting server ... 
22-01-27 20:15:19-08  |Portal| Portal starting server ... 
22-01-27 20:16:26-08  |Portal| Portal starting server ... 
22-01-27 20:30:15-08  |Portal| Portal starting server ... 
22-01-27 20:36:30-08  |Portal| Portal starting server ... 
22-01-27 20:36:59-08  |Portal| Portal starting server ... 
22-01-27 20:40:21-08  |Portal| Portal starting server ... 
22-01-27 21:10:56-08  |Portal| Portal starting server ... 
22-01-27 21:11:38-08  |Portal| Portal starting server ... 
22-01-27 21:13:12-08  |Portal| Portal starting server ... 
22-01-27 21:27:18-08  |Portal| Portal starting server ... 
22-01-27 21:28:57-08  |Portal| Portal starting server ... 
22-01-27 21:30:48-08  |Portal| Portal starting server ... 
22-01-27 21:32:42-08  |Portal| Portal starting server ... 
22-01-27 21:52:39-08  |Portal| Portal starting server ... 
22-01-27 21:56:42-08  |Portal| Portal starting server ... 
22-01-27 21:58:45-08  |Portal| Portal starting server ... 
22-01-27 22:05:05-08  |Portal| Portal starting server ... 
22-01-27 22:06:16-08  |Portal| Portal starting server ... 
22-01-27 22:09:03-08  |Portal| Portal starting server ... 
22-01-27 22:09:36-08  |Portal| Portal starting server ... 
22-01-27 22:11:22-08  |Portal| Portal starting server ... 
22-01-27 22:12:43-08  |Portal| Portal starting server ... 
22-01-27 22:15:15-08  |Portal| Portal starting server ... 
22-01-27 22:17:06-08  |Portal| Portal starting server ... 
22-01-27 22:18:11-08  |Portal| Portal starting server ... 
22-01-27 22:20:14-08  |Portal| Portal starting server ... 
22-01-27 22:21:25-08  |Portal| Portal starting server ... 
22-01-27 22:22:23-08  |Portal| Portal starting server ... 
22-01-27 22:23:36-08  |Portal| Portal starting server ... 
22-01-27 23:03:39-08  |Portal| Portal starting server ... 
22-01-27 23:04:00-08  |Portal| Portal starting server ... 
22-01-27 23:06:41-08  |Portal| Portal starting server ... 
22-01-27 23:09:44-08  |Portal| Portal starting server ... 
22-01-27 23:10:31-08  |Portal| Portal starting server ... 
22-01-29 19:35:31-08  |Portal| Unhandled Error
	Traceback (most recent call last):
	  File "C:\muddev\evenv\Lib\site-packages\twisted\python\log.py", line 101, in callWithLogger
	    return callWithContext({"system": lp}, func, *args, **kw)
	  File "C:\muddev\evenv\Lib\site-packages\twisted\python\log.py", line 85, in callWithContext
	    return context.call({ILogContext: newCtx}, func, *args, **kw)
	  File "C:\muddev\evenv\Lib\site-packages\twisted\python\context.py", line 118, in callWithContext
	    return self.currentContext().callWithContext(ctx, func, *args, **kw)
	  File "C:\muddev\evenv\Lib\site-packages\twisted\python\context.py", line 83, in callWithContext
	    return func(*args, **kw)
	--- <exception caught here> ---
	  File "C:\muddev\evenv\Lib\site-packages\twisted\internet\selectreactor.py", line 149, in _doReadOrWrite
	    why = getattr(selectable, method)()
	  File "C:\muddev\evenv\Lib\site-packages\twisted\internet\tcp.py", line 247, in doRead
	    return self._dataReceived(data)
	  File "C:\muddev\evenv\Lib\site-packages\twisted\internet\tcp.py", line 252, in _dataReceived
	    rval = self.protocol.dataReceived(data)
	  File "C:\muddev\evenv\Lib\site-packages\twisted\protocols\basic.py", line 554, in dataReceived
	    why = self.rawDataReceived(data)
	  File "C:\muddev\evenv\Lib\site-packages\twisted\web\http.py", line 706, in rawDataReceived
	    self.handleResponseEnd()
	  File "C:\muddev\evenv\Lib\site-packages\twisted\web\proxy.py", line 82, in handleResponseEnd
	    self.father.finish()
	  File "C:\muddev\evenv\Lib\site-packages\twisted\web\server.py", line 279, in finish
	    return http.Request.finish(self)
	  File "C:\muddev\evenv\Lib\site-packages\twisted\web\http.py", line 1132, in finish
	    "Request.finish called on a request after its connection was lost; "
	builtins.RuntimeError: Request.finish called on a request after its connection was lost; use Request.notifyFinish to keep track of this.
	
22-01-29 19:35:31-08  |Portal| Unhandled Error
	Traceback (most recent call last):
	  File "C:\muddev\evenv\Lib\site-packages\twisted\python\log.py", line 101, in callWithLogger
	    return callWithContext({"system": lp}, func, *args, **kw)
	  File "C:\muddev\evenv\Lib\site-packages\twisted\python\log.py", line 85, in callWithContext
	    return context.call({ILogContext: newCtx}, func, *args, **kw)
	  File "C:\muddev\evenv\Lib\site-packages\twisted\python\context.py", line 118, in callWithContext
	    return self.currentContext().callWithContext(ctx, func, *args, **kw)
	  File "C:\muddev\evenv\Lib\site-packages\twisted\python\context.py", line 83, in callWithContext
	    return func(*args, **kw)
	--- <exception caught here> ---
	  File "C:\muddev\evenv\Lib\site-packages\twisted\internet\selectreactor.py", line 149, in _doReadOrWrite
	    why = getattr(selectable, method)()
	  File "C:\muddev\evenv\Lib\site-packages\twisted\internet\tcp.py", line 247, in doRead
	    return self._dataReceived(data)
	  File "C:\muddev\evenv\Lib\site-packages\twisted\internet\tcp.py", line 252, in _dataReceived
	    rval = self.protocol.dataReceived(data)
	  File "C:\muddev\evenv\Lib\site-packages\twisted\protocols\basic.py", line 554, in dataReceived
	    why = self.rawDataReceived(data)
	  File "C:\muddev\evenv\Lib\site-packages\twisted\web\http.py", line 706, in rawDataReceived
	    self.handleResponseEnd()
	  File "C:\muddev\evenv\Lib\site-packages\twisted\web\proxy.py", line 82, in handleResponseEnd
	    self.father.finish()
	  File "C:\muddev\evenv\Lib\site-packages\twisted\web\server.py", line 279, in finish
	    return http.Request.finish(self)
	  File "C:\muddev\evenv\Lib\site-packages\twisted\web\http.py", line 1132, in finish
	    "Request.finish called on a request after its connection was lost; "
	builtins.RuntimeError: Request.finish called on a request after its connection was lost; use Request.notifyFinish to keep track of this.
	
22-01-29 19:35:31-08  |Portal| Unhandled Error
	Traceback (most recent call last):
	  File "C:\muddev\evenv\Lib\site-packages\twisted\python\log.py", line 101, in callWithLogger
	    return callWithContext({"system": lp}, func, *args, **kw)
	  File "C:\muddev\evenv\Lib\site-packages\twisted\python\log.py", line 85, in callWithContext
	    return context.call({ILogContext: newCtx}, func, *args, **kw)
	  File "C:\muddev\evenv\Lib\site-packages\twisted\python\context.py", line 118, in callWithContext
	    return self.currentContext().callWithContext(ctx, func, *args, **kw)
	  File "C:\muddev\evenv\Lib\site-packages\twisted\python\context.py", line 83, in callWithContext
	    return func(*args, **kw)
	--- <exception caught here> ---
	  File "C:\muddev\evenv\Lib\site-packages\twisted\internet\selectreactor.py", line 149, in _doReadOrWrite
	    why = getattr(selectable, method)()
	  File "C:\muddev\evenv\Lib\site-packages\twisted\internet\tcp.py", line 247, in doRead
	    return self._dataReceived(data)
	  File "C:\muddev\evenv\Lib\site-packages\twisted\internet\tcp.py", line 252, in _dataReceived
	    rval = self.protocol.dataReceived(data)
	  File "C:\muddev\evenv\Lib\site-packages\twisted\protocols\basic.py", line 554, in dataReceived
	    why = self.rawDataReceived(data)
	  File "C:\muddev\evenv\Lib\site-packages\twisted\web\http.py", line 706, in rawDataReceived
	    self.handleResponseEnd()
	  File "C:\muddev\evenv\Lib\site-packages\twisted\web\proxy.py", line 82, in handleResponseEnd
	    self.father.finish()
	  File "C:\muddev\evenv\Lib\site-packages\twisted\web\server.py", line 279, in finish
	    return http.Request.finish(self)
	  File "C:\muddev\evenv\Lib\site-packages\twisted\web\http.py", line 1132, in finish
	    "Request.finish called on a request after its connection was lost; "
	builtins.RuntimeError: Request.finish called on a request after its connection was lost; use Request.notifyFinish to keep track of this.
	
22-01-29 19:35:31-08  |Portal| Unhandled Error
	Traceback (most recent call last):
	  File "C:\muddev\evenv\Lib\site-packages\twisted\python\log.py", line 101, in callWithLogger
	    return callWithContext({"system": lp}, func, *args, **kw)
	  File "C:\muddev\evenv\Lib\site-packages\twisted\python\log.py", line 85, in callWithContext
	    return context.call({ILogContext: newCtx}, func, *args, **kw)
	  File "C:\muddev\evenv\Lib\site-packages\twisted\python\context.py", line 118, in callWithContext
	    return self.currentContext().callWithContext(ctx, func, *args, **kw)
	  File "C:\muddev\evenv\Lib\site-packages\twisted\python\context.py", line 83, in callWithContext
	    return func(*args, **kw)
	--- <exception caught here> ---
	  File "C:\muddev\evenv\Lib\site-packages\twisted\internet\selectreactor.py", line 149, in _doReadOrWrite
	    why = getattr(selectable, method)()
	  File "C:\muddev\evenv\Lib\site-packages\twisted\internet\tcp.py", line 247, in doRead
	    return self._dataReceived(data)
	  File "C:\muddev\evenv\Lib\site-packages\twisted\internet\tcp.py", line 252, in _dataReceived
	    rval = self.protocol.dataReceived(data)
	  File "C:\muddev\evenv\Lib\site-packages\twisted\protocols\basic.py", line 554, in dataReceived
	    why = self.rawDataReceived(data)
	  File "C:\muddev\evenv\Lib\site-packages\twisted\web\http.py", line 706, in rawDataReceived
	    self.handleResponseEnd()
	  File "C:\muddev\evenv\Lib\site-packages\twisted\web\proxy.py", line 82, in handleResponseEnd
	    self.father.finish()
	  File "C:\muddev\evenv\Lib\site-packages\twisted\web\server.py", line 279, in finish
	    return http.Request.finish(self)
	  File "C:\muddev\evenv\Lib\site-packages\twisted\web\http.py", line 1132, in finish
	    "Request.finish called on a request after its connection was lost; "
	builtins.RuntimeError: Request.finish called on a request after its connection was lost; use Request.notifyFinish to keep track of this.
	
22-01-29 19:35:31-08  |Portal| Unhandled Error
	Traceback (most recent call last):
	  File "C:\muddev\evenv\Lib\site-packages\twisted\python\log.py", line 101, in callWithLogger
	    return callWithContext({"system": lp}, func, *args, **kw)
	  File "C:\muddev\evenv\Lib\site-packages\twisted\python\log.py", line 85, in callWithContext
	    return context.call({ILogContext: newCtx}, func, *args, **kw)
	  File "C:\muddev\evenv\Lib\site-packages\twisted\python\context.py", line 118, in callWithContext
	    return self.currentContext().callWithContext(ctx, func, *args, **kw)
	  File "C:\muddev\evenv\Lib\site-packages\twisted\python\context.py", line 83, in callWithContext
	    return func(*args, **kw)
	--- <exception caught here> ---
	  File "C:\muddev\evenv\Lib\site-packages\twisted\internet\selectreactor.py", line 149, in _doReadOrWrite
	    why = getattr(selectable, method)()
	  File "C:\muddev\evenv\Lib\site-packages\twisted\internet\tcp.py", line 247, in doRead
	    return self._dataReceived(data)
	  File "C:\muddev\evenv\Lib\site-packages\twisted\internet\tcp.py", line 252, in _dataReceived
	    rval = self.protocol.dataReceived(data)
	  File "C:\muddev\evenv\Lib\site-packages\twisted\protocols\basic.py", line 554, in dataReceived
	    why = self.rawDataReceived(data)
	  File "C:\muddev\evenv\Lib\site-packages\twisted\web\http.py", line 706, in rawDataReceived
	    self.handleResponseEnd()
	  File "C:\muddev\evenv\Lib\site-packages\twisted\web\proxy.py", line 82, in handleResponseEnd
	    self.father.finish()
	  File "C:\muddev\evenv\Lib\site-packages\twisted\web\server.py", line 279, in finish
	    return http.Request.finish(self)
	  File "C:\muddev\evenv\Lib\site-packages\twisted\web\http.py", line 1132, in finish
	    "Request.finish called on a request after its connection was lost; "
	builtins.RuntimeError: Request.finish called on a request after its connection was lost; use Request.notifyFinish to keep track of this.
	
22-01-29 19:35:31-08  |Portal| Unhandled Error
	Traceback (most recent call last):
	  File "C:\muddev\evenv\Lib\site-packages\twisted\python\log.py", line 101, in callWithLogger
	    return callWithContext({"system": lp}, func, *args, **kw)
	  File "C:\muddev\evenv\Lib\site-packages\twisted\python\log.py", line 85, in callWithContext
	    return context.call({ILogContext: newCtx}, func, *args, **kw)
	  File "C:\muddev\evenv\Lib\site-packages\twisted\python\context.py", line 118, in callWithContext
	    return self.currentContext().callWithContext(ctx, func, *args, **kw)
	  File "C:\muddev\evenv\Lib\site-packages\twisted\python\context.py", line 83, in callWithContext
	    return func(*args, **kw)
	--- <exception caught here> ---
	  File "C:\muddev\evenv\Lib\site-packages\twisted\internet\selectreactor.py", line 149, in _doReadOrWrite
	    why = getattr(selectable, method)()
	  File "C:\muddev\evenv\Lib\site-packages\twisted\internet\tcp.py", line 247, in doRead
	    return self._dataReceived(data)
	  File "C:\muddev\evenv\Lib\site-packages\twisted\internet\tcp.py", line 252, in _dataReceived
	    rval = self.protocol.dataReceived(data)
	  File "C:\muddev\evenv\Lib\site-packages\twisted\protocols\basic.py", line 554, in dataReceived
	    why = self.rawDataReceived(data)
	  File "C:\muddev\evenv\Lib\site-packages\twisted\web\http.py", line 706, in rawDataReceived
	    self.handleResponseEnd()
	  File "C:\muddev\evenv\Lib\site-packages\twisted\web\proxy.py", line 82, in handleResponseEnd
	    self.father.finish()
	  File "C:\muddev\evenv\Lib\site-packages\twisted\web\server.py", line 279, in finish
	    return http.Request.finish(self)
	  File "C:\muddev\evenv\Lib\site-packages\twisted\web\http.py", line 1132, in finish
	    "Request.finish called on a request after its connection was lost; "
	builtins.RuntimeError: Request.finish called on a request after its connection was lost; use Request.notifyFinish to keep track of this.
	
22-01-29 19:35:31-08  |Portal| Unhandled Error
	Traceback (most recent call last):
	  File "C:\muddev\evenv\Lib\site-packages\twisted\python\log.py", line 101, in callWithLogger
	    return callWithContext({"system": lp}, func, *args, **kw)
	  File "C:\muddev\evenv\Lib\site-packages\twisted\python\log.py", line 85, in callWithContext
	    return context.call({ILogContext: newCtx}, func, *args, **kw)
	  File "C:\muddev\evenv\Lib\site-packages\twisted\python\context.py", line 118, in callWithContext
	    return self.currentContext().callWithContext(ctx, func, *args, **kw)
	  File "C:\muddev\evenv\Lib\site-packages\twisted\python\context.py", line 83, in callWithContext
	    return func(*args, **kw)
	--- <exception caught here> ---
	  File "C:\muddev\evenv\Lib\site-packages\twisted\internet\selectreactor.py", line 149, in _doReadOrWrite
	    why = getattr(selectable, method)()
	  File "C:\muddev\evenv\Lib\site-packages\twisted\internet\tcp.py", line 247, in doRead
	    return self._dataReceived(data)
	  File "C:\muddev\evenv\Lib\site-packages\twisted\internet\tcp.py", line 252, in _dataReceived
	    rval = self.protocol.dataReceived(data)
	  File "C:\muddev\evenv\Lib\site-packages\twisted\protocols\basic.py", line 554, in dataReceived
	    why = self.rawDataReceived(data)
	  File "C:\muddev\evenv\Lib\site-packages\twisted\web\http.py", line 706, in rawDataReceived
	    self.handleResponseEnd()
	  File "C:\muddev\evenv\Lib\site-packages\twisted\web\proxy.py", line 82, in handleResponseEnd
	    self.father.finish()
	  File "C:\muddev\evenv\Lib\site-packages\twisted\web\server.py", line 279, in finish
	    return http.Request.finish(self)
	  File "C:\muddev\evenv\Lib\site-packages\twisted\web\http.py", line 1132, in finish
	    "Request.finish called on a request after its connection was lost; "
	builtins.RuntimeError: Request.finish called on a request after its connection was lost; use Request.notifyFinish to keep track of this.
	
22-01-29 19:35:31-08  |Portal| Unhandled Error
	Traceback (most recent call last):
	  File "C:\muddev\evenv\Lib\site-packages\twisted\python\log.py", line 101, in callWithLogger
	    return callWithContext({"system": lp}, func, *args, **kw)
	  File "C:\muddev\evenv\Lib\site-packages\twisted\python\log.py", line 85, in callWithContext
	    return context.call({ILogContext: newCtx}, func, *args, **kw)
	  File "C:\muddev\evenv\Lib\site-packages\twisted\python\context.py", line 118, in callWithContext
	    return self.currentContext().callWithContext(ctx, func, *args, **kw)
	  File "C:\muddev\evenv\Lib\site-packages\twisted\python\context.py", line 83, in callWithContext
	    return func(*args, **kw)
	--- <exception caught here> ---
	  File "C:\muddev\evenv\Lib\site-packages\twisted\internet\selectreactor.py", line 149, in _doReadOrWrite
	    why = getattr(selectable, method)()
	  File "C:\muddev\evenv\Lib\site-packages\twisted\internet\tcp.py", line 247, in doRead
	    return self._dataReceived(data)
	  File "C:\muddev\evenv\Lib\site-packages\twisted\internet\tcp.py", line 252, in _dataReceived
	    rval = self.protocol.dataReceived(data)
	  File "C:\muddev\evenv\Lib\site-packages\twisted\protocols\basic.py", line 554, in dataReceived
	    why = self.rawDataReceived(data)
	  File "C:\muddev\evenv\Lib\site-packages\twisted\web\http.py", line 706, in rawDataReceived
	    self.handleResponseEnd()
	  File "C:\muddev\evenv\Lib\site-packages\twisted\web\proxy.py", line 82, in handleResponseEnd
	    self.father.finish()
	  File "C:\muddev\evenv\Lib\site-packages\twisted\web\server.py", line 279, in finish
	    return http.Request.finish(self)
	  File "C:\muddev\evenv\Lib\site-packages\twisted\web\http.py", line 1132, in finish
	    "Request.finish called on a request after its connection was lost; "
	builtins.RuntimeError: Request.finish called on a request after its connection was lost; use Request.notifyFinish to keep track of this.
	
22-01-29 19:35:31-08  |Portal| Unhandled Error
	Traceback (most recent call last):
	  File "C:\muddev\evenv\Lib\site-packages\twisted\python\log.py", line 101, in callWithLogger
	    return callWithContext({"system": lp}, func, *args, **kw)
	  File "C:\muddev\evenv\Lib\site-packages\twisted\python\log.py", line 85, in callWithContext
	    return context.call({ILogContext: newCtx}, func, *args, **kw)
	  File "C:\muddev\evenv\Lib\site-packages\twisted\python\context.py", line 118, in callWithContext
	    return self.currentContext().callWithContext(ctx, func, *args, **kw)
	  File "C:\muddev\evenv\Lib\site-packages\twisted\python\context.py", line 83, in callWithContext
	    return func(*args, **kw)
	--- <exception caught here> ---
	  File "C:\muddev\evenv\Lib\site-packages\twisted\internet\selectreactor.py", line 149, in _doReadOrWrite
	    why = getattr(selectable, method)()
	  File "C:\muddev\evenv\Lib\site-packages\twisted\internet\tcp.py", line 247, in doRead
	    return self._dataReceived(data)
	  File "C:\muddev\evenv\Lib\site-packages\twisted\internet\tcp.py", line 252, in _dataReceived
	    rval = self.protocol.dataReceived(data)
	  File "C:\muddev\evenv\Lib\site-packages\twisted\protocols\basic.py", line 554, in dataReceived
	    why = self.rawDataReceived(data)
	  File "C:\muddev\evenv\Lib\site-packages\twisted\web\http.py", line 706, in rawDataReceived
	    self.handleResponseEnd()
	  File "C:\muddev\evenv\Lib\site-packages\twisted\web\proxy.py", line 82, in handleResponseEnd
	    self.father.finish()
	  File "C:\muddev\evenv\Lib\site-packages\twisted\web\server.py", line 279, in finish
	    return http.Request.finish(self)
	  File "C:\muddev\evenv\Lib\site-packages\twisted\web\http.py", line 1132, in finish
	    "Request.finish called on a request after its connection was lost; "
	builtins.RuntimeError: Request.finish called on a request after its connection was lost; use Request.notifyFinish to keep track of this.
	
22-01-29 19:35:31-08  |Portal| Unhandled Error
	Traceback (most recent call last):
	  File "C:\muddev\evenv\Lib\site-packages\twisted\python\log.py", line 101, in callWithLogger
	    return callWithContext({"system": lp}, func, *args, **kw)
	  File "C:\muddev\evenv\Lib\site-packages\twisted\python\log.py", line 85, in callWithContext
	    return context.call({ILogContext: newCtx}, func, *args, **kw)
	  File "C:\muddev\evenv\Lib\site-packages\twisted\python\context.py", line 118, in callWithContext
	    return self.currentContext().callWithContext(ctx, func, *args, **kw)
	  File "C:\muddev\evenv\Lib\site-packages\twisted\python\context.py", line 83, in callWithContext
	    return func(*args, **kw)
	--- <exception caught here> ---
	  File "C:\muddev\evenv\Lib\site-packages\twisted\internet\selectreactor.py", line 149, in _doReadOrWrite
	    why = getattr(selectable, method)()
	  File "C:\muddev\evenv\Lib\site-packages\twisted\internet\tcp.py", line 247, in doRead
	    return self._dataReceived(data)
	  File "C:\muddev\evenv\Lib\site-packages\twisted\internet\tcp.py", line 252, in _dataReceived
	    rval = self.protocol.dataReceived(data)
	  File "C:\muddev\evenv\Lib\site-packages\twisted\protocols\basic.py", line 554, in dataReceived
	    why = self.rawDataReceived(data)
	  File "C:\muddev\evenv\Lib\site-packages\twisted\web\http.py", line 706, in rawDataReceived
	    self.handleResponseEnd()
	  File "C:\muddev\evenv\Lib\site-packages\twisted\web\proxy.py", line 82, in handleResponseEnd
	    self.father.finish()
	  File "C:\muddev\evenv\Lib\site-packages\twisted\web\server.py", line 279, in finish
	    return http.Request.finish(self)
	  File "C:\muddev\evenv\Lib\site-packages\twisted\web\http.py", line 1132, in finish
	    "Request.finish called on a request after its connection was lost; "
	builtins.RuntimeError: Request.finish called on a request after its connection was lost; use Request.notifyFinish to keep track of this.
	
22-01-29 19:35:31-08  |Portal| Unhandled Error
	Traceback (most recent call last):
	  File "C:\muddev\evenv\Lib\site-packages\twisted\python\log.py", line 101, in callWithLogger
	    return callWithContext({"system": lp}, func, *args, **kw)
	  File "C:\muddev\evenv\Lib\site-packages\twisted\python\log.py", line 85, in callWithContext
	    return context.call({ILogContext: newCtx}, func, *args, **kw)
	  File "C:\muddev\evenv\Lib\site-packages\twisted\python\context.py", line 118, in callWithContext
	    return self.currentContext().callWithContext(ctx, func, *args, **kw)
	  File "C:\muddev\evenv\Lib\site-packages\twisted\python\context.py", line 83, in callWithContext
	    return func(*args, **kw)
	--- <exception caught here> ---
	  File "C:\muddev\evenv\Lib\site-packages\twisted\internet\selectreactor.py", line 149, in _doReadOrWrite
	    why = getattr(selectable, method)()
	  File "C:\muddev\evenv\Lib\site-packages\twisted\internet\tcp.py", line 247, in doRead
	    return self._dataReceived(data)
	  File "C:\muddev\evenv\Lib\site-packages\twisted\internet\tcp.py", line 252, in _dataReceived
	    rval = self.protocol.dataReceived(data)
	  File "C:\muddev\evenv\Lib\site-packages\twisted\protocols\basic.py", line 554, in dataReceived
	    why = self.rawDataReceived(data)
	  File "C:\muddev\evenv\Lib\site-packages\twisted\web\http.py", line 706, in rawDataReceived
	    self.handleResponseEnd()
	  File "C:\muddev\evenv\Lib\site-packages\twisted\web\proxy.py", line 82, in handleResponseEnd
	    self.father.finish()
	  File "C:\muddev\evenv\Lib\site-packages\twisted\web\server.py", line 279, in finish
	    return http.Request.finish(self)
	  File "C:\muddev\evenv\Lib\site-packages\twisted\web\http.py", line 1132, in finish
	    "Request.finish called on a request after its connection was lost; "
	builtins.RuntimeError: Request.finish called on a request after its connection was lost; use Request.notifyFinish to keep track of this.
	
22-01-29 19:35:31-08  |Portal| Unhandled Error
	Traceback (most recent call last):
	  File "C:\muddev\evenv\Lib\site-packages\twisted\python\log.py", line 101, in callWithLogger
	    return callWithContext({"system": lp}, func, *args, **kw)
	  File "C:\muddev\evenv\Lib\site-packages\twisted\python\log.py", line 85, in callWithContext
	    return context.call({ILogContext: newCtx}, func, *args, **kw)
	  File "C:\muddev\evenv\Lib\site-packages\twisted\python\context.py", line 118, in callWithContext
	    return self.currentContext().callWithContext(ctx, func, *args, **kw)
	  File "C:\muddev\evenv\Lib\site-packages\twisted\python\context.py", line 83, in callWithContext
	    return func(*args, **kw)
	--- <exception caught here> ---
	  File "C:\muddev\evenv\Lib\site-packages\twisted\internet\selectreactor.py", line 149, in _doReadOrWrite
	    why = getattr(selectable, method)()
	  File "C:\muddev\evenv\Lib\site-packages\twisted\internet\tcp.py", line 247, in doRead
	    return self._dataReceived(data)
	  File "C:\muddev\evenv\Lib\site-packages\twisted\internet\tcp.py", line 252, in _dataReceived
	    rval = self.protocol.dataReceived(data)
	  File "C:\muddev\evenv\Lib\site-packages\twisted\protocols\basic.py", line 554, in dataReceived
	    why = self.rawDataReceived(data)
	  File "C:\muddev\evenv\Lib\site-packages\twisted\web\http.py", line 706, in rawDataReceived
	    self.handleResponseEnd()
	  File "C:\muddev\evenv\Lib\site-packages\twisted\web\proxy.py", line 82, in handleResponseEnd
	    self.father.finish()
	  File "C:\muddev\evenv\Lib\site-packages\twisted\web\server.py", line 279, in finish
	    return http.Request.finish(self)
	  File "C:\muddev\evenv\Lib\site-packages\twisted\web\http.py", line 1132, in finish
	    "Request.finish called on a request after its connection was lost; "
	builtins.RuntimeError: Request.finish called on a request after its connection was lost; use Request.notifyFinish to keep track of this.
	
22-01-29 19:35:31-08  |Portal| Unhandled Error
	Traceback (most recent call last):
	  File "C:\muddev\evenv\Lib\site-packages\twisted\python\log.py", line 101, in callWithLogger
	    return callWithContext({"system": lp}, func, *args, **kw)
	  File "C:\muddev\evenv\Lib\site-packages\twisted\python\log.py", line 85, in callWithContext
	    return context.call({ILogContext: newCtx}, func, *args, **kw)
	  File "C:\muddev\evenv\Lib\site-packages\twisted\python\context.py", line 118, in callWithContext
	    return self.currentContext().callWithContext(ctx, func, *args, **kw)
	  File "C:\muddev\evenv\Lib\site-packages\twisted\python\context.py", line 83, in callWithContext
	    return func(*args, **kw)
	--- <exception caught here> ---
	  File "C:\muddev\evenv\Lib\site-packages\twisted\internet\selectreactor.py", line 149, in _doReadOrWrite
	    why = getattr(selectable, method)()
	  File "C:\muddev\evenv\Lib\site-packages\twisted\internet\tcp.py", line 247, in doRead
	    return self._dataReceived(data)
	  File "C:\muddev\evenv\Lib\site-packages\twisted\internet\tcp.py", line 252, in _dataReceived
	    rval = self.protocol.dataReceived(data)
	  File "C:\muddev\evenv\Lib\site-packages\twisted\protocols\basic.py", line 554, in dataReceived
	    why = self.rawDataReceived(data)
	  File "C:\muddev\evenv\Lib\site-packages\twisted\web\http.py", line 706, in rawDataReceived
	    self.handleResponseEnd()
	  File "C:\muddev\evenv\Lib\site-packages\twisted\web\proxy.py", line 82, in handleResponseEnd
	    self.father.finish()
	  File "C:\muddev\evenv\Lib\site-packages\twisted\web\server.py", line 279, in finish
	    return http.Request.finish(self)
	  File "C:\muddev\evenv\Lib\site-packages\twisted\web\http.py", line 1132, in finish
	    "Request.finish called on a request after its connection was lost; "
	builtins.RuntimeError: Request.finish called on a request after its connection was lost; use Request.notifyFinish to keep track of this.
	
22-01-29 19:35:31-08  |Portal| Unhandled Error
	Traceback (most recent call last):
	  File "C:\muddev\evenv\Lib\site-packages\twisted\python\log.py", line 101, in callWithLogger
	    return callWithContext({"system": lp}, func, *args, **kw)
	  File "C:\muddev\evenv\Lib\site-packages\twisted\python\log.py", line 85, in callWithContext
	    return context.call({ILogContext: newCtx}, func, *args, **kw)
	  File "C:\muddev\evenv\Lib\site-packages\twisted\python\context.py", line 118, in callWithContext
	    return self.currentContext().callWithContext(ctx, func, *args, **kw)
	  File "C:\muddev\evenv\Lib\site-packages\twisted\python\context.py", line 83, in callWithContext
	    return func(*args, **kw)
	--- <exception caught here> ---
	  File "C:\muddev\evenv\Lib\site-packages\twisted\internet\selectreactor.py", line 149, in _doReadOrWrite
	    why = getattr(selectable, method)()
	  File "C:\muddev\evenv\Lib\site-packages\twisted\internet\tcp.py", line 247, in doRead
	    return self._dataReceived(data)
	  File "C:\muddev\evenv\Lib\site-packages\twisted\internet\tcp.py", line 252, in _dataReceived
	    rval = self.protocol.dataReceived(data)
	  File "C:\muddev\evenv\Lib\site-packages\twisted\protocols\basic.py", line 554, in dataReceived
	    why = self.rawDataReceived(data)
	  File "C:\muddev\evenv\Lib\site-packages\twisted\web\http.py", line 706, in rawDataReceived
	    self.handleResponseEnd()
	  File "C:\muddev\evenv\Lib\site-packages\twisted\web\proxy.py", line 82, in handleResponseEnd
	    self.father.finish()
	  File "C:\muddev\evenv\Lib\site-packages\twisted\web\server.py", line 279, in finish
	    return http.Request.finish(self)
	  File "C:\muddev\evenv\Lib\site-packages\twisted\web\http.py", line 1132, in finish
	    "Request.finish called on a request after its connection was lost; "
	builtins.RuntimeError: Request.finish called on a request after its connection was lost; use Request.notifyFinish to keep track of this.
	
22-01-29 19:35:31-08  |Portal| Unhandled Error
	Traceback (most recent call last):
	  File "C:\muddev\evenv\Lib\site-packages\twisted\python\log.py", line 101, in callWithLogger
	    return callWithContext({"system": lp}, func, *args, **kw)
	  File "C:\muddev\evenv\Lib\site-packages\twisted\python\log.py", line 85, in callWithContext
	    return context.call({ILogContext: newCtx}, func, *args, **kw)
	  File "C:\muddev\evenv\Lib\site-packages\twisted\python\context.py", line 118, in callWithContext
	    return self.currentContext().callWithContext(ctx, func, *args, **kw)
	  File "C:\muddev\evenv\Lib\site-packages\twisted\python\context.py", line 83, in callWithContext
	    return func(*args, **kw)
	--- <exception caught here> ---
	  File "C:\muddev\evenv\Lib\site-packages\twisted\internet\selectreactor.py", line 149, in _doReadOrWrite
	    why = getattr(selectable, method)()
	  File "C:\muddev\evenv\Lib\site-packages\twisted\internet\tcp.py", line 247, in doRead
	    return self._dataReceived(data)
	  File "C:\muddev\evenv\Lib\site-packages\twisted\internet\tcp.py", line 252, in _dataReceived
	    rval = self.protocol.dataReceived(data)
	  File "C:\muddev\evenv\Lib\site-packages\twisted\protocols\basic.py", line 554, in dataReceived
	    why = self.rawDataReceived(data)
	  File "C:\muddev\evenv\Lib\site-packages\twisted\web\http.py", line 706, in rawDataReceived
	    self.handleResponseEnd()
	  File "C:\muddev\evenv\Lib\site-packages\twisted\web\proxy.py", line 82, in handleResponseEnd
	    self.father.finish()
	  File "C:\muddev\evenv\Lib\site-packages\twisted\web\server.py", line 279, in finish
	    return http.Request.finish(self)
	  File "C:\muddev\evenv\Lib\site-packages\twisted\web\http.py", line 1132, in finish
	    "Request.finish called on a request after its connection was lost; "
	builtins.RuntimeError: Request.finish called on a request after its connection was lost; use Request.notifyFinish to keep track of this.
	
22-01-29 19:35:31-08  |Portal| Unhandled Error
	Traceback (most recent call last):
	  File "C:\muddev\evenv\Lib\site-packages\twisted\python\log.py", line 101, in callWithLogger
	    return callWithContext({"system": lp}, func, *args, **kw)
	  File "C:\muddev\evenv\Lib\site-packages\twisted\python\log.py", line 85, in callWithContext
	    return context.call({ILogContext: newCtx}, func, *args, **kw)
	  File "C:\muddev\evenv\Lib\site-packages\twisted\python\context.py", line 118, in callWithContext
	    return self.currentContext().callWithContext(ctx, func, *args, **kw)
	  File "C:\muddev\evenv\Lib\site-packages\twisted\python\context.py", line 83, in callWithContext
	    return func(*args, **kw)
	--- <exception caught here> ---
	  File "C:\muddev\evenv\Lib\site-packages\twisted\internet\selectreactor.py", line 149, in _doReadOrWrite
	    why = getattr(selectable, method)()
	  File "C:\muddev\evenv\Lib\site-packages\twisted\internet\tcp.py", line 247, in doRead
	    return self._dataReceived(data)
	  File "C:\muddev\evenv\Lib\site-packages\twisted\internet\tcp.py", line 252, in _dataReceived
	    rval = self.protocol.dataReceived(data)
	  File "C:\muddev\evenv\Lib\site-packages\twisted\protocols\basic.py", line 554, in dataReceived
	    why = self.rawDataReceived(data)
	  File "C:\muddev\evenv\Lib\site-packages\twisted\web\http.py", line 706, in rawDataReceived
	    self.handleResponseEnd()
	  File "C:\muddev\evenv\Lib\site-packages\twisted\web\proxy.py", line 82, in handleResponseEnd
	    self.father.finish()
	  File "C:\muddev\evenv\Lib\site-packages\twisted\web\server.py", line 279, in finish
	    return http.Request.finish(self)
	  File "C:\muddev\evenv\Lib\site-packages\twisted\web\http.py", line 1132, in finish
	    "Request.finish called on a request after its connection was lost; "
	builtins.RuntimeError: Request.finish called on a request after its connection was lost; use Request.notifyFinish to keep track of this.
	
22-01-29 19:36:31-08  |Portal| Timing out client: IPv4Address(type='TCP', host='127.0.0.1', port=60419)
22-01-30 18:52:09-08  |Portal| (TCP Port 4001 Closed)
22-01-30 18:52:09-08  |Portal| (TCP Port 4000 Closed)
22-01-30 18:52:09-08  |Portal| (TCP Port 4006 Closed)
22-01-30 18:52:09-08  |Portal| (TCP Port 4002 Closed)
22-01-30 18:52:09-08  |Portal| Main loop terminated.
22-01-30 18:52:09-08  |Portal| Server Shut Down.
22-01-30 18:52:09-08  |Portal| Server Shut Down.
