|Portal| 2022-07-13 00:05:39 [..] Loaded.
|Portal| 2022-07-13 00:05:38 [..] Loading c:\muddev\evennia\evennia\server\portal\portal.py...
|Portal| 2022-07-13 00:05:39 [EE] Could not find file-help module world.help_entries (skipping).
|Portal| 2022-07-13 00:05:39 [..] Loaded.
|Portal| 2022-07-13 00:05:39 [..] twistd 21.7.0 (C:\muddev\evenv\Scripts\python.exe 3.9.2) starting up.
|Portal| 2022-07-13 00:05:39 [..] reactor class: twisted.internet.selectreactor.SelectReactor.
|Portal| 2022-07-13 00:05:39 [..] AMP starting on 4006
|Portal| 2022-07-13 00:05:39 [..] Telnet starting on 4000
|Portal| 2022-07-13 00:05:39 [..] Websocket starting on 4002
|Portal| 2022-07-13 00:05:39 [..] Webserver-proxy starting on 4001
|Portal| 2022-07-13 00:05:39 [..] Portal starting server ... 
|Portal| 2022-07-13 00:05:41 [EE] AMP Error from AdminPortal2Server: Traceback (most recent call last):
|Portal| 2022-07-13 00:05:41 [EE] Failure: builtins.Exception: maximum recursion depth exceeded while calling a Python object (error logged on other side)
|Portal| 2022-07-13 00:05:41 [EE]  maximum recursion depth exceeded while calling a Python object (error logged on other side)
|Portal| 2022-07-13 00:05:53 [..] Portal starting server ... 
|Portal| 2022-07-13 00:05:55 [EE] AMP Error from AdminPortal2Server: Traceback (most recent call last):
|Portal| 2022-07-13 00:05:55 [EE] Failure: builtins.Exception: maximum recursion depth exceeded while calling a Python object (error logged on other side)
|Portal| 2022-07-13 00:05:55 [EE]  maximum recursion depth exceeded while calling a Python object (error logged on other side)
|Portal| 2022-07-13 00:06:45 [..] Portal starting server ... 
|Portal| 2022-07-13 00:07:11 [..] Portal starting server ... 
|Portal| 2022-07-13 00:08:08 [..] Portal starting server ... 
|Portal| 2022-07-13 00:08:31 [..] Portal starting server ... 
|Portal| 2022-07-13 00:08:42 [..] Portal starting server ... 
|Portal| 2022-07-13 00:20:57 [..] Portal starting server ... 
|Portal| 2022-07-13 00:21:26 [..] Portal starting server ... 
|Portal| 2022-07-13 00:21:36 [..] Portal starting server ... 
|Portal| 2022-07-13 00:24:18 [..] Portal starting server ... 
|Portal| 2022-07-13 00:26:03 [..] Portal starting server ... 
|Portal| 2022-07-13 00:48:37 [..] Portal starting server ... 
|Portal| 2022-07-13 00:53:38 [..] Portal starting server ... 
|Portal| 2022-07-13 00:56:51 [..] Portal starting server ... 
|Portal| 2022-07-13 15:20:54 [!!] Unhandled Error
	Traceback (most recent call last):
	  File "C:\muddev\evenv\Lib\site-packages\twisted\python\log.py", line 101, in callWithLogger
	    return callWithContext({"system": lp}, func, *args, **kw)
	  File "C:\muddev\evenv\Lib\site-packages\twisted\python\log.py", line 85, in callWithContext
	    return context.call({ILogContext: newCtx}, func, *args, **kw)
	  File "C:\muddev\evenv\Lib\site-packages\twisted\python\context.py", line 118, in callWithContext
	    return self.currentContext().callWithContext(ctx, func, *args, **kw)
	  File "C:\muddev\evenv\Lib\site-packages\twisted\python\context.py", line 83, in callWithContext
	    return func(*args, **kw)
	--- <exception caught here> ---
	  File "C:\muddev\evenv\Lib\site-packages\twisted\internet\selectreactor.py", line 149, in _doReadOrWrite
	    why = getattr(selectable, method)()
	  File "C:\muddev\evenv\Lib\site-packages\twisted\internet\tcp.py", line 247, in doRead
	    return self._dataReceived(data)
	  File "C:\muddev\evenv\Lib\site-packages\twisted\internet\tcp.py", line 252, in _dataReceived
	    rval = self.protocol.dataReceived(data)
	  File "C:\muddev\evenv\Lib\site-packages\twisted\protocols\basic.py", line 554, in dataReceived
	    why = self.rawDataReceived(data)
	  File "C:\muddev\evenv\Lib\site-packages\twisted\web\http.py", line 706, in rawDataReceived
	    self.handleResponseEnd()
	  File "C:\muddev\evenv\Lib\site-packages\twisted\web\proxy.py", line 82, in handleResponseEnd
	    self.father.finish()
	  File "C:\muddev\evenv\Lib\site-packages\twisted\web\server.py", line 279, in finish
	    return http.Request.finish(self)
	  File "C:\muddev\evenv\Lib\site-packages\twisted\web\http.py", line 1131, in finish
	    raise RuntimeError(
	builtins.RuntimeError: Request.finish called on a request after its connection was lost; use Request.notifyFinish to keep track of this.
	
|Portal| 2022-07-13 15:20:54 [!!] Unhandled Error
	Traceback (most recent call last):
	  File "C:\muddev\evenv\Lib\site-packages\twisted\python\log.py", line 101, in callWithLogger
	    return callWithContext({"system": lp}, func, *args, **kw)
	  File "C:\muddev\evenv\Lib\site-packages\twisted\python\log.py", line 85, in callWithContext
	    return context.call({ILogContext: newCtx}, func, *args, **kw)
	  File "C:\muddev\evenv\Lib\site-packages\twisted\python\context.py", line 118, in callWithContext
	    return self.currentContext().callWithContext(ctx, func, *args, **kw)
	  File "C:\muddev\evenv\Lib\site-packages\twisted\python\context.py", line 83, in callWithContext
	    return func(*args, **kw)
	--- <exception caught here> ---
	  File "C:\muddev\evenv\Lib\site-packages\twisted\internet\selectreactor.py", line 149, in _doReadOrWrite
	    why = getattr(selectable, method)()
	  File "C:\muddev\evenv\Lib\site-packages\twisted\internet\tcp.py", line 247, in doRead
	    return self._dataReceived(data)
	  File "C:\muddev\evenv\Lib\site-packages\twisted\internet\tcp.py", line 252, in _dataReceived
	    rval = self.protocol.dataReceived(data)
	  File "C:\muddev\evenv\Lib\site-packages\twisted\protocols\basic.py", line 554, in dataReceived
	    why = self.rawDataReceived(data)
	  File "C:\muddev\evenv\Lib\site-packages\twisted\web\http.py", line 706, in rawDataReceived
	    self.handleResponseEnd()
	  File "C:\muddev\evenv\Lib\site-packages\twisted\web\proxy.py", line 82, in handleResponseEnd
	    self.father.finish()
	  File "C:\muddev\evenv\Lib\site-packages\twisted\web\server.py", line 279, in finish
	    return http.Request.finish(self)
	  File "C:\muddev\evenv\Lib\site-packages\twisted\web\http.py", line 1131, in finish
	    raise RuntimeError(
	builtins.RuntimeError: Request.finish called on a request after its connection was lost; use Request.notifyFinish to keep track of this.
	
|Portal| 2022-07-13 15:20:54 [!!] Unhandled Error
	Traceback (most recent call last):
	  File "C:\muddev\evenv\Lib\site-packages\twisted\python\log.py", line 101, in callWithLogger
	    return callWithContext({"system": lp}, func, *args, **kw)
	  File "C:\muddev\evenv\Lib\site-packages\twisted\python\log.py", line 85, in callWithContext
	    return context.call({ILogContext: newCtx}, func, *args, **kw)
	  File "C:\muddev\evenv\Lib\site-packages\twisted\python\context.py", line 118, in callWithContext
	    return self.currentContext().callWithContext(ctx, func, *args, **kw)
	  File "C:\muddev\evenv\Lib\site-packages\twisted\python\context.py", line 83, in callWithContext
	    return func(*args, **kw)
	--- <exception caught here> ---
	  File "C:\muddev\evenv\Lib\site-packages\twisted\internet\selectreactor.py", line 149, in _doReadOrWrite
	    why = getattr(selectable, method)()
	  File "C:\muddev\evenv\Lib\site-packages\twisted\internet\tcp.py", line 247, in doRead
	    return self._dataReceived(data)
	  File "C:\muddev\evenv\Lib\site-packages\twisted\internet\tcp.py", line 252, in _dataReceived
	    rval = self.protocol.dataReceived(data)
	  File "C:\muddev\evenv\Lib\site-packages\twisted\protocols\basic.py", line 554, in dataReceived
	    why = self.rawDataReceived(data)
	  File "C:\muddev\evenv\Lib\site-packages\twisted\web\http.py", line 706, in rawDataReceived
	    self.handleResponseEnd()
	  File "C:\muddev\evenv\Lib\site-packages\twisted\web\proxy.py", line 82, in handleResponseEnd
	    self.father.finish()
	  File "C:\muddev\evenv\Lib\site-packages\twisted\web\server.py", line 279, in finish
	    return http.Request.finish(self)
	  File "C:\muddev\evenv\Lib\site-packages\twisted\web\http.py", line 1131, in finish
	    raise RuntimeError(
	builtins.RuntimeError: Request.finish called on a request after its connection was lost; use Request.notifyFinish to keep track of this.
	
|Portal| 2022-07-13 15:20:54 [!!] Unhandled Error
	Traceback (most recent call last):
	  File "C:\muddev\evenv\Lib\site-packages\twisted\python\log.py", line 101, in callWithLogger
	    return callWithContext({"system": lp}, func, *args, **kw)
	  File "C:\muddev\evenv\Lib\site-packages\twisted\python\log.py", line 85, in callWithContext
	    return context.call({ILogContext: newCtx}, func, *args, **kw)
	  File "C:\muddev\evenv\Lib\site-packages\twisted\python\context.py", line 118, in callWithContext
	    return self.currentContext().callWithContext(ctx, func, *args, **kw)
	  File "C:\muddev\evenv\Lib\site-packages\twisted\python\context.py", line 83, in callWithContext
	    return func(*args, **kw)
	--- <exception caught here> ---
	  File "C:\muddev\evenv\Lib\site-packages\twisted\internet\selectreactor.py", line 149, in _doReadOrWrite
	    why = getattr(selectable, method)()
	  File "C:\muddev\evenv\Lib\site-packages\twisted\internet\tcp.py", line 247, in doRead
	    return self._dataReceived(data)
	  File "C:\muddev\evenv\Lib\site-packages\twisted\internet\tcp.py", line 252, in _dataReceived
	    rval = self.protocol.dataReceived(data)
	  File "C:\muddev\evenv\Lib\site-packages\twisted\protocols\basic.py", line 554, in dataReceived
	    why = self.rawDataReceived(data)
	  File "C:\muddev\evenv\Lib\site-packages\twisted\web\http.py", line 706, in rawDataReceived
	    self.handleResponseEnd()
	  File "C:\muddev\evenv\Lib\site-packages\twisted\web\proxy.py", line 82, in handleResponseEnd
	    self.father.finish()
	  File "C:\muddev\evenv\Lib\site-packages\twisted\web\server.py", line 279, in finish
	    return http.Request.finish(self)
	  File "C:\muddev\evenv\Lib\site-packages\twisted\web\http.py", line 1131, in finish
	    raise RuntimeError(
	builtins.RuntimeError: Request.finish called on a request after its connection was lost; use Request.notifyFinish to keep track of this.
	
|Portal| 2022-07-13 15:21:54 [..] Timing out client: IPv4Address(type='TCP', host='127.0.0.1', port=63726)
|Portal| 2022-07-14 12:32:23 [!!] Unhandled Error
	Traceback (most recent call last):
	  File "C:\muddev\evenv\Lib\site-packages\twisted\python\log.py", line 101, in callWithLogger
	    return callWithContext({"system": lp}, func, *args, **kw)
	  File "C:\muddev\evenv\Lib\site-packages\twisted\python\log.py", line 85, in callWithContext
	    return context.call({ILogContext: newCtx}, func, *args, **kw)
	  File "C:\muddev\evenv\Lib\site-packages\twisted\python\context.py", line 118, in callWithContext
	    return self.currentContext().callWithContext(ctx, func, *args, **kw)
	  File "C:\muddev\evenv\Lib\site-packages\twisted\python\context.py", line 83, in callWithContext
	    return func(*args, **kw)
	--- <exception caught here> ---
	  File "C:\muddev\evenv\Lib\site-packages\twisted\internet\selectreactor.py", line 149, in _doReadOrWrite
	    why = getattr(selectable, method)()
	  File "C:\muddev\evenv\Lib\site-packages\twisted\internet\tcp.py", line 247, in doRead
	    return self._dataReceived(data)
	  File "C:\muddev\evenv\Lib\site-packages\twisted\internet\tcp.py", line 252, in _dataReceived
	    rval = self.protocol.dataReceived(data)
	  File "C:\muddev\evenv\Lib\site-packages\twisted\protocols\basic.py", line 554, in dataReceived
	    why = self.rawDataReceived(data)
	  File "C:\muddev\evenv\Lib\site-packages\twisted\web\http.py", line 706, in rawDataReceived
	    self.handleResponseEnd()
	  File "C:\muddev\evenv\Lib\site-packages\twisted\web\proxy.py", line 82, in handleResponseEnd
	    self.father.finish()
	  File "C:\muddev\evenv\Lib\site-packages\twisted\web\server.py", line 279, in finish
	    return http.Request.finish(self)
	  File "C:\muddev\evenv\Lib\site-packages\twisted\web\http.py", line 1131, in finish
	    raise RuntimeError(
	builtins.RuntimeError: Request.finish called on a request after its connection was lost; use Request.notifyFinish to keep track of this.
	
|Portal| 2022-07-14 12:32:23 [!!] Unhandled Error
	Traceback (most recent call last):
	  File "C:\muddev\evenv\Lib\site-packages\twisted\python\log.py", line 101, in callWithLogger
	    return callWithContext({"system": lp}, func, *args, **kw)
	  File "C:\muddev\evenv\Lib\site-packages\twisted\python\log.py", line 85, in callWithContext
	    return context.call({ILogContext: newCtx}, func, *args, **kw)
	  File "C:\muddev\evenv\Lib\site-packages\twisted\python\context.py", line 118, in callWithContext
	    return self.currentContext().callWithContext(ctx, func, *args, **kw)
	  File "C:\muddev\evenv\Lib\site-packages\twisted\python\context.py", line 83, in callWithContext
	    return func(*args, **kw)
	--- <exception caught here> ---
	  File "C:\muddev\evenv\Lib\site-packages\twisted\internet\selectreactor.py", line 149, in _doReadOrWrite
	    why = getattr(selectable, method)()
	  File "C:\muddev\evenv\Lib\site-packages\twisted\internet\tcp.py", line 247, in doRead
	    return self._dataReceived(data)
	  File "C:\muddev\evenv\Lib\site-packages\twisted\internet\tcp.py", line 252, in _dataReceived
	    rval = self.protocol.dataReceived(data)
	  File "C:\muddev\evenv\Lib\site-packages\twisted\protocols\basic.py", line 554, in dataReceived
	    why = self.rawDataReceived(data)
	  File "C:\muddev\evenv\Lib\site-packages\twisted\web\http.py", line 706, in rawDataReceived
	    self.handleResponseEnd()
	  File "C:\muddev\evenv\Lib\site-packages\twisted\web\proxy.py", line 82, in handleResponseEnd
	    self.father.finish()
	  File "C:\muddev\evenv\Lib\site-packages\twisted\web\server.py", line 279, in finish
	    return http.Request.finish(self)
	  File "C:\muddev\evenv\Lib\site-packages\twisted\web\http.py", line 1131, in finish
	    raise RuntimeError(
	builtins.RuntimeError: Request.finish called on a request after its connection was lost; use Request.notifyFinish to keep track of this.
	
|Portal| 2022-07-14 12:32:23 [!!] Unhandled Error
	Traceback (most recent call last):
	  File "C:\muddev\evenv\Lib\site-packages\twisted\python\log.py", line 101, in callWithLogger
	    return callWithContext({"system": lp}, func, *args, **kw)
	  File "C:\muddev\evenv\Lib\site-packages\twisted\python\log.py", line 85, in callWithContext
	    return context.call({ILogContext: newCtx}, func, *args, **kw)
	  File "C:\muddev\evenv\Lib\site-packages\twisted\python\context.py", line 118, in callWithContext
	    return self.currentContext().callWithContext(ctx, func, *args, **kw)
	  File "C:\muddev\evenv\Lib\site-packages\twisted\python\context.py", line 83, in callWithContext
	    return func(*args, **kw)
	--- <exception caught here> ---
	  File "C:\muddev\evenv\Lib\site-packages\twisted\internet\selectreactor.py", line 149, in _doReadOrWrite
	    why = getattr(selectable, method)()
	  File "C:\muddev\evenv\Lib\site-packages\twisted\internet\tcp.py", line 247, in doRead
	    return self._dataReceived(data)
	  File "C:\muddev\evenv\Lib\site-packages\twisted\internet\tcp.py", line 252, in _dataReceived
	    rval = self.protocol.dataReceived(data)
	  File "C:\muddev\evenv\Lib\site-packages\twisted\protocols\basic.py", line 554, in dataReceived
	    why = self.rawDataReceived(data)
	  File "C:\muddev\evenv\Lib\site-packages\twisted\web\http.py", line 706, in rawDataReceived
	    self.handleResponseEnd()
	  File "C:\muddev\evenv\Lib\site-packages\twisted\web\proxy.py", line 82, in handleResponseEnd
	    self.father.finish()
	  File "C:\muddev\evenv\Lib\site-packages\twisted\web\server.py", line 279, in finish
	    return http.Request.finish(self)
	  File "C:\muddev\evenv\Lib\site-packages\twisted\web\http.py", line 1131, in finish
	    raise RuntimeError(
	builtins.RuntimeError: Request.finish called on a request after its connection was lost; use Request.notifyFinish to keep track of this.
	
|Portal| 2022-07-14 12:32:23 [!!] Unhandled Error
	Traceback (most recent call last):
	  File "C:\muddev\evenv\Lib\site-packages\twisted\python\log.py", line 101, in callWithLogger
	    return callWithContext({"system": lp}, func, *args, **kw)
	  File "C:\muddev\evenv\Lib\site-packages\twisted\python\log.py", line 85, in callWithContext
	    return context.call({ILogContext: newCtx}, func, *args, **kw)
	  File "C:\muddev\evenv\Lib\site-packages\twisted\python\context.py", line 118, in callWithContext
	    return self.currentContext().callWithContext(ctx, func, *args, **kw)
	  File "C:\muddev\evenv\Lib\site-packages\twisted\python\context.py", line 83, in callWithContext
	    return func(*args, **kw)
	--- <exception caught here> ---
	  File "C:\muddev\evenv\Lib\site-packages\twisted\internet\selectreactor.py", line 149, in _doReadOrWrite
	    why = getattr(selectable, method)()
	  File "C:\muddev\evenv\Lib\site-packages\twisted\internet\tcp.py", line 247, in doRead
	    return self._dataReceived(data)
	  File "C:\muddev\evenv\Lib\site-packages\twisted\internet\tcp.py", line 252, in _dataReceived
	    rval = self.protocol.dataReceived(data)
	  File "C:\muddev\evenv\Lib\site-packages\twisted\protocols\basic.py", line 554, in dataReceived
	    why = self.rawDataReceived(data)
	  File "C:\muddev\evenv\Lib\site-packages\twisted\web\http.py", line 706, in rawDataReceived
	    self.handleResponseEnd()
	  File "C:\muddev\evenv\Lib\site-packages\twisted\web\proxy.py", line 82, in handleResponseEnd
	    self.father.finish()
	  File "C:\muddev\evenv\Lib\site-packages\twisted\web\server.py", line 279, in finish
	    return http.Request.finish(self)
	  File "C:\muddev\evenv\Lib\site-packages\twisted\web\http.py", line 1131, in finish
	    raise RuntimeError(
	builtins.RuntimeError: Request.finish called on a request after its connection was lost; use Request.notifyFinish to keep track of this.
	
|Portal| 2022-07-14 12:32:23 [!!] Unhandled Error
	Traceback (most recent call last):
	  File "C:\muddev\evenv\Lib\site-packages\twisted\python\log.py", line 101, in callWithLogger
	    return callWithContext({"system": lp}, func, *args, **kw)
	  File "C:\muddev\evenv\Lib\site-packages\twisted\python\log.py", line 85, in callWithContext
	    return context.call({ILogContext: newCtx}, func, *args, **kw)
	  File "C:\muddev\evenv\Lib\site-packages\twisted\python\context.py", line 118, in callWithContext
	    return self.currentContext().callWithContext(ctx, func, *args, **kw)
	  File "C:\muddev\evenv\Lib\site-packages\twisted\python\context.py", line 83, in callWithContext
	    return func(*args, **kw)
	--- <exception caught here> ---
	  File "C:\muddev\evenv\Lib\site-packages\twisted\internet\selectreactor.py", line 149, in _doReadOrWrite
	    why = getattr(selectable, method)()
	  File "C:\muddev\evenv\Lib\site-packages\twisted\internet\tcp.py", line 247, in doRead
	    return self._dataReceived(data)
	  File "C:\muddev\evenv\Lib\site-packages\twisted\internet\tcp.py", line 252, in _dataReceived
	    rval = self.protocol.dataReceived(data)
	  File "C:\muddev\evenv\Lib\site-packages\twisted\protocols\basic.py", line 554, in dataReceived
	    why = self.rawDataReceived(data)
	  File "C:\muddev\evenv\Lib\site-packages\twisted\web\http.py", line 706, in rawDataReceived
	    self.handleResponseEnd()
	  File "C:\muddev\evenv\Lib\site-packages\twisted\web\proxy.py", line 82, in handleResponseEnd
	    self.father.finish()
	  File "C:\muddev\evenv\Lib\site-packages\twisted\web\server.py", line 279, in finish
	    return http.Request.finish(self)
	  File "C:\muddev\evenv\Lib\site-packages\twisted\web\http.py", line 1131, in finish
	    raise RuntimeError(
	builtins.RuntimeError: Request.finish called on a request after its connection was lost; use Request.notifyFinish to keep track of this.
	
|Portal| 2022-07-14 12:32:23 [!!] Unhandled Error
	Traceback (most recent call last):
	  File "C:\muddev\evenv\Lib\site-packages\twisted\python\log.py", line 101, in callWithLogger
	    return callWithContext({"system": lp}, func, *args, **kw)
	  File "C:\muddev\evenv\Lib\site-packages\twisted\python\log.py", line 85, in callWithContext
	    return context.call({ILogContext: newCtx}, func, *args, **kw)
	  File "C:\muddev\evenv\Lib\site-packages\twisted\python\context.py", line 118, in callWithContext
	    return self.currentContext().callWithContext(ctx, func, *args, **kw)
	  File "C:\muddev\evenv\Lib\site-packages\twisted\python\context.py", line 83, in callWithContext
	    return func(*args, **kw)
	--- <exception caught here> ---
	  File "C:\muddev\evenv\Lib\site-packages\twisted\internet\selectreactor.py", line 149, in _doReadOrWrite
	    why = getattr(selectable, method)()
	  File "C:\muddev\evenv\Lib\site-packages\twisted\internet\tcp.py", line 247, in doRead
	    return self._dataReceived(data)
	  File "C:\muddev\evenv\Lib\site-packages\twisted\internet\tcp.py", line 252, in _dataReceived
	    rval = self.protocol.dataReceived(data)
	  File "C:\muddev\evenv\Lib\site-packages\twisted\protocols\basic.py", line 554, in dataReceived
	    why = self.rawDataReceived(data)
	  File "C:\muddev\evenv\Lib\site-packages\twisted\web\http.py", line 706, in rawDataReceived
	    self.handleResponseEnd()
	  File "C:\muddev\evenv\Lib\site-packages\twisted\web\proxy.py", line 82, in handleResponseEnd
	    self.father.finish()
	  File "C:\muddev\evenv\Lib\site-packages\twisted\web\server.py", line 279, in finish
	    return http.Request.finish(self)
	  File "C:\muddev\evenv\Lib\site-packages\twisted\web\http.py", line 1131, in finish
	    raise RuntimeError(
	builtins.RuntimeError: Request.finish called on a request after its connection was lost; use Request.notifyFinish to keep track of this.
	
|Portal| 2022-07-14 12:32:23 [!!] Unhandled Error
	Traceback (most recent call last):
	  File "C:\muddev\evenv\Lib\site-packages\twisted\python\log.py", line 101, in callWithLogger
	    return callWithContext({"system": lp}, func, *args, **kw)
	  File "C:\muddev\evenv\Lib\site-packages\twisted\python\log.py", line 85, in callWithContext
	    return context.call({ILogContext: newCtx}, func, *args, **kw)
	  File "C:\muddev\evenv\Lib\site-packages\twisted\python\context.py", line 118, in callWithContext
	    return self.currentContext().callWithContext(ctx, func, *args, **kw)
	  File "C:\muddev\evenv\Lib\site-packages\twisted\python\context.py", line 83, in callWithContext
	    return func(*args, **kw)
	--- <exception caught here> ---
	  File "C:\muddev\evenv\Lib\site-packages\twisted\internet\selectreactor.py", line 149, in _doReadOrWrite
	    why = getattr(selectable, method)()
	  File "C:\muddev\evenv\Lib\site-packages\twisted\internet\tcp.py", line 247, in doRead
	    return self._dataReceived(data)
	  File "C:\muddev\evenv\Lib\site-packages\twisted\internet\tcp.py", line 252, in _dataReceived
	    rval = self.protocol.dataReceived(data)
	  File "C:\muddev\evenv\Lib\site-packages\twisted\protocols\basic.py", line 554, in dataReceived
	    why = self.rawDataReceived(data)
	  File "C:\muddev\evenv\Lib\site-packages\twisted\web\http.py", line 706, in rawDataReceived
	    self.handleResponseEnd()
	  File "C:\muddev\evenv\Lib\site-packages\twisted\web\proxy.py", line 82, in handleResponseEnd
	    self.father.finish()
	  File "C:\muddev\evenv\Lib\site-packages\twisted\web\server.py", line 279, in finish
	    return http.Request.finish(self)
	  File "C:\muddev\evenv\Lib\site-packages\twisted\web\http.py", line 1131, in finish
	    raise RuntimeError(
	builtins.RuntimeError: Request.finish called on a request after its connection was lost; use Request.notifyFinish to keep track of this.
	
|Portal| 2022-07-14 12:32:23 [!!] Unhandled Error
	Traceback (most recent call last):
	  File "C:\muddev\evenv\Lib\site-packages\twisted\python\log.py", line 101, in callWithLogger
	    return callWithContext({"system": lp}, func, *args, **kw)
	  File "C:\muddev\evenv\Lib\site-packages\twisted\python\log.py", line 85, in callWithContext
	    return context.call({ILogContext: newCtx}, func, *args, **kw)
	  File "C:\muddev\evenv\Lib\site-packages\twisted\python\context.py", line 118, in callWithContext
	    return self.currentContext().callWithContext(ctx, func, *args, **kw)
	  File "C:\muddev\evenv\Lib\site-packages\twisted\python\context.py", line 83, in callWithContext
	    return func(*args, **kw)
	--- <exception caught here> ---
	  File "C:\muddev\evenv\Lib\site-packages\twisted\internet\selectreactor.py", line 149, in _doReadOrWrite
	    why = getattr(selectable, method)()
	  File "C:\muddev\evenv\Lib\site-packages\twisted\internet\tcp.py", line 247, in doRead
	    return self._dataReceived(data)
	  File "C:\muddev\evenv\Lib\site-packages\twisted\internet\tcp.py", line 252, in _dataReceived
	    rval = self.protocol.dataReceived(data)
	  File "C:\muddev\evenv\Lib\site-packages\twisted\protocols\basic.py", line 554, in dataReceived
	    why = self.rawDataReceived(data)
	  File "C:\muddev\evenv\Lib\site-packages\twisted\web\http.py", line 706, in rawDataReceived
	    self.handleResponseEnd()
	  File "C:\muddev\evenv\Lib\site-packages\twisted\web\proxy.py", line 82, in handleResponseEnd
	    self.father.finish()
	  File "C:\muddev\evenv\Lib\site-packages\twisted\web\server.py", line 279, in finish
	    return http.Request.finish(self)
	  File "C:\muddev\evenv\Lib\site-packages\twisted\web\http.py", line 1131, in finish
	    raise RuntimeError(
	builtins.RuntimeError: Request.finish called on a request after its connection was lost; use Request.notifyFinish to keep track of this.
	
|Portal| 2022-07-14 12:32:23 [!!] Unhandled Error
	Traceback (most recent call last):
	  File "C:\muddev\evenv\Lib\site-packages\twisted\python\log.py", line 101, in callWithLogger
	    return callWithContext({"system": lp}, func, *args, **kw)
	  File "C:\muddev\evenv\Lib\site-packages\twisted\python\log.py", line 85, in callWithContext
	    return context.call({ILogContext: newCtx}, func, *args, **kw)
	  File "C:\muddev\evenv\Lib\site-packages\twisted\python\context.py", line 118, in callWithContext
	    return self.currentContext().callWithContext(ctx, func, *args, **kw)
	  File "C:\muddev\evenv\Lib\site-packages\twisted\python\context.py", line 83, in callWithContext
	    return func(*args, **kw)
	--- <exception caught here> ---
	  File "C:\muddev\evenv\Lib\site-packages\twisted\internet\selectreactor.py", line 149, in _doReadOrWrite
	    why = getattr(selectable, method)()
	  File "C:\muddev\evenv\Lib\site-packages\twisted\internet\tcp.py", line 247, in doRead
	    return self._dataReceived(data)
	  File "C:\muddev\evenv\Lib\site-packages\twisted\internet\tcp.py", line 252, in _dataReceived
	    rval = self.protocol.dataReceived(data)
	  File "C:\muddev\evenv\Lib\site-packages\twisted\protocols\basic.py", line 554, in dataReceived
	    why = self.rawDataReceived(data)
	  File "C:\muddev\evenv\Lib\site-packages\twisted\web\http.py", line 706, in rawDataReceived
	    self.handleResponseEnd()
	  File "C:\muddev\evenv\Lib\site-packages\twisted\web\proxy.py", line 82, in handleResponseEnd
	    self.father.finish()
	  File "C:\muddev\evenv\Lib\site-packages\twisted\web\server.py", line 279, in finish
	    return http.Request.finish(self)
	  File "C:\muddev\evenv\Lib\site-packages\twisted\web\http.py", line 1131, in finish
	    raise RuntimeError(
	builtins.RuntimeError: Request.finish called on a request after its connection was lost; use Request.notifyFinish to keep track of this.
	
|Portal| 2022-07-14 12:33:23 [..] Timing out client: IPv4Address(type='TCP', host='127.0.0.1', port=58163)
|Portal| 2022-07-14 12:35:26 [!!] Unhandled Error
	Traceback (most recent call last):
	  File "C:\muddev\evenv\Lib\site-packages\twisted\python\log.py", line 101, in callWithLogger
	    return callWithContext({"system": lp}, func, *args, **kw)
	  File "C:\muddev\evenv\Lib\site-packages\twisted\python\log.py", line 85, in callWithContext
	    return context.call({ILogContext: newCtx}, func, *args, **kw)
	  File "C:\muddev\evenv\Lib\site-packages\twisted\python\context.py", line 118, in callWithContext
	    return self.currentContext().callWithContext(ctx, func, *args, **kw)
	  File "C:\muddev\evenv\Lib\site-packages\twisted\python\context.py", line 83, in callWithContext
	    return func(*args, **kw)
	--- <exception caught here> ---
	  File "C:\muddev\evenv\Lib\site-packages\twisted\internet\selectreactor.py", line 149, in _doReadOrWrite
	    why = getattr(selectable, method)()
	  File "C:\muddev\evenv\Lib\site-packages\twisted\internet\tcp.py", line 247, in doRead
	    return self._dataReceived(data)
	  File "C:\muddev\evenv\Lib\site-packages\twisted\internet\tcp.py", line 252, in _dataReceived
	    rval = self.protocol.dataReceived(data)
	  File "C:\muddev\evenv\Lib\site-packages\twisted\protocols\basic.py", line 554, in dataReceived
	    why = self.rawDataReceived(data)
	  File "C:\muddev\evenv\Lib\site-packages\twisted\web\http.py", line 706, in rawDataReceived
	    self.handleResponseEnd()
	  File "C:\muddev\evenv\Lib\site-packages\twisted\web\proxy.py", line 82, in handleResponseEnd
	    self.father.finish()
	  File "C:\muddev\evenv\Lib\site-packages\twisted\web\server.py", line 279, in finish
	    return http.Request.finish(self)
	  File "C:\muddev\evenv\Lib\site-packages\twisted\web\http.py", line 1131, in finish
	    raise RuntimeError(
	builtins.RuntimeError: Request.finish called on a request after its connection was lost; use Request.notifyFinish to keep track of this.
	
|Portal| 2022-07-14 12:36:27 [..] Timing out client: IPv4Address(type='TCP', host='127.0.0.1', port=58239)
|Portal| 2022-07-15 12:19:56 [!!] Unhandled Error
	Traceback (most recent call last):
	  File "C:\muddev\evenv\Lib\site-packages\twisted\python\log.py", line 101, in callWithLogger
	    return callWithContext({"system": lp}, func, *args, **kw)
	  File "C:\muddev\evenv\Lib\site-packages\twisted\python\log.py", line 85, in callWithContext
	    return context.call({ILogContext: newCtx}, func, *args, **kw)
	  File "C:\muddev\evenv\Lib\site-packages\twisted\python\context.py", line 118, in callWithContext
	    return self.currentContext().callWithContext(ctx, func, *args, **kw)
	  File "C:\muddev\evenv\Lib\site-packages\twisted\python\context.py", line 83, in callWithContext
	    return func(*args, **kw)
	--- <exception caught here> ---
	  File "C:\muddev\evenv\Lib\site-packages\twisted\internet\selectreactor.py", line 149, in _doReadOrWrite
	    why = getattr(selectable, method)()
	  File "C:\muddev\evenv\Lib\site-packages\twisted\internet\tcp.py", line 247, in doRead
	    return self._dataReceived(data)
	  File "C:\muddev\evenv\Lib\site-packages\twisted\internet\tcp.py", line 252, in _dataReceived
	    rval = self.protocol.dataReceived(data)
	  File "C:\muddev\evenv\Lib\site-packages\twisted\protocols\basic.py", line 554, in dataReceived
	    why = self.rawDataReceived(data)
	  File "C:\muddev\evenv\Lib\site-packages\twisted\web\http.py", line 706, in rawDataReceived
	    self.handleResponseEnd()
	  File "C:\muddev\evenv\Lib\site-packages\twisted\web\proxy.py", line 82, in handleResponseEnd
	    self.father.finish()
	  File "C:\muddev\evenv\Lib\site-packages\twisted\web\server.py", line 279, in finish
	    return http.Request.finish(self)
	  File "C:\muddev\evenv\Lib\site-packages\twisted\web\http.py", line 1131, in finish
	    raise RuntimeError(
	builtins.RuntimeError: Request.finish called on a request after its connection was lost; use Request.notifyFinish to keep track of this.
	
|Portal| 2022-07-15 12:19:56 [!!] Unhandled Error
	Traceback (most recent call last):
	  File "C:\muddev\evenv\Lib\site-packages\twisted\python\log.py", line 101, in callWithLogger
	    return callWithContext({"system": lp}, func, *args, **kw)
	  File "C:\muddev\evenv\Lib\site-packages\twisted\python\log.py", line 85, in callWithContext
	    return context.call({ILogContext: newCtx}, func, *args, **kw)
	  File "C:\muddev\evenv\Lib\site-packages\twisted\python\context.py", line 118, in callWithContext
	    return self.currentContext().callWithContext(ctx, func, *args, **kw)
	  File "C:\muddev\evenv\Lib\site-packages\twisted\python\context.py", line 83, in callWithContext
	    return func(*args, **kw)
	--- <exception caught here> ---
	  File "C:\muddev\evenv\Lib\site-packages\twisted\internet\selectreactor.py", line 149, in _doReadOrWrite
	    why = getattr(selectable, method)()
	  File "C:\muddev\evenv\Lib\site-packages\twisted\internet\tcp.py", line 247, in doRead
	    return self._dataReceived(data)
	  File "C:\muddev\evenv\Lib\site-packages\twisted\internet\tcp.py", line 252, in _dataReceived
	    rval = self.protocol.dataReceived(data)
	  File "C:\muddev\evenv\Lib\site-packages\twisted\protocols\basic.py", line 554, in dataReceived
	    why = self.rawDataReceived(data)
	  File "C:\muddev\evenv\Lib\site-packages\twisted\web\http.py", line 706, in rawDataReceived
	    self.handleResponseEnd()
	  File "C:\muddev\evenv\Lib\site-packages\twisted\web\proxy.py", line 82, in handleResponseEnd
	    self.father.finish()
	  File "C:\muddev\evenv\Lib\site-packages\twisted\web\server.py", line 279, in finish
	    return http.Request.finish(self)
	  File "C:\muddev\evenv\Lib\site-packages\twisted\web\http.py", line 1131, in finish
	    raise RuntimeError(
	builtins.RuntimeError: Request.finish called on a request after its connection was lost; use Request.notifyFinish to keep track of this.
	
|Portal| 2022-07-15 12:19:56 [!!] Unhandled Error
	Traceback (most recent call last):
	  File "C:\muddev\evenv\Lib\site-packages\twisted\python\log.py", line 101, in callWithLogger
	    return callWithContext({"system": lp}, func, *args, **kw)
	  File "C:\muddev\evenv\Lib\site-packages\twisted\python\log.py", line 85, in callWithContext
	    return context.call({ILogContext: newCtx}, func, *args, **kw)
	  File "C:\muddev\evenv\Lib\site-packages\twisted\python\context.py", line 118, in callWithContext
	    return self.currentContext().callWithContext(ctx, func, *args, **kw)
	  File "C:\muddev\evenv\Lib\site-packages\twisted\python\context.py", line 83, in callWithContext
	    return func(*args, **kw)
	--- <exception caught here> ---
	  File "C:\muddev\evenv\Lib\site-packages\twisted\internet\selectreactor.py", line 149, in _doReadOrWrite
	    why = getattr(selectable, method)()
	  File "C:\muddev\evenv\Lib\site-packages\twisted\internet\tcp.py", line 247, in doRead
	    return self._dataReceived(data)
	  File "C:\muddev\evenv\Lib\site-packages\twisted\internet\tcp.py", line 252, in _dataReceived
	    rval = self.protocol.dataReceived(data)
	  File "C:\muddev\evenv\Lib\site-packages\twisted\protocols\basic.py", line 554, in dataReceived
	    why = self.rawDataReceived(data)
	  File "C:\muddev\evenv\Lib\site-packages\twisted\web\http.py", line 706, in rawDataReceived
	    self.handleResponseEnd()
	  File "C:\muddev\evenv\Lib\site-packages\twisted\web\proxy.py", line 82, in handleResponseEnd
	    self.father.finish()
	  File "C:\muddev\evenv\Lib\site-packages\twisted\web\server.py", line 279, in finish
	    return http.Request.finish(self)
	  File "C:\muddev\evenv\Lib\site-packages\twisted\web\http.py", line 1131, in finish
	    raise RuntimeError(
	builtins.RuntimeError: Request.finish called on a request after its connection was lost; use Request.notifyFinish to keep track of this.
	
|Portal| 2022-07-15 12:19:56 [!!] Unhandled Error
	Traceback (most recent call last):
	  File "C:\muddev\evenv\Lib\site-packages\twisted\python\log.py", line 101, in callWithLogger
	    return callWithContext({"system": lp}, func, *args, **kw)
	  File "C:\muddev\evenv\Lib\site-packages\twisted\python\log.py", line 85, in callWithContext
	    return context.call({ILogContext: newCtx}, func, *args, **kw)
	  File "C:\muddev\evenv\Lib\site-packages\twisted\python\context.py", line 118, in callWithContext
	    return self.currentContext().callWithContext(ctx, func, *args, **kw)
	  File "C:\muddev\evenv\Lib\site-packages\twisted\python\context.py", line 83, in callWithContext
	    return func(*args, **kw)
	--- <exception caught here> ---
	  File "C:\muddev\evenv\Lib\site-packages\twisted\internet\selectreactor.py", line 149, in _doReadOrWrite
	    why = getattr(selectable, method)()
	  File "C:\muddev\evenv\Lib\site-packages\twisted\internet\tcp.py", line 247, in doRead
	    return self._dataReceived(data)
	  File "C:\muddev\evenv\Lib\site-packages\twisted\internet\tcp.py", line 252, in _dataReceived
	    rval = self.protocol.dataReceived(data)
	  File "C:\muddev\evenv\Lib\site-packages\twisted\protocols\basic.py", line 554, in dataReceived
	    why = self.rawDataReceived(data)
	  File "C:\muddev\evenv\Lib\site-packages\twisted\web\http.py", line 706, in rawDataReceived
	    self.handleResponseEnd()
	  File "C:\muddev\evenv\Lib\site-packages\twisted\web\proxy.py", line 82, in handleResponseEnd
	    self.father.finish()
	  File "C:\muddev\evenv\Lib\site-packages\twisted\web\server.py", line 279, in finish
	    return http.Request.finish(self)
	  File "C:\muddev\evenv\Lib\site-packages\twisted\web\http.py", line 1131, in finish
	    raise RuntimeError(
	builtins.RuntimeError: Request.finish called on a request after its connection was lost; use Request.notifyFinish to keep track of this.
	
|Portal| 2022-07-15 12:22:55 [..] Portal starting server ... 
|Portal| 2022-07-15 12:22:57 [EE] AMP Error from AdminPortal2Server: Traceback (most recent call last):
|Portal| 2022-07-15 12:22:57 [EE] Failure: builtins.Exception: maximum recursion depth exceeded while calling a Python object (error logged on other side)
|Portal| 2022-07-15 12:22:57 [EE]  maximum recursion depth exceeded while calling a Python object (error logged on other side)
|Portal| 2022-07-15 13:31:06 [..] Portal starting server ... 
|Portal| 2022-07-15 13:31:07 [EE] AMP Error from AdminPortal2Server: Traceback (most recent call last):
|Portal| 2022-07-15 13:31:07 [EE] Failure: builtins.Exception: maximum recursion depth exceeded while calling a Python object (error logged on other side)
|Portal| 2022-07-15 13:31:07 [EE]  maximum recursion depth exceeded while calling a Python object (error logged on other side)
|Portal| 2022-07-15 13:31:15 [..] Portal starting server ... 
|Portal| 2022-07-15 13:31:16 [EE] AMP Error from AdminPortal2Server: Traceback (most recent call last):
|Portal| 2022-07-15 13:31:16 [EE] Failure: builtins.Exception: maximum recursion depth exceeded while calling a Python object (error logged on other side)
|Portal| 2022-07-15 13:31:16 [EE]  maximum recursion depth exceeded while calling a Python object (error logged on other side)
|Portal| 2022-07-15 13:31:34 [..] Portal starting server ... 
|Portal| 2022-07-15 13:31:35 [EE] AMP Error from AdminPortal2Server: Traceback (most recent call last):
|Portal| 2022-07-15 13:31:35 [EE] Failure: builtins.Exception: maximum recursion depth exceeded while calling a Python object (error logged on other side)
|Portal| 2022-07-15 13:31:35 [EE]  maximum recursion depth exceeded while calling a Python object (error logged on other side)
|Portal| 2022-07-15 13:33:01 [..] Portal starting server ... 
|Portal| 2022-07-15 13:33:02 [EE] AMP Error from AdminPortal2Server: Traceback (most recent call last):
|Portal| 2022-07-15 13:33:02 [EE] Failure: builtins.Exception: maximum recursion depth exceeded while calling a Python object (error logged on other side)
|Portal| 2022-07-15 13:33:02 [EE]  maximum recursion depth exceeded while calling a Python object (error logged on other side)
|Portal| 2022-07-15 13:34:56 [..] Portal starting server ... 
|Portal| 2022-07-15 13:34:56 [EE] AMP Error from b'MsgPortal2Server': Traceback (most recent call last):
|Portal| 2022-07-15 13:34:56 [EE] --- <exception caught here> ---
|Portal| 2022-07-15 13:34:56 [EE]   File "C:\muddev\evenv\Lib\site-packages\twisted\internet\defer.py", line 858, in _runCallbacks
|Portal| 2022-07-15 13:34:56 [EE]     current.result = callback(  # type: ignore[misc]
|Portal| 2022-07-15 13:34:56 [EE]   File "C:\muddev\evenv\Lib\site-packages\twisted\protocols\amp.py", line 1947, in _massageError
|Portal| 2022-07-15 13:34:56 [EE]     error.trap(RemoteAmpError)
|Portal| 2022-07-15 13:34:56 [EE]   File "C:\muddev\evenv\Lib\site-packages\twisted\python\failure.py", line 450, in trap
|Portal| 2022-07-15 13:34:56 [EE]     self.raiseException()
|Portal| 2022-07-15 13:34:56 [EE]   File "C:\muddev\evenv\Lib\site-packages\twisted\python\failure.py", line 475, in raiseException
|Portal| 2022-07-15 13:34:56 [EE]     raise self.value.with_traceback(self.tb)
|Portal| 2022-07-15 13:34:56 [EE] twisted.protocols.amp.UnhandledCommand: (b'UNHANDLED', "Unhandled Command: b'MsgPortal2Server'")
|Portal| 2022-07-15 13:34:56 [EE]  (b'UNHANDLED', "Unhandled Command: b'MsgPortal2Server'")
|Portal| 2022-07-15 13:35:06 [..] Portal starting server ... 
|Portal| 2022-07-15 13:35:52 [..] Portal starting server ... 
|Portal| 2022-07-15 13:35:53 [EE] AMP Error from AdminPortal2Server: Traceback (most recent call last):
|Portal| 2022-07-15 13:35:53 [EE] Failure: builtins.Exception: local variable '_owner' referenced before assignment (error logged on other side)
|Portal| 2022-07-15 13:35:53 [EE]  local variable '_owner' referenced before assignment (error logged on other side)
|Portal| 2022-07-15 13:36:05 [..] Portal starting server ... 
|Portal| 2022-07-15 14:30:22 [..] Portal starting server ... 
|Portal| 2022-07-15 14:31:41 [..] Portal starting server ... 
|Portal| 2022-07-15 14:37:18 [..] Portal starting server ... 
|Portal| 2022-07-16 16:13:56 [..] Portal starting server ... 
|Portal| 2022-07-16 16:14:37 [..] Portal starting server ... 
|Portal| 2022-07-16 16:16:13 [..] Portal starting server ... 
|Portal| 2022-07-18 14:07:59 [..] (TCP Port 4001 Closed)
|Portal| 2022-07-18 14:07:59 [..] (TCP Port 4000 Closed)
|Portal| 2022-07-18 14:07:59 [..] (TCP Port 4006 Closed)
|Portal| 2022-07-18 14:07:59 [..] (TCP Port 4002 Closed)
|Portal| 2022-07-18 14:07:59 [..] Main loop terminated.
|Portal| 2022-07-18 14:07:59 [..] Server Shut Down.
|Portal| 2022-07-18 14:07:59 [..] Server Shut Down.
|Portal| 2022-07-18 14:14:12 [..] Loaded.
|Portal| 2022-07-18 14:14:12 [..] Loading c:\muddev\evennia\evennia\server\portal\portal.py...
|Portal| 2022-07-18 14:14:12 [EE] Could not find file-help module world.help_entries (skipping).
|Portal| 2022-07-18 14:14:12 [..] Loaded.
|Portal| 2022-07-18 14:14:12 [..] twistd 21.7.0 (C:\muddev\evenv\Scripts\python.exe 3.9.2) starting up.
|Portal| 2022-07-18 14:14:12 [..] reactor class: twisted.internet.selectreactor.SelectReactor.
|Portal| 2022-07-18 14:14:12 [..] AMP starting on 4006
|Portal| 2022-07-18 14:14:12 [..] Telnet starting on 4000
|Portal| 2022-07-18 14:14:12 [..] Websocket starting on 4002
|Portal| 2022-07-18 14:14:12 [..] Webserver-proxy starting on 4001
|Portal| 2022-07-18 14:14:13 [..] Portal starting server ... 
|Portal| 2022-07-21 21:59:20 [..] Loaded.
|Portal| 2022-07-21 21:59:19 [..] Loading c:\muddev\evennia\evennia\server\portal\portal.py...
|Portal| 2022-07-21 21:59:19 [EE] Could not find file-help module world.help_entries (skipping).
|Portal| 2022-07-21 21:59:20 [..] Loaded.
|Portal| 2022-07-21 21:59:20 [..] twistd 21.7.0 (C:\muddev\evenv\Scripts\python.exe 3.9.2) starting up.
|Portal| 2022-07-21 21:59:20 [..] reactor class: twisted.internet.selectreactor.SelectReactor.
|Portal| 2022-07-21 21:59:20 [..] AMP starting on 4006
|Portal| 2022-07-21 21:59:20 [..] Telnet starting on 4000
|Portal| 2022-07-21 21:59:20 [..] Websocket starting on 4002
|Portal| 2022-07-21 21:59:20 [..] Webserver-proxy starting on 4001
|Portal| 2022-07-21 21:59:20 [..] Portal starting server ... 
|Portal| 2022-07-22 13:39:26 [..] Timing out client: IPv4Address(type='TCP', host='127.0.0.1', port=55275)
|Portal| 2022-07-22 13:39:26 [..] Timing out client: IPv4Address(type='TCP', host='127.0.0.1', port=55278)
|Portal| 2022-07-22 13:39:26 [..] Timing out client: IPv4Address(type='TCP', host='127.0.0.1', port=55280)
|Portal| 2022-07-22 13:39:26 [..] Timing out client: IPv4Address(type='TCP', host='127.0.0.1', port=55281)
|Portal| 2022-07-22 13:39:27 [..] Timing out client: IPv4Address(type='TCP', host='127.0.0.1', port=55277)
|Portal| 2022-07-22 13:39:27 [..] Timing out client: IPv4Address(type='TCP', host='127.0.0.1', port=55273)
|Portal| 2022-07-22 13:39:59 [..] Portal starting server ... 
|Portal| 2022-07-22 13:45:48 [..] Portal starting server ... 
|Portal| 2022-07-22 13:46:17 [..] Portal starting server ... 
|Portal| 2022-07-22 14:05:13 [..] Portal starting server ... 
|Portal| 2022-07-22 14:09:07 [..] Portal starting server ... 
|Portal| 2022-07-22 14:10:28 [..] Portal starting server ... 
|Portal| 2022-07-22 14:12:16 [..] (TCP Port 4001 Closed)
|Portal| 2022-07-22 14:12:16 [..] (TCP Port 4000 Closed)
|Portal| 2022-07-22 14:12:16 [..] (TCP Port 4006 Closed)
|Portal| 2022-07-22 14:12:16 [..] (TCP Port 4002 Closed)
|Portal| 2022-07-22 14:12:16 [..] Main loop terminated.
|Portal| 2022-07-22 14:12:16 [..] Server Shut Down.
|Portal| 2022-07-22 14:12:16 [..] Server Shut Down.
|Portal| 2022-07-22 14:16:03 [..] Loaded.
|Portal| 2022-07-22 14:16:02 [..] Loading c:\muddev\evennia\evennia\server\portal\portal.py...
|Portal| 2022-07-22 14:16:02 [EE] Could not find file-help module world.help_entries (skipping).
|Portal| 2022-07-22 14:16:03 [..] Loaded.
|Portal| 2022-07-22 14:16:03 [..] twistd 21.7.0 (C:\muddev\evenv\Scripts\python.exe 3.9.2) starting up.
|Portal| 2022-07-22 14:16:03 [..] reactor class: twisted.internet.selectreactor.SelectReactor.
|Portal| 2022-07-22 14:16:03 [..] AMP starting on 4006
|Portal| 2022-07-22 14:16:03 [..] Telnet starting on 4000
|Portal| 2022-07-22 14:16:03 [..] Websocket starting on 4002
|Portal| 2022-07-22 14:16:03 [..] Webserver-proxy starting on 4001
|Portal| 2022-07-22 14:16:03 [..] Portal starting server ... 
|Portal| 2022-07-22 14:24:17 [..] Portal starting server ... 
|Portal| 2022-07-22 14:26:12 [!!] Unhandled Error
	Traceback (most recent call last):
	  File "C:\muddev\evenv\Lib\site-packages\twisted\python\log.py", line 101, in callWithLogger
	    return callWithContext({"system": lp}, func, *args, **kw)
	  File "C:\muddev\evenv\Lib\site-packages\twisted\python\log.py", line 85, in callWithContext
	    return context.call({ILogContext: newCtx}, func, *args, **kw)
	  File "C:\muddev\evenv\Lib\site-packages\twisted\python\context.py", line 118, in callWithContext
	    return self.currentContext().callWithContext(ctx, func, *args, **kw)
	  File "C:\muddev\evenv\Lib\site-packages\twisted\python\context.py", line 83, in callWithContext
	    return func(*args, **kw)
	--- <exception caught here> ---
	  File "C:\muddev\evenv\Lib\site-packages\twisted\internet\selectreactor.py", line 149, in _doReadOrWrite
	    why = getattr(selectable, method)()
	  File "C:\muddev\evenv\Lib\site-packages\twisted\internet\tcp.py", line 247, in doRead
	    return self._dataReceived(data)
	  File "C:\muddev\evenv\Lib\site-packages\twisted\internet\tcp.py", line 252, in _dataReceived
	    rval = self.protocol.dataReceived(data)
	  File "C:\muddev\evenv\Lib\site-packages\twisted\protocols\basic.py", line 554, in dataReceived
	    why = self.rawDataReceived(data)
	  File "C:\muddev\evenv\Lib\site-packages\twisted\web\http.py", line 706, in rawDataReceived
	    self.handleResponseEnd()
	  File "C:\muddev\evenv\Lib\site-packages\twisted\web\proxy.py", line 82, in handleResponseEnd
	    self.father.finish()
	  File "C:\muddev\evenv\Lib\site-packages\twisted\web\server.py", line 279, in finish
	    return http.Request.finish(self)
	  File "C:\muddev\evenv\Lib\site-packages\twisted\web\http.py", line 1131, in finish
	    raise RuntimeError(
	builtins.RuntimeError: Request.finish called on a request after its connection was lost; use Request.notifyFinish to keep track of this.
	
|Portal| 2022-07-22 14:26:12 [!!] Unhandled Error
	Traceback (most recent call last):
	  File "C:\muddev\evenv\Lib\site-packages\twisted\python\log.py", line 101, in callWithLogger
	    return callWithContext({"system": lp}, func, *args, **kw)
	  File "C:\muddev\evenv\Lib\site-packages\twisted\python\log.py", line 85, in callWithContext
	    return context.call({ILogContext: newCtx}, func, *args, **kw)
	  File "C:\muddev\evenv\Lib\site-packages\twisted\python\context.py", line 118, in callWithContext
	    return self.currentContext().callWithContext(ctx, func, *args, **kw)
	  File "C:\muddev\evenv\Lib\site-packages\twisted\python\context.py", line 83, in callWithContext
	    return func(*args, **kw)
	--- <exception caught here> ---
	  File "C:\muddev\evenv\Lib\site-packages\twisted\internet\selectreactor.py", line 149, in _doReadOrWrite
	    why = getattr(selectable, method)()
	  File "C:\muddev\evenv\Lib\site-packages\twisted\internet\tcp.py", line 247, in doRead
	    return self._dataReceived(data)
	  File "C:\muddev\evenv\Lib\site-packages\twisted\internet\tcp.py", line 252, in _dataReceived
	    rval = self.protocol.dataReceived(data)
	  File "C:\muddev\evenv\Lib\site-packages\twisted\protocols\basic.py", line 554, in dataReceived
	    why = self.rawDataReceived(data)
	  File "C:\muddev\evenv\Lib\site-packages\twisted\web\http.py", line 706, in rawDataReceived
	    self.handleResponseEnd()
	  File "C:\muddev\evenv\Lib\site-packages\twisted\web\proxy.py", line 82, in handleResponseEnd
	    self.father.finish()
	  File "C:\muddev\evenv\Lib\site-packages\twisted\web\server.py", line 279, in finish
	    return http.Request.finish(self)
	  File "C:\muddev\evenv\Lib\site-packages\twisted\web\http.py", line 1131, in finish
	    raise RuntimeError(
	builtins.RuntimeError: Request.finish called on a request after its connection was lost; use Request.notifyFinish to keep track of this.
	
|Portal| 2022-07-22 14:26:12 [!!] Unhandled Error
	Traceback (most recent call last):
	  File "C:\muddev\evenv\Lib\site-packages\twisted\python\log.py", line 101, in callWithLogger
	    return callWithContext({"system": lp}, func, *args, **kw)
	  File "C:\muddev\evenv\Lib\site-packages\twisted\python\log.py", line 85, in callWithContext
	    return context.call({ILogContext: newCtx}, func, *args, **kw)
	  File "C:\muddev\evenv\Lib\site-packages\twisted\python\context.py", line 118, in callWithContext
	    return self.currentContext().callWithContext(ctx, func, *args, **kw)
	  File "C:\muddev\evenv\Lib\site-packages\twisted\python\context.py", line 83, in callWithContext
	    return func(*args, **kw)
	--- <exception caught here> ---
	  File "C:\muddev\evenv\Lib\site-packages\twisted\internet\selectreactor.py", line 149, in _doReadOrWrite
	    why = getattr(selectable, method)()
	  File "C:\muddev\evenv\Lib\site-packages\twisted\internet\tcp.py", line 247, in doRead
	    return self._dataReceived(data)
	  File "C:\muddev\evenv\Lib\site-packages\twisted\internet\tcp.py", line 252, in _dataReceived
	    rval = self.protocol.dataReceived(data)
	  File "C:\muddev\evenv\Lib\site-packages\twisted\protocols\basic.py", line 554, in dataReceived
	    why = self.rawDataReceived(data)
	  File "C:\muddev\evenv\Lib\site-packages\twisted\web\http.py", line 706, in rawDataReceived
	    self.handleResponseEnd()
	  File "C:\muddev\evenv\Lib\site-packages\twisted\web\proxy.py", line 82, in handleResponseEnd
	    self.father.finish()
	  File "C:\muddev\evenv\Lib\site-packages\twisted\web\server.py", line 279, in finish
	    return http.Request.finish(self)
	  File "C:\muddev\evenv\Lib\site-packages\twisted\web\http.py", line 1131, in finish
	    raise RuntimeError(
	builtins.RuntimeError: Request.finish called on a request after its connection was lost; use Request.notifyFinish to keep track of this.
	
|Portal| 2022-07-22 14:26:12 [!!] Unhandled Error
	Traceback (most recent call last):
	  File "C:\muddev\evenv\Lib\site-packages\twisted\python\log.py", line 101, in callWithLogger
	    return callWithContext({"system": lp}, func, *args, **kw)
	  File "C:\muddev\evenv\Lib\site-packages\twisted\python\log.py", line 85, in callWithContext
	    return context.call({ILogContext: newCtx}, func, *args, **kw)
	  File "C:\muddev\evenv\Lib\site-packages\twisted\python\context.py", line 118, in callWithContext
	    return self.currentContext().callWithContext(ctx, func, *args, **kw)
	  File "C:\muddev\evenv\Lib\site-packages\twisted\python\context.py", line 83, in callWithContext
	    return func(*args, **kw)
	--- <exception caught here> ---
	  File "C:\muddev\evenv\Lib\site-packages\twisted\internet\selectreactor.py", line 149, in _doReadOrWrite
	    why = getattr(selectable, method)()
	  File "C:\muddev\evenv\Lib\site-packages\twisted\internet\tcp.py", line 247, in doRead
	    return self._dataReceived(data)
	  File "C:\muddev\evenv\Lib\site-packages\twisted\internet\tcp.py", line 252, in _dataReceived
	    rval = self.protocol.dataReceived(data)
	  File "C:\muddev\evenv\Lib\site-packages\twisted\protocols\basic.py", line 554, in dataReceived
	    why = self.rawDataReceived(data)
	  File "C:\muddev\evenv\Lib\site-packages\twisted\web\http.py", line 706, in rawDataReceived
	    self.handleResponseEnd()
	  File "C:\muddev\evenv\Lib\site-packages\twisted\web\proxy.py", line 82, in handleResponseEnd
	    self.father.finish()
	  File "C:\muddev\evenv\Lib\site-packages\twisted\web\server.py", line 279, in finish
	    return http.Request.finish(self)
	  File "C:\muddev\evenv\Lib\site-packages\twisted\web\http.py", line 1131, in finish
	    raise RuntimeError(
	builtins.RuntimeError: Request.finish called on a request after its connection was lost; use Request.notifyFinish to keep track of this.
	
|Portal| 2022-07-22 14:26:12 [!!] Unhandled Error
	Traceback (most recent call last):
	  File "C:\muddev\evenv\Lib\site-packages\twisted\python\log.py", line 101, in callWithLogger
	    return callWithContext({"system": lp}, func, *args, **kw)
	  File "C:\muddev\evenv\Lib\site-packages\twisted\python\log.py", line 85, in callWithContext
	    return context.call({ILogContext: newCtx}, func, *args, **kw)
	  File "C:\muddev\evenv\Lib\site-packages\twisted\python\context.py", line 118, in callWithContext
	    return self.currentContext().callWithContext(ctx, func, *args, **kw)
	  File "C:\muddev\evenv\Lib\site-packages\twisted\python\context.py", line 83, in callWithContext
	    return func(*args, **kw)
	--- <exception caught here> ---
	  File "C:\muddev\evenv\Lib\site-packages\twisted\internet\selectreactor.py", line 149, in _doReadOrWrite
	    why = getattr(selectable, method)()
	  File "C:\muddev\evenv\Lib\site-packages\twisted\internet\tcp.py", line 247, in doRead
	    return self._dataReceived(data)
	  File "C:\muddev\evenv\Lib\site-packages\twisted\internet\tcp.py", line 252, in _dataReceived
	    rval = self.protocol.dataReceived(data)
	  File "C:\muddev\evenv\Lib\site-packages\twisted\protocols\basic.py", line 554, in dataReceived
	    why = self.rawDataReceived(data)
	  File "C:\muddev\evenv\Lib\site-packages\twisted\web\http.py", line 706, in rawDataReceived
	    self.handleResponseEnd()
	  File "C:\muddev\evenv\Lib\site-packages\twisted\web\proxy.py", line 82, in handleResponseEnd
	    self.father.finish()
	  File "C:\muddev\evenv\Lib\site-packages\twisted\web\server.py", line 279, in finish
	    return http.Request.finish(self)
	  File "C:\muddev\evenv\Lib\site-packages\twisted\web\http.py", line 1131, in finish
	    raise RuntimeError(
	builtins.RuntimeError: Request.finish called on a request after its connection was lost; use Request.notifyFinish to keep track of this.
	
|Portal| 2022-07-22 14:26:12 [!!] Unhandled Error
	Traceback (most recent call last):
	  File "C:\muddev\evenv\Lib\site-packages\twisted\python\log.py", line 101, in callWithLogger
	    return callWithContext({"system": lp}, func, *args, **kw)
	  File "C:\muddev\evenv\Lib\site-packages\twisted\python\log.py", line 85, in callWithContext
	    return context.call({ILogContext: newCtx}, func, *args, **kw)
	  File "C:\muddev\evenv\Lib\site-packages\twisted\python\context.py", line 118, in callWithContext
	    return self.currentContext().callWithContext(ctx, func, *args, **kw)
	  File "C:\muddev\evenv\Lib\site-packages\twisted\python\context.py", line 83, in callWithContext
	    return func(*args, **kw)
	--- <exception caught here> ---
	  File "C:\muddev\evenv\Lib\site-packages\twisted\internet\selectreactor.py", line 149, in _doReadOrWrite
	    why = getattr(selectable, method)()
	  File "C:\muddev\evenv\Lib\site-packages\twisted\internet\tcp.py", line 247, in doRead
	    return self._dataReceived(data)
	  File "C:\muddev\evenv\Lib\site-packages\twisted\internet\tcp.py", line 252, in _dataReceived
	    rval = self.protocol.dataReceived(data)
	  File "C:\muddev\evenv\Lib\site-packages\twisted\protocols\basic.py", line 554, in dataReceived
	    why = self.rawDataReceived(data)
	  File "C:\muddev\evenv\Lib\site-packages\twisted\web\http.py", line 706, in rawDataReceived
	    self.handleResponseEnd()
	  File "C:\muddev\evenv\Lib\site-packages\twisted\web\proxy.py", line 82, in handleResponseEnd
	    self.father.finish()
	  File "C:\muddev\evenv\Lib\site-packages\twisted\web\server.py", line 279, in finish
	    return http.Request.finish(self)
	  File "C:\muddev\evenv\Lib\site-packages\twisted\web\http.py", line 1131, in finish
	    raise RuntimeError(
	builtins.RuntimeError: Request.finish called on a request after its connection was lost; use Request.notifyFinish to keep track of this.
	
|Portal| 2022-07-22 14:26:12 [!!] Unhandled Error
	Traceback (most recent call last):
	  File "C:\muddev\evenv\Lib\site-packages\twisted\python\log.py", line 101, in callWithLogger
	    return callWithContext({"system": lp}, func, *args, **kw)
	  File "C:\muddev\evenv\Lib\site-packages\twisted\python\log.py", line 85, in callWithContext
	    return context.call({ILogContext: newCtx}, func, *args, **kw)
	  File "C:\muddev\evenv\Lib\site-packages\twisted\python\context.py", line 118, in callWithContext
	    return self.currentContext().callWithContext(ctx, func, *args, **kw)
	  File "C:\muddev\evenv\Lib\site-packages\twisted\python\context.py", line 83, in callWithContext
	    return func(*args, **kw)
	--- <exception caught here> ---
	  File "C:\muddev\evenv\Lib\site-packages\twisted\internet\selectreactor.py", line 149, in _doReadOrWrite
	    why = getattr(selectable, method)()
	  File "C:\muddev\evenv\Lib\site-packages\twisted\internet\tcp.py", line 247, in doRead
	    return self._dataReceived(data)
	  File "C:\muddev\evenv\Lib\site-packages\twisted\internet\tcp.py", line 252, in _dataReceived
	    rval = self.protocol.dataReceived(data)
	  File "C:\muddev\evenv\Lib\site-packages\twisted\protocols\basic.py", line 554, in dataReceived
	    why = self.rawDataReceived(data)
	  File "C:\muddev\evenv\Lib\site-packages\twisted\web\http.py", line 706, in rawDataReceived
	    self.handleResponseEnd()
	  File "C:\muddev\evenv\Lib\site-packages\twisted\web\proxy.py", line 82, in handleResponseEnd
	    self.father.finish()
	  File "C:\muddev\evenv\Lib\site-packages\twisted\web\server.py", line 279, in finish
	    return http.Request.finish(self)
	  File "C:\muddev\evenv\Lib\site-packages\twisted\web\http.py", line 1131, in finish
	    raise RuntimeError(
	builtins.RuntimeError: Request.finish called on a request after its connection was lost; use Request.notifyFinish to keep track of this.
	
|Portal| 2022-07-22 14:27:58 [..] Portal starting server ... 
|Portal| 2022-07-24 00:49:19 [!!] Unhandled Error
	Traceback (most recent call last):
	  File "C:\muddev\evenv\Lib\site-packages\twisted\python\log.py", line 101, in callWithLogger
	    return callWithContext({"system": lp}, func, *args, **kw)
	  File "C:\muddev\evenv\Lib\site-packages\twisted\python\log.py", line 85, in callWithContext
	    return context.call({ILogContext: newCtx}, func, *args, **kw)
	  File "C:\muddev\evenv\Lib\site-packages\twisted\python\context.py", line 118, in callWithContext
	    return self.currentContext().callWithContext(ctx, func, *args, **kw)
	  File "C:\muddev\evenv\Lib\site-packages\twisted\python\context.py", line 83, in callWithContext
	    return func(*args, **kw)
	--- <exception caught here> ---
	  File "C:\muddev\evenv\Lib\site-packages\twisted\internet\selectreactor.py", line 149, in _doReadOrWrite
	    why = getattr(selectable, method)()
	  File "C:\muddev\evenv\Lib\site-packages\twisted\internet\tcp.py", line 247, in doRead
	    return self._dataReceived(data)
	  File "C:\muddev\evenv\Lib\site-packages\twisted\internet\tcp.py", line 252, in _dataReceived
	    rval = self.protocol.dataReceived(data)
	  File "C:\muddev\evenv\Lib\site-packages\twisted\protocols\basic.py", line 554, in dataReceived
	    why = self.rawDataReceived(data)
	  File "C:\muddev\evenv\Lib\site-packages\twisted\web\http.py", line 706, in rawDataReceived
	    self.handleResponseEnd()
	  File "C:\muddev\evenv\Lib\site-packages\twisted\web\proxy.py", line 82, in handleResponseEnd
	    self.father.finish()
	  File "C:\muddev\evenv\Lib\site-packages\twisted\web\server.py", line 279, in finish
	    return http.Request.finish(self)
	  File "C:\muddev\evenv\Lib\site-packages\twisted\web\http.py", line 1131, in finish
	    raise RuntimeError(
	builtins.RuntimeError: Request.finish called on a request after its connection was lost; use Request.notifyFinish to keep track of this.
	
|Portal| 2022-07-24 00:49:19 [!!] Unhandled Error
	Traceback (most recent call last):
	  File "C:\muddev\evenv\Lib\site-packages\twisted\python\log.py", line 101, in callWithLogger
	    return callWithContext({"system": lp}, func, *args, **kw)
	  File "C:\muddev\evenv\Lib\site-packages\twisted\python\log.py", line 85, in callWithContext
	    return context.call({ILogContext: newCtx}, func, *args, **kw)
	  File "C:\muddev\evenv\Lib\site-packages\twisted\python\context.py", line 118, in callWithContext
	    return self.currentContext().callWithContext(ctx, func, *args, **kw)
	  File "C:\muddev\evenv\Lib\site-packages\twisted\python\context.py", line 83, in callWithContext
	    return func(*args, **kw)
	--- <exception caught here> ---
	  File "C:\muddev\evenv\Lib\site-packages\twisted\internet\selectreactor.py", line 149, in _doReadOrWrite
	    why = getattr(selectable, method)()
	  File "C:\muddev\evenv\Lib\site-packages\twisted\internet\tcp.py", line 247, in doRead
	    return self._dataReceived(data)
	  File "C:\muddev\evenv\Lib\site-packages\twisted\internet\tcp.py", line 252, in _dataReceived
	    rval = self.protocol.dataReceived(data)
	  File "C:\muddev\evenv\Lib\site-packages\twisted\protocols\basic.py", line 554, in dataReceived
	    why = self.rawDataReceived(data)
	  File "C:\muddev\evenv\Lib\site-packages\twisted\web\http.py", line 706, in rawDataReceived
	    self.handleResponseEnd()
	  File "C:\muddev\evenv\Lib\site-packages\twisted\web\proxy.py", line 82, in handleResponseEnd
	    self.father.finish()
	  File "C:\muddev\evenv\Lib\site-packages\twisted\web\server.py", line 279, in finish
	    return http.Request.finish(self)
	  File "C:\muddev\evenv\Lib\site-packages\twisted\web\http.py", line 1131, in finish
	    raise RuntimeError(
	builtins.RuntimeError: Request.finish called on a request after its connection was lost; use Request.notifyFinish to keep track of this.
	
|Portal| 2022-07-24 00:49:19 [!!] Unhandled Error
	Traceback (most recent call last):
	  File "C:\muddev\evenv\Lib\site-packages\twisted\python\log.py", line 101, in callWithLogger
	    return callWithContext({"system": lp}, func, *args, **kw)
	  File "C:\muddev\evenv\Lib\site-packages\twisted\python\log.py", line 85, in callWithContext
	    return context.call({ILogContext: newCtx}, func, *args, **kw)
	  File "C:\muddev\evenv\Lib\site-packages\twisted\python\context.py", line 118, in callWithContext
	    return self.currentContext().callWithContext(ctx, func, *args, **kw)
	  File "C:\muddev\evenv\Lib\site-packages\twisted\python\context.py", line 83, in callWithContext
	    return func(*args, **kw)
	--- <exception caught here> ---
	  File "C:\muddev\evenv\Lib\site-packages\twisted\internet\selectreactor.py", line 149, in _doReadOrWrite
	    why = getattr(selectable, method)()
	  File "C:\muddev\evenv\Lib\site-packages\twisted\internet\tcp.py", line 247, in doRead
	    return self._dataReceived(data)
	  File "C:\muddev\evenv\Lib\site-packages\twisted\internet\tcp.py", line 252, in _dataReceived
	    rval = self.protocol.dataReceived(data)
	  File "C:\muddev\evenv\Lib\site-packages\twisted\protocols\basic.py", line 554, in dataReceived
	    why = self.rawDataReceived(data)
	  File "C:\muddev\evenv\Lib\site-packages\twisted\web\http.py", line 706, in rawDataReceived
	    self.handleResponseEnd()
	  File "C:\muddev\evenv\Lib\site-packages\twisted\web\proxy.py", line 82, in handleResponseEnd
	    self.father.finish()
	  File "C:\muddev\evenv\Lib\site-packages\twisted\web\server.py", line 279, in finish
	    return http.Request.finish(self)
	  File "C:\muddev\evenv\Lib\site-packages\twisted\web\http.py", line 1131, in finish
	    raise RuntimeError(
	builtins.RuntimeError: Request.finish called on a request after its connection was lost; use Request.notifyFinish to keep track of this.
	
|Portal| 2022-07-24 00:49:19 [!!] Unhandled Error
	Traceback (most recent call last):
	  File "C:\muddev\evenv\Lib\site-packages\twisted\python\log.py", line 101, in callWithLogger
	    return callWithContext({"system": lp}, func, *args, **kw)
	  File "C:\muddev\evenv\Lib\site-packages\twisted\python\log.py", line 85, in callWithContext
	    return context.call({ILogContext: newCtx}, func, *args, **kw)
	  File "C:\muddev\evenv\Lib\site-packages\twisted\python\context.py", line 118, in callWithContext
	    return self.currentContext().callWithContext(ctx, func, *args, **kw)
	  File "C:\muddev\evenv\Lib\site-packages\twisted\python\context.py", line 83, in callWithContext
	    return func(*args, **kw)
	--- <exception caught here> ---
	  File "C:\muddev\evenv\Lib\site-packages\twisted\internet\selectreactor.py", line 149, in _doReadOrWrite
	    why = getattr(selectable, method)()
	  File "C:\muddev\evenv\Lib\site-packages\twisted\internet\tcp.py", line 247, in doRead
	    return self._dataReceived(data)
	  File "C:\muddev\evenv\Lib\site-packages\twisted\internet\tcp.py", line 252, in _dataReceived
	    rval = self.protocol.dataReceived(data)
	  File "C:\muddev\evenv\Lib\site-packages\twisted\protocols\basic.py", line 554, in dataReceived
	    why = self.rawDataReceived(data)
	  File "C:\muddev\evenv\Lib\site-packages\twisted\web\http.py", line 706, in rawDataReceived
	    self.handleResponseEnd()
	  File "C:\muddev\evenv\Lib\site-packages\twisted\web\proxy.py", line 82, in handleResponseEnd
	    self.father.finish()
	  File "C:\muddev\evenv\Lib\site-packages\twisted\web\server.py", line 279, in finish
	    return http.Request.finish(self)
	  File "C:\muddev\evenv\Lib\site-packages\twisted\web\http.py", line 1131, in finish
	    raise RuntimeError(
	builtins.RuntimeError: Request.finish called on a request after its connection was lost; use Request.notifyFinish to keep track of this.
	
|Portal| 2022-07-24 00:49:19 [!!] Unhandled Error
	Traceback (most recent call last):
	  File "C:\muddev\evenv\Lib\site-packages\twisted\python\log.py", line 101, in callWithLogger
	    return callWithContext({"system": lp}, func, *args, **kw)
	  File "C:\muddev\evenv\Lib\site-packages\twisted\python\log.py", line 85, in callWithContext
	    return context.call({ILogContext: newCtx}, func, *args, **kw)
	  File "C:\muddev\evenv\Lib\site-packages\twisted\python\context.py", line 118, in callWithContext
	    return self.currentContext().callWithContext(ctx, func, *args, **kw)
	  File "C:\muddev\evenv\Lib\site-packages\twisted\python\context.py", line 83, in callWithContext
	    return func(*args, **kw)
	--- <exception caught here> ---
	  File "C:\muddev\evenv\Lib\site-packages\twisted\internet\selectreactor.py", line 149, in _doReadOrWrite
	    why = getattr(selectable, method)()
	  File "C:\muddev\evenv\Lib\site-packages\twisted\internet\tcp.py", line 247, in doRead
	    return self._dataReceived(data)
	  File "C:\muddev\evenv\Lib\site-packages\twisted\internet\tcp.py", line 252, in _dataReceived
	    rval = self.protocol.dataReceived(data)
	  File "C:\muddev\evenv\Lib\site-packages\twisted\protocols\basic.py", line 554, in dataReceived
	    why = self.rawDataReceived(data)
	  File "C:\muddev\evenv\Lib\site-packages\twisted\web\http.py", line 706, in rawDataReceived
	    self.handleResponseEnd()
	  File "C:\muddev\evenv\Lib\site-packages\twisted\web\proxy.py", line 82, in handleResponseEnd
	    self.father.finish()
	  File "C:\muddev\evenv\Lib\site-packages\twisted\web\server.py", line 279, in finish
	    return http.Request.finish(self)
	  File "C:\muddev\evenv\Lib\site-packages\twisted\web\http.py", line 1131, in finish
	    raise RuntimeError(
	builtins.RuntimeError: Request.finish called on a request after its connection was lost; use Request.notifyFinish to keep track of this.
	
|Portal| 2022-07-24 00:49:19 [!!] Unhandled Error
	Traceback (most recent call last):
	  File "C:\muddev\evenv\Lib\site-packages\twisted\python\log.py", line 101, in callWithLogger
	    return callWithContext({"system": lp}, func, *args, **kw)
	  File "C:\muddev\evenv\Lib\site-packages\twisted\python\log.py", line 85, in callWithContext
	    return context.call({ILogContext: newCtx}, func, *args, **kw)
	  File "C:\muddev\evenv\Lib\site-packages\twisted\python\context.py", line 118, in callWithContext
	    return self.currentContext().callWithContext(ctx, func, *args, **kw)
	  File "C:\muddev\evenv\Lib\site-packages\twisted\python\context.py", line 83, in callWithContext
	    return func(*args, **kw)
	--- <exception caught here> ---
	  File "C:\muddev\evenv\Lib\site-packages\twisted\internet\selectreactor.py", line 149, in _doReadOrWrite
	    why = getattr(selectable, method)()
	  File "C:\muddev\evenv\Lib\site-packages\twisted\internet\tcp.py", line 247, in doRead
	    return self._dataReceived(data)
	  File "C:\muddev\evenv\Lib\site-packages\twisted\internet\tcp.py", line 252, in _dataReceived
	    rval = self.protocol.dataReceived(data)
	  File "C:\muddev\evenv\Lib\site-packages\twisted\protocols\basic.py", line 554, in dataReceived
	    why = self.rawDataReceived(data)
	  File "C:\muddev\evenv\Lib\site-packages\twisted\web\http.py", line 706, in rawDataReceived
	    self.handleResponseEnd()
	  File "C:\muddev\evenv\Lib\site-packages\twisted\web\proxy.py", line 82, in handleResponseEnd
	    self.father.finish()
	  File "C:\muddev\evenv\Lib\site-packages\twisted\web\server.py", line 279, in finish
	    return http.Request.finish(self)
	  File "C:\muddev\evenv\Lib\site-packages\twisted\web\http.py", line 1131, in finish
	    raise RuntimeError(
	builtins.RuntimeError: Request.finish called on a request after its connection was lost; use Request.notifyFinish to keep track of this.
	
|Portal| 2022-07-24 00:49:19 [!!] Unhandled Error
	Traceback (most recent call last):
	  File "C:\muddev\evenv\Lib\site-packages\twisted\python\log.py", line 101, in callWithLogger
	    return callWithContext({"system": lp}, func, *args, **kw)
	  File "C:\muddev\evenv\Lib\site-packages\twisted\python\log.py", line 85, in callWithContext
	    return context.call({ILogContext: newCtx}, func, *args, **kw)
	  File "C:\muddev\evenv\Lib\site-packages\twisted\python\context.py", line 118, in callWithContext
	    return self.currentContext().callWithContext(ctx, func, *args, **kw)
	  File "C:\muddev\evenv\Lib\site-packages\twisted\python\context.py", line 83, in callWithContext
	    return func(*args, **kw)
	--- <exception caught here> ---
	  File "C:\muddev\evenv\Lib\site-packages\twisted\internet\selectreactor.py", line 149, in _doReadOrWrite
	    why = getattr(selectable, method)()
	  File "C:\muddev\evenv\Lib\site-packages\twisted\internet\tcp.py", line 247, in doRead
	    return self._dataReceived(data)
	  File "C:\muddev\evenv\Lib\site-packages\twisted\internet\tcp.py", line 252, in _dataReceived
	    rval = self.protocol.dataReceived(data)
	  File "C:\muddev\evenv\Lib\site-packages\twisted\protocols\basic.py", line 554, in dataReceived
	    why = self.rawDataReceived(data)
	  File "C:\muddev\evenv\Lib\site-packages\twisted\web\http.py", line 706, in rawDataReceived
	    self.handleResponseEnd()
	  File "C:\muddev\evenv\Lib\site-packages\twisted\web\proxy.py", line 82, in handleResponseEnd
	    self.father.finish()
	  File "C:\muddev\evenv\Lib\site-packages\twisted\web\server.py", line 279, in finish
	    return http.Request.finish(self)
	  File "C:\muddev\evenv\Lib\site-packages\twisted\web\http.py", line 1131, in finish
	    raise RuntimeError(
	builtins.RuntimeError: Request.finish called on a request after its connection was lost; use Request.notifyFinish to keep track of this.
	
|Portal| 2022-07-24 00:49:19 [!!] Unhandled Error
	Traceback (most recent call last):
	  File "C:\muddev\evenv\Lib\site-packages\twisted\python\log.py", line 101, in callWithLogger
	    return callWithContext({"system": lp}, func, *args, **kw)
	  File "C:\muddev\evenv\Lib\site-packages\twisted\python\log.py", line 85, in callWithContext
	    return context.call({ILogContext: newCtx}, func, *args, **kw)
	  File "C:\muddev\evenv\Lib\site-packages\twisted\python\context.py", line 118, in callWithContext
	    return self.currentContext().callWithContext(ctx, func, *args, **kw)
	  File "C:\muddev\evenv\Lib\site-packages\twisted\python\context.py", line 83, in callWithContext
	    return func(*args, **kw)
	--- <exception caught here> ---
	  File "C:\muddev\evenv\Lib\site-packages\twisted\internet\selectreactor.py", line 149, in _doReadOrWrite
	    why = getattr(selectable, method)()
	  File "C:\muddev\evenv\Lib\site-packages\twisted\internet\tcp.py", line 247, in doRead
	    return self._dataReceived(data)
	  File "C:\muddev\evenv\Lib\site-packages\twisted\internet\tcp.py", line 252, in _dataReceived
	    rval = self.protocol.dataReceived(data)
	  File "C:\muddev\evenv\Lib\site-packages\twisted\protocols\basic.py", line 554, in dataReceived
	    why = self.rawDataReceived(data)
	  File "C:\muddev\evenv\Lib\site-packages\twisted\web\http.py", line 706, in rawDataReceived
	    self.handleResponseEnd()
	  File "C:\muddev\evenv\Lib\site-packages\twisted\web\proxy.py", line 82, in handleResponseEnd
	    self.father.finish()
	  File "C:\muddev\evenv\Lib\site-packages\twisted\web\server.py", line 279, in finish
	    return http.Request.finish(self)
	  File "C:\muddev\evenv\Lib\site-packages\twisted\web\http.py", line 1131, in finish
	    raise RuntimeError(
	builtins.RuntimeError: Request.finish called on a request after its connection was lost; use Request.notifyFinish to keep track of this.
	
|Portal| 2022-07-24 00:49:19 [!!] Unhandled Error
	Traceback (most recent call last):
	  File "C:\muddev\evenv\Lib\site-packages\twisted\python\log.py", line 101, in callWithLogger
	    return callWithContext({"system": lp}, func, *args, **kw)
	  File "C:\muddev\evenv\Lib\site-packages\twisted\python\log.py", line 85, in callWithContext
	    return context.call({ILogContext: newCtx}, func, *args, **kw)
	  File "C:\muddev\evenv\Lib\site-packages\twisted\python\context.py", line 118, in callWithContext
	    return self.currentContext().callWithContext(ctx, func, *args, **kw)
	  File "C:\muddev\evenv\Lib\site-packages\twisted\python\context.py", line 83, in callWithContext
	    return func(*args, **kw)
	--- <exception caught here> ---
	  File "C:\muddev\evenv\Lib\site-packages\twisted\internet\selectreactor.py", line 149, in _doReadOrWrite
	    why = getattr(selectable, method)()
	  File "C:\muddev\evenv\Lib\site-packages\twisted\internet\tcp.py", line 247, in doRead
	    return self._dataReceived(data)
	  File "C:\muddev\evenv\Lib\site-packages\twisted\internet\tcp.py", line 252, in _dataReceived
	    rval = self.protocol.dataReceived(data)
	  File "C:\muddev\evenv\Lib\site-packages\twisted\protocols\basic.py", line 554, in dataReceived
	    why = self.rawDataReceived(data)
	  File "C:\muddev\evenv\Lib\site-packages\twisted\web\http.py", line 706, in rawDataReceived
	    self.handleResponseEnd()
	  File "C:\muddev\evenv\Lib\site-packages\twisted\web\proxy.py", line 82, in handleResponseEnd
	    self.father.finish()
	  File "C:\muddev\evenv\Lib\site-packages\twisted\web\server.py", line 279, in finish
	    return http.Request.finish(self)
	  File "C:\muddev\evenv\Lib\site-packages\twisted\web\http.py", line 1131, in finish
	    raise RuntimeError(
	builtins.RuntimeError: Request.finish called on a request after its connection was lost; use Request.notifyFinish to keep track of this.
	
|Portal| 2022-07-24 00:49:20 [!!] Unhandled Error
	Traceback (most recent call last):
	  File "C:\muddev\evenv\Lib\site-packages\twisted\python\log.py", line 101, in callWithLogger
	    return callWithContext({"system": lp}, func, *args, **kw)
	  File "C:\muddev\evenv\Lib\site-packages\twisted\python\log.py", line 85, in callWithContext
	    return context.call({ILogContext: newCtx}, func, *args, **kw)
	  File "C:\muddev\evenv\Lib\site-packages\twisted\python\context.py", line 118, in callWithContext
	    return self.currentContext().callWithContext(ctx, func, *args, **kw)
	  File "C:\muddev\evenv\Lib\site-packages\twisted\python\context.py", line 83, in callWithContext
	    return func(*args, **kw)
	--- <exception caught here> ---
	  File "C:\muddev\evenv\Lib\site-packages\twisted\internet\selectreactor.py", line 149, in _doReadOrWrite
	    why = getattr(selectable, method)()
	  File "C:\muddev\evenv\Lib\site-packages\twisted\internet\tcp.py", line 247, in doRead
	    return self._dataReceived(data)
	  File "C:\muddev\evenv\Lib\site-packages\twisted\internet\tcp.py", line 252, in _dataReceived
	    rval = self.protocol.dataReceived(data)
	  File "C:\muddev\evenv\Lib\site-packages\twisted\protocols\basic.py", line 554, in dataReceived
	    why = self.rawDataReceived(data)
	  File "C:\muddev\evenv\Lib\site-packages\twisted\web\http.py", line 706, in rawDataReceived
	    self.handleResponseEnd()
	  File "C:\muddev\evenv\Lib\site-packages\twisted\web\proxy.py", line 82, in handleResponseEnd
	    self.father.finish()
	  File "C:\muddev\evenv\Lib\site-packages\twisted\web\server.py", line 279, in finish
	    return http.Request.finish(self)
	  File "C:\muddev\evenv\Lib\site-packages\twisted\web\http.py", line 1131, in finish
	    raise RuntimeError(
	builtins.RuntimeError: Request.finish called on a request after its connection was lost; use Request.notifyFinish to keep track of this.
	
|Portal| 2022-07-24 01:09:17 [..] (TCP Port 4001 Closed)
|Portal| 2022-07-24 01:09:17 [..] (TCP Port 4000 Closed)
|Portal| 2022-07-24 01:09:17 [..] (TCP Port 4006 Closed)
|Portal| 2022-07-24 01:09:17 [..] (TCP Port 4002 Closed)
|Portal| 2022-07-24 01:09:17 [..] Main loop terminated.
|Portal| 2022-07-24 01:09:17 [..] Server Shut Down.
|Portal| 2022-07-24 01:09:17 [..] Server Shut Down.
|Portal| 2022-07-24 01:10:10 [..] Loaded.
|Portal| 2022-07-24 01:10:09 [..] Loading c:\muddev\evennia\evennia\server\portal\portal.py...
|Portal| 2022-07-24 01:10:09 [EE] Could not find file-help module world.help_entries (skipping).
|Portal| 2022-07-24 01:10:10 [..] Loaded.
|Portal| 2022-07-24 01:10:10 [..] twistd 21.7.0 (C:\muddev\evenv\Scripts\python.exe 3.9.2) starting up.
|Portal| 2022-07-24 01:10:10 [..] reactor class: twisted.internet.selectreactor.SelectReactor.
|Portal| 2022-07-24 01:10:10 [..] AMP starting on 4006
|Portal| 2022-07-24 01:10:10 [..] Telnet starting on 4000
|Portal| 2022-07-24 01:10:10 [..] Websocket starting on 4002
|Portal| 2022-07-24 01:10:10 [..] Webserver-proxy starting on 4001
|Portal| 2022-07-24 01:10:10 [..] Portal starting server ... 
|Portal| 2022-07-24 01:10:10 [EE] AMP Error from AdminPortal2Server: Traceback (most recent call last):
|Portal| 2022-07-24 01:10:10 [EE] --- <exception caught here> ---
|Portal| 2022-07-24 01:10:10 [EE]   File "C:\muddev\evenv\Lib\site-packages\twisted\internet\defer.py", line 858, in _runCallbacks
|Portal| 2022-07-24 01:10:10 [EE]     current.result = callback(  # type: ignore[misc]
|Portal| 2022-07-24 01:10:10 [EE]   File "C:\muddev\evenv\Lib\site-packages\twisted\protocols\amp.py", line 1947, in _massageError
|Portal| 2022-07-24 01:10:10 [EE]     error.trap(RemoteAmpError)
|Portal| 2022-07-24 01:10:10 [EE]   File "C:\muddev\evenv\Lib\site-packages\twisted\python\failure.py", line 450, in trap
|Portal| 2022-07-24 01:10:10 [EE]     self.raiseException()
|Portal| 2022-07-24 01:10:10 [EE]   File "C:\muddev\evenv\Lib\site-packages\twisted\python\failure.py", line 475, in raiseException
|Portal| 2022-07-24 01:10:10 [EE]     raise self.value.with_traceback(self.tb)
|Portal| 2022-07-24 01:10:10 [EE] twisted.protocols.amp.UnhandledCommand: (b'UNHANDLED', "Unhandled Command: b'AdminPortal2Server'")
|Portal| 2022-07-24 01:10:10 [EE]  (b'UNHANDLED', "Unhandled Command: b'AdminPortal2Server'")
|Portal| 2022-07-24 01:10:15 [WW] dropping connection to peer tcp4:127.0.0.1:62686 with abort=True: WebSocket opening handshake timeout (peer did not finish the opening handshake in time)
|Portal| 2022-07-24 15:49:12 [..] Portal starting server ... 
|Portal| 2022-07-24 15:55:30 [..] Portal starting server ... 
|Portal| 2022-07-24 16:00:57 [..] Portal starting server ... 
|Portal| 2022-07-24 16:25:24 [..] Portal starting server ... 
|Portal| 2022-07-24 16:27:22 [..] Portal starting server ... 
|Portal| 2022-07-24 16:31:09 [..] Portal starting server ... 
|Portal| 2022-07-24 23:27:05 [..] Portal starting server ... 
|Portal| 2022-07-25 02:46:00 [EE] AMP Error from AdminPortal2Server: Traceback (most recent call last):
|Portal| 2022-07-25 02:46:00 [EE] Failure: builtins.Exception: 'NoneType' object has no attribute 'items' (error logged on other side)
|Portal| 2022-07-25 02:46:00 [EE]  'NoneType' object has no attribute 'items' (error logged on other side)
|Portal| 2022-07-27 16:25:49 [EE] AMP Error from AdminPortal2Server: Traceback (most recent call last):
|Portal| 2022-07-27 16:25:49 [EE] Failure: builtins.Exception: 'NoneType' object has no attribute 'items' (error logged on other side)
|Portal| 2022-07-27 16:25:49 [EE]  'NoneType' object has no attribute 'items' (error logged on other side)
|Portal| 2022-07-27 16:26:27 [..] Portal starting server ... 
|Portal| 2022-07-27 16:26:49 [..] Timing out client: IPv4Address(type='TCP', host='127.0.0.1', port=65255)
|Portal| 2022-07-27 16:26:49 [..] Timing out client: IPv4Address(type='TCP', host='127.0.0.1', port=65257)
|Portal| 2022-07-27 16:26:49 [..] Timing out client: IPv4Address(type='TCP', host='127.0.0.1', port=65260)
|Portal| 2022-07-27 16:26:49 [..] Timing out client: IPv4Address(type='TCP', host='127.0.0.1', port=65262)
|Portal| 2022-07-27 16:26:49 [..] Timing out client: IPv4Address(type='TCP', host='127.0.0.1', port=65261)
|Portal| 2022-07-27 16:27:29 [..] Timing out client: IPv4Address(type='TCP', host='127.0.0.1', port=65258)
