22-01-04 21:01:10-08  |Portal| Loading c:\muddev\evennia\evennia\server\portal\portal.py...
22-01-04 21:01:11-08  |Portal| Loaded.
22-01-04 21:01:11-08  |Portal| twistd 21.7.0 (c:\muddev\evenv\scripts\python.exe 3.7.0) starting up.
22-01-04 21:01:11-08  |Portal| reactor class: twisted.internet.selectreactor.SelectReactor.
22-01-04 21:01:11-08  |Portal| AMP starting on 4006
22-01-04 21:01:11-08  |Portal| Telnet starting on 4000
22-01-04 21:01:11-08  |Portal| Websocket starting on 4002
22-01-04 21:01:11-08  |Portal| Webserver-proxy starting on 4001
22-01-04 21:01:11-08  |Portal| Portal starting server ... 
22-01-04 21:02:17-08  |Portal| Timing out client: IPv4Address(type='TCP', host='127.0.0.1', port=59181)
22-01-04 21:02:17-08  |Portal| Timing out client: IPv4Address(type='TCP', host='127.0.0.1', port=59184)
22-01-04 21:02:17-08  |Portal| Timing out client: IPv4Address(type='TCP', host='127.0.0.1', port=59188)
22-01-04 21:02:17-08  |Portal| Timing out client: IPv4Address(type='TCP', host='127.0.0.1', port=59189)
22-01-04 21:02:17-08  |Portal| Timing out client: IPv4Address(type='TCP', host='127.0.0.1', port=59190)
22-01-04 21:02:17-08  |Portal| Timing out client: IPv4Address(type='TCP', host='127.0.0.1', port=59186)
22-01-04 21:13:45-08  |Portal| Portal starting server ... 
22-01-04 21:19:12-08  |Portal| Portal starting server ... 
22-01-05 03:47:10-08  |Portal| Portal starting server ... 
22-01-05 03:51:21-08  |Portal| Portal starting server ... 
22-01-05 03:51:57-08  |Portal| Portal starting server ... 
22-01-05 04:05:42-08  |Portal| Portal starting server ... 
22-01-05 04:06:14-08  |Portal| Portal starting server ... 
22-01-05 04:10:30-08  |Portal| Portal starting server ... 
22-01-05 04:11:58-08  |Portal| Portal starting server ... 
22-01-05 04:13:59-08  |Portal| (TCP Port 4001 Closed)
22-01-05 04:13:59-08  |Portal| (TCP Port 4000 Closed)
22-01-05 04:13:59-08  |Portal| (TCP Port 4006 Closed)
22-01-05 04:13:59-08  |Portal| (TCP Port 4002 Closed)
22-01-05 04:13:59-08  |Portal| Main loop terminated.
22-01-05 04:13:59-08  |Portal| Server Shut Down.
22-01-05 04:13:59-08  |Portal| Server Shut Down.
22-01-05 04:14:06-08  |Portal| Loading c:\muddev\evennia\evennia\server\portal\portal.py...
22-01-05 04:14:07-08  |Portal| Loaded.
22-01-05 04:14:07-08  |Portal| twistd 21.7.0 (c:\muddev\evenv\scripts\python.exe 3.7.0) starting up.
22-01-05 04:14:07-08  |Portal| reactor class: twisted.internet.selectreactor.SelectReactor.
22-01-05 04:14:07-08  |Portal| AMP starting on 4006
22-01-05 04:14:07-08  |Portal| Telnet starting on 4000
22-01-05 04:14:07-08  |Portal| Websocket starting on 4002
22-01-05 04:14:07-08  |Portal| Webserver-proxy starting on 4001
22-01-05 04:14:07-08  |Portal| Portal starting server ... 
22-01-05 04:15:32-08  |Portal| (TCP Port 4001 Closed)
22-01-05 04:15:32-08  |Portal| (TCP Port 4000 Closed)
22-01-05 04:15:32-08  |Portal| (TCP Port 4006 Closed)
22-01-05 04:15:32-08  |Portal| (TCP Port 4002 Closed)
22-01-05 04:15:32-08  |Portal| Main loop terminated.
22-01-05 04:15:32-08  |Portal| Server Shut Down.
22-01-05 04:15:32-08  |Portal| Server Shut Down.
22-01-05 04:15:38-08  |Portal| Loading c:\muddev\evennia\evennia\server\portal\portal.py...
22-01-05 04:15:39-08  |Portal| Loaded.
22-01-05 04:15:39-08  |Portal| twistd 21.7.0 (c:\muddev\evenv\scripts\python.exe 3.7.0) starting up.
22-01-05 04:15:39-08  |Portal| reactor class: twisted.internet.selectreactor.SelectReactor.
22-01-05 04:15:39-08  |Portal| AMP starting on 4006
22-01-05 04:15:39-08  |Portal| Telnet starting on 4000
22-01-05 04:15:39-08  |Portal| Websocket starting on 4002
22-01-05 04:15:39-08  |Portal| Webserver-proxy starting on 4001
22-01-05 04:15:40-08  |Portal| Portal starting server ... 
22-01-05 04:21:53-08  |Portal| Portal starting server ... 
22-01-05 04:22:49-08  |Portal| Portal starting server ... 
22-01-05 04:25:51-08  |Portal| Portal starting server ... 
22-01-05 04:26:12-08  |Portal| Portal starting server ... 
22-01-05 04:28:16-08  |Portal| Portal starting server ... 
22-01-05 04:30:27-08  |Portal| Portal starting server ... 
22-01-05 04:31:39-08  |Portal| Portal starting server ... 
22-01-05 04:35:06-08  |Portal| Portal starting server ... 
22-01-05 04:36:24-08  |Portal| Portal starting server ... 
22-01-05 04:38:32-08  |Portal| Portal starting server ... 
22-01-05 04:39:31-08  |Portal| Portal starting server ... 
22-01-05 04:40:37-08  |Portal| Portal starting server ... 
22-01-05 04:41:45-08  |Portal| Portal starting server ... 
22-01-05 04:42:43-08  |Portal| Portal starting server ... 
22-01-05 04:43:38-08  |Portal| Portal starting server ... 
22-01-05 04:44:32-08  |Portal| Portal starting server ... 
22-01-05 12:28:41-08  |Portal| Portal starting server ... 
22-01-05 12:29:05-08  |Portal| Portal starting server ... 
22-01-05 12:33:31-08  |Portal| Portal starting server ... 
22-01-05 12:34:31-08  |Portal| Portal starting server ... 
22-01-05 12:35:11-08  |Portal| Portal starting server ... 
22-01-05 12:37:50-08  |Portal| Portal starting server ... 
22-01-05 12:38:32-08  |Portal| Portal starting server ... 
22-01-05 12:40:50-08  |Portal| Portal starting server ... 
22-01-05 12:46:18-08  |Portal| Portal starting server ... 
22-01-05 12:47:05-08  |Portal| Portal starting server ... 
22-01-05 12:47:23-08  |Portal| Portal starting server ... 
22-01-05 12:48:39-08  |Portal| Portal starting server ... 
22-01-05 12:52:29-08  |Portal| Portal starting server ... 
22-01-05 12:53:55-08  |Portal| Portal starting server ... 
22-01-05 12:54:39-08  |Portal| Portal starting server ... 
22-01-05 12:55:04-08  |Portal| Portal starting server ... 
22-01-05 12:56:06-08  |Portal| Portal starting server ... 
22-01-05 12:56:56-08  |Portal| Portal starting server ... 
22-01-05 13:01:01-08  |Portal| Portal starting server ... 
22-01-05 13:03:28-08  |Portal| Portal starting server ... 
22-01-05 13:18:41-08  |Portal| Portal starting server ... 
22-01-05 13:20:07-08  |Portal| Portal starting server ... 
22-01-05 13:21:49-08  |Portal| Portal starting server ... 
22-01-05 13:29:36-08  |Portal| Portal starting server ... 
22-01-05 13:33:43-08  |Portal| Portal starting server ... 
22-01-05 13:43:12-08  |Portal| Portal starting server ... 
22-01-05 13:45:21-08  |Portal| Portal starting server ... 
22-01-05 14:09:07-08  |Portal| Portal starting server ... 
22-01-05 14:12:26-08  |Portal| Portal starting server ... 
22-01-05 14:14:06-08  |Portal| Portal starting server ... 
22-01-05 14:15:39-08  |Portal| Portal starting server ... 
22-01-05 14:16:38-08  |Portal| Portal starting server ... 
22-01-05 14:16:53-08  |Portal| Portal starting server ... 
22-01-05 14:19:21-08  |Portal| Portal starting server ... 
22-01-05 14:20:28-08  |Portal| Portal starting server ... 
22-01-05 14:21:18-08  |Portal| Portal starting server ... 
22-01-05 14:30:56-08  |Portal| Portal starting server ... 
22-01-05 14:56:20-08  |Portal| Portal starting server ... 
22-01-05 14:56:40-08  |Portal| Portal starting server ... 
22-01-05 14:58:27-08  |Portal| Portal starting server ... 
22-01-05 15:07:12-08  |Portal| Portal starting server ... 
22-01-05 15:15:27-08  |Portal| Portal starting server ... 
22-01-05 15:15:42-08  |Portal| Portal starting server ... 
22-01-05 15:17:37-08  |Portal| Portal starting server ... 
22-01-05 15:23:33-08  |Portal| Portal starting server ... 
22-01-05 17:11:34-08  |Portal| Portal starting server ... 
22-01-05 17:11:35-08  |Portal| [EE] AMP Error from AdminPortal2Server: Traceback (most recent call last):
22-01-05 17:11:35-08  |Portal| [EE] Failure: builtins.Exception: cannot import name 'tick_buff' from 'typeclasses.buffhandler' (c:\muddev\destiny\typeclasses\buffhandler.py) (error logged on other side)
22-01-05 17:11:35-08  |Portal| [EE]  cannot import name 'tick_buff' from 'typeclasses.buffhandler' (c:\muddev\destiny\typeclasses\buffhandler.py) (error logged on other side)
22-01-05 17:19:16-08  |Portal| Portal starting server ... 
22-01-05 17:19:17-08  |Portal| [EE] AMP Error from AdminPortal2Server: Traceback (most recent call last):
22-01-05 17:19:17-08  |Portal| [EE] Failure: builtins.Exception: cannot import name 'tick_buff' from 'typeclasses.buffhandler' (c:\muddev\destiny\typeclasses\buffhandler.py) (error logged on other side)
22-01-05 17:19:17-08  |Portal| [EE]  cannot import name 'tick_buff' from 'typeclasses.buffhandler' (c:\muddev\destiny\typeclasses\buffhandler.py) (error logged on other side)
22-01-05 17:19:53-08  |Portal| Portal starting server ... 
22-01-05 17:20:03-08  |Portal| Portal starting server ... 
22-01-05 17:20:59-08  |Portal| Portal starting server ... 
22-01-05 17:23:44-08  |Portal| Portal starting server ... 
22-01-05 17:24:05-08  |Portal| Portal starting server ... 
22-01-05 17:24:09-08  |Portal| Portal starting server ... 
22-01-05 17:25:41-08  |Portal| Portal starting server ... 
22-01-05 17:26:34-08  |Portal| Portal starting server ... 
22-01-05 17:29:24-08  |Portal| Portal starting server ... 
22-01-05 17:30:44-08  |Portal| Portal starting server ... 
22-01-05 17:32:17-08  |Portal| Portal starting server ... 
22-01-05 17:33:32-08  |Portal| Portal starting server ... 
22-01-05 17:48:58-08  |Portal| Portal starting server ... 
22-01-05 17:50:07-08  |Portal| Portal starting server ... 
22-01-05 17:50:49-08  |Portal| Portal starting server ... 
22-01-05 17:53:42-08  |Portal| Portal starting server ... 
22-01-05 17:57:03-08  |Portal| Portal starting server ... 
22-01-05 18:46:55-08  |Portal| Portal starting server ... 
22-01-05 18:47:45-08  |Portal| Portal starting server ... 
22-01-05 18:48:23-08  |Portal| Portal starting server ... 
22-01-05 18:49:44-08  |Portal| Portal starting server ... 
22-01-05 18:55:25-08  |Portal| Portal starting server ... 
22-01-05 18:56:07-08  |Portal| Portal starting server ... 
22-01-05 18:58:10-08  |Portal| Portal starting server ... 
22-01-05 19:03:27-08  |Portal| Portal starting server ... 
22-01-05 19:21:06-08  |Portal| Portal starting server ... 
22-01-05 19:29:40-08  |Portal| Portal starting server ... 
22-01-05 19:31:16-08  |Portal| Portal starting server ... 
22-01-05 19:32:50-08  |Portal| Portal starting server ... 
22-01-05 19:33:39-08  |Portal| Portal starting server ... 
22-01-05 19:34:57-08  |Portal| Portal starting server ... 
22-01-05 19:36:09-08  |Portal| Unhandled Error
	Traceback (most recent call last):
	  File "C:\muddev\evenv\Lib\site-packages\twisted\python\log.py", line 101, in callWithLogger
	    return callWithContext({"system": lp}, func, *args, **kw)
	  File "C:\muddev\evenv\Lib\site-packages\twisted\python\log.py", line 85, in callWithContext
	    return context.call({ILogContext: newCtx}, func, *args, **kw)
	  File "C:\muddev\evenv\Lib\site-packages\twisted\python\context.py", line 118, in callWithContext
	    return self.currentContext().callWithContext(ctx, func, *args, **kw)
	  File "C:\muddev\evenv\Lib\site-packages\twisted\python\context.py", line 83, in callWithContext
	    return func(*args, **kw)
	--- <exception caught here> ---
	  File "C:\muddev\evenv\Lib\site-packages\twisted\internet\selectreactor.py", line 149, in _doReadOrWrite
	    why = getattr(selectable, method)()
	  File "C:\muddev\evenv\Lib\site-packages\twisted\internet\tcp.py", line 247, in doRead
	    return self._dataReceived(data)
	  File "C:\muddev\evenv\Lib\site-packages\twisted\internet\tcp.py", line 252, in _dataReceived
	    rval = self.protocol.dataReceived(data)
	  File "C:\muddev\evenv\Lib\site-packages\twisted\protocols\basic.py", line 554, in dataReceived
	    why = self.rawDataReceived(data)
	  File "C:\muddev\evenv\Lib\site-packages\twisted\web\http.py", line 706, in rawDataReceived
	    self.handleResponseEnd()
	  File "C:\muddev\evenv\Lib\site-packages\twisted\web\proxy.py", line 82, in handleResponseEnd
	    self.father.finish()
	  File "C:\muddev\evenv\Lib\site-packages\twisted\web\server.py", line 279, in finish
	    return http.Request.finish(self)
	  File "C:\muddev\evenv\Lib\site-packages\twisted\web\http.py", line 1132, in finish
	    "Request.finish called on a request after its connection was lost; "
	builtins.RuntimeError: Request.finish called on a request after its connection was lost; use Request.notifyFinish to keep track of this.
	
22-01-05 19:36:09-08  |Portal| Unhandled Error
	Traceback (most recent call last):
	  File "C:\muddev\evenv\Lib\site-packages\twisted\python\log.py", line 101, in callWithLogger
	    return callWithContext({"system": lp}, func, *args, **kw)
	  File "C:\muddev\evenv\Lib\site-packages\twisted\python\log.py", line 85, in callWithContext
	    return context.call({ILogContext: newCtx}, func, *args, **kw)
	  File "C:\muddev\evenv\Lib\site-packages\twisted\python\context.py", line 118, in callWithContext
	    return self.currentContext().callWithContext(ctx, func, *args, **kw)
	  File "C:\muddev\evenv\Lib\site-packages\twisted\python\context.py", line 83, in callWithContext
	    return func(*args, **kw)
	--- <exception caught here> ---
	  File "C:\muddev\evenv\Lib\site-packages\twisted\internet\selectreactor.py", line 149, in _doReadOrWrite
	    why = getattr(selectable, method)()
	  File "C:\muddev\evenv\Lib\site-packages\twisted\internet\tcp.py", line 247, in doRead
	    return self._dataReceived(data)
	  File "C:\muddev\evenv\Lib\site-packages\twisted\internet\tcp.py", line 252, in _dataReceived
	    rval = self.protocol.dataReceived(data)
	  File "C:\muddev\evenv\Lib\site-packages\twisted\protocols\basic.py", line 554, in dataReceived
	    why = self.rawDataReceived(data)
	  File "C:\muddev\evenv\Lib\site-packages\twisted\web\http.py", line 706, in rawDataReceived
	    self.handleResponseEnd()
	  File "C:\muddev\evenv\Lib\site-packages\twisted\web\proxy.py", line 82, in handleResponseEnd
	    self.father.finish()
	  File "C:\muddev\evenv\Lib\site-packages\twisted\web\server.py", line 279, in finish
	    return http.Request.finish(self)
	  File "C:\muddev\evenv\Lib\site-packages\twisted\web\http.py", line 1132, in finish
	    "Request.finish called on a request after its connection was lost; "
	builtins.RuntimeError: Request.finish called on a request after its connection was lost; use Request.notifyFinish to keep track of this.
	
22-01-05 19:36:09-08  |Portal| Unhandled Error
	Traceback (most recent call last):
	  File "C:\muddev\evenv\Lib\site-packages\twisted\python\log.py", line 101, in callWithLogger
	    return callWithContext({"system": lp}, func, *args, **kw)
	  File "C:\muddev\evenv\Lib\site-packages\twisted\python\log.py", line 85, in callWithContext
	    return context.call({ILogContext: newCtx}, func, *args, **kw)
	  File "C:\muddev\evenv\Lib\site-packages\twisted\python\context.py", line 118, in callWithContext
	    return self.currentContext().callWithContext(ctx, func, *args, **kw)
	  File "C:\muddev\evenv\Lib\site-packages\twisted\python\context.py", line 83, in callWithContext
	    return func(*args, **kw)
	--- <exception caught here> ---
	  File "C:\muddev\evenv\Lib\site-packages\twisted\internet\selectreactor.py", line 149, in _doReadOrWrite
	    why = getattr(selectable, method)()
	  File "C:\muddev\evenv\Lib\site-packages\twisted\internet\tcp.py", line 247, in doRead
	    return self._dataReceived(data)
	  File "C:\muddev\evenv\Lib\site-packages\twisted\internet\tcp.py", line 252, in _dataReceived
	    rval = self.protocol.dataReceived(data)
	  File "C:\muddev\evenv\Lib\site-packages\twisted\protocols\basic.py", line 554, in dataReceived
	    why = self.rawDataReceived(data)
	  File "C:\muddev\evenv\Lib\site-packages\twisted\web\http.py", line 706, in rawDataReceived
	    self.handleResponseEnd()
	  File "C:\muddev\evenv\Lib\site-packages\twisted\web\proxy.py", line 82, in handleResponseEnd
	    self.father.finish()
	  File "C:\muddev\evenv\Lib\site-packages\twisted\web\server.py", line 279, in finish
	    return http.Request.finish(self)
	  File "C:\muddev\evenv\Lib\site-packages\twisted\web\http.py", line 1132, in finish
	    "Request.finish called on a request after its connection was lost; "
	builtins.RuntimeError: Request.finish called on a request after its connection was lost; use Request.notifyFinish to keep track of this.
	
22-01-05 19:36:09-08  |Portal| Unhandled Error
	Traceback (most recent call last):
	  File "C:\muddev\evenv\Lib\site-packages\twisted\python\log.py", line 101, in callWithLogger
	    return callWithContext({"system": lp}, func, *args, **kw)
	  File "C:\muddev\evenv\Lib\site-packages\twisted\python\log.py", line 85, in callWithContext
	    return context.call({ILogContext: newCtx}, func, *args, **kw)
	  File "C:\muddev\evenv\Lib\site-packages\twisted\python\context.py", line 118, in callWithContext
	    return self.currentContext().callWithContext(ctx, func, *args, **kw)
	  File "C:\muddev\evenv\Lib\site-packages\twisted\python\context.py", line 83, in callWithContext
	    return func(*args, **kw)
	--- <exception caught here> ---
	  File "C:\muddev\evenv\Lib\site-packages\twisted\internet\selectreactor.py", line 149, in _doReadOrWrite
	    why = getattr(selectable, method)()
	  File "C:\muddev\evenv\Lib\site-packages\twisted\internet\tcp.py", line 247, in doRead
	    return self._dataReceived(data)
	  File "C:\muddev\evenv\Lib\site-packages\twisted\internet\tcp.py", line 252, in _dataReceived
	    rval = self.protocol.dataReceived(data)
	  File "C:\muddev\evenv\Lib\site-packages\twisted\protocols\basic.py", line 554, in dataReceived
	    why = self.rawDataReceived(data)
	  File "C:\muddev\evenv\Lib\site-packages\twisted\web\http.py", line 706, in rawDataReceived
	    self.handleResponseEnd()
	  File "C:\muddev\evenv\Lib\site-packages\twisted\web\proxy.py", line 82, in handleResponseEnd
	    self.father.finish()
	  File "C:\muddev\evenv\Lib\site-packages\twisted\web\server.py", line 279, in finish
	    return http.Request.finish(self)
	  File "C:\muddev\evenv\Lib\site-packages\twisted\web\http.py", line 1132, in finish
	    "Request.finish called on a request after its connection was lost; "
	builtins.RuntimeError: Request.finish called on a request after its connection was lost; use Request.notifyFinish to keep track of this.
	
22-01-05 19:36:09-08  |Portal| Unhandled Error
	Traceback (most recent call last):
	  File "C:\muddev\evenv\Lib\site-packages\twisted\python\log.py", line 101, in callWithLogger
	    return callWithContext({"system": lp}, func, *args, **kw)
	  File "C:\muddev\evenv\Lib\site-packages\twisted\python\log.py", line 85, in callWithContext
	    return context.call({ILogContext: newCtx}, func, *args, **kw)
	  File "C:\muddev\evenv\Lib\site-packages\twisted\python\context.py", line 118, in callWithContext
	    return self.currentContext().callWithContext(ctx, func, *args, **kw)
	  File "C:\muddev\evenv\Lib\site-packages\twisted\python\context.py", line 83, in callWithContext
	    return func(*args, **kw)
	--- <exception caught here> ---
	  File "C:\muddev\evenv\Lib\site-packages\twisted\internet\selectreactor.py", line 149, in _doReadOrWrite
	    why = getattr(selectable, method)()
	  File "C:\muddev\evenv\Lib\site-packages\twisted\internet\tcp.py", line 247, in doRead
	    return self._dataReceived(data)
	  File "C:\muddev\evenv\Lib\site-packages\twisted\internet\tcp.py", line 252, in _dataReceived
	    rval = self.protocol.dataReceived(data)
	  File "C:\muddev\evenv\Lib\site-packages\twisted\protocols\basic.py", line 554, in dataReceived
	    why = self.rawDataReceived(data)
	  File "C:\muddev\evenv\Lib\site-packages\twisted\web\http.py", line 706, in rawDataReceived
	    self.handleResponseEnd()
	  File "C:\muddev\evenv\Lib\site-packages\twisted\web\proxy.py", line 82, in handleResponseEnd
	    self.father.finish()
	  File "C:\muddev\evenv\Lib\site-packages\twisted\web\server.py", line 279, in finish
	    return http.Request.finish(self)
	  File "C:\muddev\evenv\Lib\site-packages\twisted\web\http.py", line 1132, in finish
	    "Request.finish called on a request after its connection was lost; "
	builtins.RuntimeError: Request.finish called on a request after its connection was lost; use Request.notifyFinish to keep track of this.
	
22-01-05 19:36:09-08  |Portal| Unhandled Error
	Traceback (most recent call last):
	  File "C:\muddev\evenv\Lib\site-packages\twisted\python\log.py", line 101, in callWithLogger
	    return callWithContext({"system": lp}, func, *args, **kw)
	  File "C:\muddev\evenv\Lib\site-packages\twisted\python\log.py", line 85, in callWithContext
	    return context.call({ILogContext: newCtx}, func, *args, **kw)
	  File "C:\muddev\evenv\Lib\site-packages\twisted\python\context.py", line 118, in callWithContext
	    return self.currentContext().callWithContext(ctx, func, *args, **kw)
	  File "C:\muddev\evenv\Lib\site-packages\twisted\python\context.py", line 83, in callWithContext
	    return func(*args, **kw)
	--- <exception caught here> ---
	  File "C:\muddev\evenv\Lib\site-packages\twisted\internet\selectreactor.py", line 149, in _doReadOrWrite
	    why = getattr(selectable, method)()
	  File "C:\muddev\evenv\Lib\site-packages\twisted\internet\tcp.py", line 247, in doRead
	    return self._dataReceived(data)
	  File "C:\muddev\evenv\Lib\site-packages\twisted\internet\tcp.py", line 252, in _dataReceived
	    rval = self.protocol.dataReceived(data)
	  File "C:\muddev\evenv\Lib\site-packages\twisted\protocols\basic.py", line 554, in dataReceived
	    why = self.rawDataReceived(data)
	  File "C:\muddev\evenv\Lib\site-packages\twisted\web\http.py", line 706, in rawDataReceived
	    self.handleResponseEnd()
	  File "C:\muddev\evenv\Lib\site-packages\twisted\web\proxy.py", line 82, in handleResponseEnd
	    self.father.finish()
	  File "C:\muddev\evenv\Lib\site-packages\twisted\web\server.py", line 279, in finish
	    return http.Request.finish(self)
	  File "C:\muddev\evenv\Lib\site-packages\twisted\web\http.py", line 1132, in finish
	    "Request.finish called on a request after its connection was lost; "
	builtins.RuntimeError: Request.finish called on a request after its connection was lost; use Request.notifyFinish to keep track of this.
	
22-01-05 19:36:09-08  |Portal| Unhandled Error
	Traceback (most recent call last):
	  File "C:\muddev\evenv\Lib\site-packages\twisted\python\log.py", line 101, in callWithLogger
	    return callWithContext({"system": lp}, func, *args, **kw)
	  File "C:\muddev\evenv\Lib\site-packages\twisted\python\log.py", line 85, in callWithContext
	    return context.call({ILogContext: newCtx}, func, *args, **kw)
	  File "C:\muddev\evenv\Lib\site-packages\twisted\python\context.py", line 118, in callWithContext
	    return self.currentContext().callWithContext(ctx, func, *args, **kw)
	  File "C:\muddev\evenv\Lib\site-packages\twisted\python\context.py", line 83, in callWithContext
	    return func(*args, **kw)
	--- <exception caught here> ---
	  File "C:\muddev\evenv\Lib\site-packages\twisted\internet\selectreactor.py", line 149, in _doReadOrWrite
	    why = getattr(selectable, method)()
	  File "C:\muddev\evenv\Lib\site-packages\twisted\internet\tcp.py", line 247, in doRead
	    return self._dataReceived(data)
	  File "C:\muddev\evenv\Lib\site-packages\twisted\internet\tcp.py", line 252, in _dataReceived
	    rval = self.protocol.dataReceived(data)
	  File "C:\muddev\evenv\Lib\site-packages\twisted\protocols\basic.py", line 554, in dataReceived
	    why = self.rawDataReceived(data)
	  File "C:\muddev\evenv\Lib\site-packages\twisted\web\http.py", line 706, in rawDataReceived
	    self.handleResponseEnd()
	  File "C:\muddev\evenv\Lib\site-packages\twisted\web\proxy.py", line 82, in handleResponseEnd
	    self.father.finish()
	  File "C:\muddev\evenv\Lib\site-packages\twisted\web\server.py", line 279, in finish
	    return http.Request.finish(self)
	  File "C:\muddev\evenv\Lib\site-packages\twisted\web\http.py", line 1132, in finish
	    "Request.finish called on a request after its connection was lost; "
	builtins.RuntimeError: Request.finish called on a request after its connection was lost; use Request.notifyFinish to keep track of this.
	
22-01-05 19:36:09-08  |Portal| Unhandled Error
	Traceback (most recent call last):
	  File "C:\muddev\evenv\Lib\site-packages\twisted\python\log.py", line 101, in callWithLogger
	    return callWithContext({"system": lp}, func, *args, **kw)
	  File "C:\muddev\evenv\Lib\site-packages\twisted\python\log.py", line 85, in callWithContext
	    return context.call({ILogContext: newCtx}, func, *args, **kw)
	  File "C:\muddev\evenv\Lib\site-packages\twisted\python\context.py", line 118, in callWithContext
	    return self.currentContext().callWithContext(ctx, func, *args, **kw)
	  File "C:\muddev\evenv\Lib\site-packages\twisted\python\context.py", line 83, in callWithContext
	    return func(*args, **kw)
	--- <exception caught here> ---
	  File "C:\muddev\evenv\Lib\site-packages\twisted\internet\selectreactor.py", line 149, in _doReadOrWrite
	    why = getattr(selectable, method)()
	  File "C:\muddev\evenv\Lib\site-packages\twisted\internet\tcp.py", line 247, in doRead
	    return self._dataReceived(data)
	  File "C:\muddev\evenv\Lib\site-packages\twisted\internet\tcp.py", line 252, in _dataReceived
	    rval = self.protocol.dataReceived(data)
	  File "C:\muddev\evenv\Lib\site-packages\twisted\protocols\basic.py", line 554, in dataReceived
	    why = self.rawDataReceived(data)
	  File "C:\muddev\evenv\Lib\site-packages\twisted\web\http.py", line 706, in rawDataReceived
	    self.handleResponseEnd()
	  File "C:\muddev\evenv\Lib\site-packages\twisted\web\proxy.py", line 82, in handleResponseEnd
	    self.father.finish()
	  File "C:\muddev\evenv\Lib\site-packages\twisted\web\server.py", line 279, in finish
	    return http.Request.finish(self)
	  File "C:\muddev\evenv\Lib\site-packages\twisted\web\http.py", line 1132, in finish
	    "Request.finish called on a request after its connection was lost; "
	builtins.RuntimeError: Request.finish called on a request after its connection was lost; use Request.notifyFinish to keep track of this.
	
22-01-05 19:36:09-08  |Portal| Unhandled Error
	Traceback (most recent call last):
	  File "C:\muddev\evenv\Lib\site-packages\twisted\python\log.py", line 101, in callWithLogger
	    return callWithContext({"system": lp}, func, *args, **kw)
	  File "C:\muddev\evenv\Lib\site-packages\twisted\python\log.py", line 85, in callWithContext
	    return context.call({ILogContext: newCtx}, func, *args, **kw)
	  File "C:\muddev\evenv\Lib\site-packages\twisted\python\context.py", line 118, in callWithContext
	    return self.currentContext().callWithContext(ctx, func, *args, **kw)
	  File "C:\muddev\evenv\Lib\site-packages\twisted\python\context.py", line 83, in callWithContext
	    return func(*args, **kw)
	--- <exception caught here> ---
	  File "C:\muddev\evenv\Lib\site-packages\twisted\internet\selectreactor.py", line 149, in _doReadOrWrite
	    why = getattr(selectable, method)()
	  File "C:\muddev\evenv\Lib\site-packages\twisted\internet\tcp.py", line 247, in doRead
	    return self._dataReceived(data)
	  File "C:\muddev\evenv\Lib\site-packages\twisted\internet\tcp.py", line 252, in _dataReceived
	    rval = self.protocol.dataReceived(data)
	  File "C:\muddev\evenv\Lib\site-packages\twisted\protocols\basic.py", line 554, in dataReceived
	    why = self.rawDataReceived(data)
	  File "C:\muddev\evenv\Lib\site-packages\twisted\web\http.py", line 706, in rawDataReceived
	    self.handleResponseEnd()
	  File "C:\muddev\evenv\Lib\site-packages\twisted\web\proxy.py", line 82, in handleResponseEnd
	    self.father.finish()
	  File "C:\muddev\evenv\Lib\site-packages\twisted\web\server.py", line 279, in finish
	    return http.Request.finish(self)
	  File "C:\muddev\evenv\Lib\site-packages\twisted\web\http.py", line 1132, in finish
	    "Request.finish called on a request after its connection was lost; "
	builtins.RuntimeError: Request.finish called on a request after its connection was lost; use Request.notifyFinish to keep track of this.
	
22-01-05 19:36:09-08  |Portal| Unhandled Error
	Traceback (most recent call last):
	  File "C:\muddev\evenv\Lib\site-packages\twisted\python\log.py", line 101, in callWithLogger
	    return callWithContext({"system": lp}, func, *args, **kw)
	  File "C:\muddev\evenv\Lib\site-packages\twisted\python\log.py", line 85, in callWithContext
	    return context.call({ILogContext: newCtx}, func, *args, **kw)
	  File "C:\muddev\evenv\Lib\site-packages\twisted\python\context.py", line 118, in callWithContext
	    return self.currentContext().callWithContext(ctx, func, *args, **kw)
	  File "C:\muddev\evenv\Lib\site-packages\twisted\python\context.py", line 83, in callWithContext
	    return func(*args, **kw)
	--- <exception caught here> ---
	  File "C:\muddev\evenv\Lib\site-packages\twisted\internet\selectreactor.py", line 149, in _doReadOrWrite
	    why = getattr(selectable, method)()
	  File "C:\muddev\evenv\Lib\site-packages\twisted\internet\tcp.py", line 247, in doRead
	    return self._dataReceived(data)
	  File "C:\muddev\evenv\Lib\site-packages\twisted\internet\tcp.py", line 252, in _dataReceived
	    rval = self.protocol.dataReceived(data)
	  File "C:\muddev\evenv\Lib\site-packages\twisted\protocols\basic.py", line 554, in dataReceived
	    why = self.rawDataReceived(data)
	  File "C:\muddev\evenv\Lib\site-packages\twisted\web\http.py", line 706, in rawDataReceived
	    self.handleResponseEnd()
	  File "C:\muddev\evenv\Lib\site-packages\twisted\web\proxy.py", line 82, in handleResponseEnd
	    self.father.finish()
	  File "C:\muddev\evenv\Lib\site-packages\twisted\web\server.py", line 279, in finish
	    return http.Request.finish(self)
	  File "C:\muddev\evenv\Lib\site-packages\twisted\web\http.py", line 1132, in finish
	    "Request.finish called on a request after its connection was lost; "
	builtins.RuntimeError: Request.finish called on a request after its connection was lost; use Request.notifyFinish to keep track of this.
	
22-01-05 19:36:09-08  |Portal| Unhandled Error
	Traceback (most recent call last):
	  File "C:\muddev\evenv\Lib\site-packages\twisted\python\log.py", line 101, in callWithLogger
	    return callWithContext({"system": lp}, func, *args, **kw)
	  File "C:\muddev\evenv\Lib\site-packages\twisted\python\log.py", line 85, in callWithContext
	    return context.call({ILogContext: newCtx}, func, *args, **kw)
	  File "C:\muddev\evenv\Lib\site-packages\twisted\python\context.py", line 118, in callWithContext
	    return self.currentContext().callWithContext(ctx, func, *args, **kw)
	  File "C:\muddev\evenv\Lib\site-packages\twisted\python\context.py", line 83, in callWithContext
	    return func(*args, **kw)
	--- <exception caught here> ---
	  File "C:\muddev\evenv\Lib\site-packages\twisted\internet\selectreactor.py", line 149, in _doReadOrWrite
	    why = getattr(selectable, method)()
	  File "C:\muddev\evenv\Lib\site-packages\twisted\internet\tcp.py", line 247, in doRead
	    return self._dataReceived(data)
	  File "C:\muddev\evenv\Lib\site-packages\twisted\internet\tcp.py", line 252, in _dataReceived
	    rval = self.protocol.dataReceived(data)
	  File "C:\muddev\evenv\Lib\site-packages\twisted\protocols\basic.py", line 554, in dataReceived
	    why = self.rawDataReceived(data)
	  File "C:\muddev\evenv\Lib\site-packages\twisted\web\http.py", line 706, in rawDataReceived
	    self.handleResponseEnd()
	  File "C:\muddev\evenv\Lib\site-packages\twisted\web\proxy.py", line 82, in handleResponseEnd
	    self.father.finish()
	  File "C:\muddev\evenv\Lib\site-packages\twisted\web\server.py", line 279, in finish
	    return http.Request.finish(self)
	  File "C:\muddev\evenv\Lib\site-packages\twisted\web\http.py", line 1132, in finish
	    "Request.finish called on a request after its connection was lost; "
	builtins.RuntimeError: Request.finish called on a request after its connection was lost; use Request.notifyFinish to keep track of this.
	
22-01-05 19:36:09-08  |Portal| Unhandled Error
	Traceback (most recent call last):
	  File "C:\muddev\evenv\Lib\site-packages\twisted\python\log.py", line 101, in callWithLogger
	    return callWithContext({"system": lp}, func, *args, **kw)
	  File "C:\muddev\evenv\Lib\site-packages\twisted\python\log.py", line 85, in callWithContext
	    return context.call({ILogContext: newCtx}, func, *args, **kw)
	  File "C:\muddev\evenv\Lib\site-packages\twisted\python\context.py", line 118, in callWithContext
	    return self.currentContext().callWithContext(ctx, func, *args, **kw)
	  File "C:\muddev\evenv\Lib\site-packages\twisted\python\context.py", line 83, in callWithContext
	    return func(*args, **kw)
	--- <exception caught here> ---
	  File "C:\muddev\evenv\Lib\site-packages\twisted\internet\selectreactor.py", line 149, in _doReadOrWrite
	    why = getattr(selectable, method)()
	  File "C:\muddev\evenv\Lib\site-packages\twisted\internet\tcp.py", line 247, in doRead
	    return self._dataReceived(data)
	  File "C:\muddev\evenv\Lib\site-packages\twisted\internet\tcp.py", line 252, in _dataReceived
	    rval = self.protocol.dataReceived(data)
	  File "C:\muddev\evenv\Lib\site-packages\twisted\protocols\basic.py", line 554, in dataReceived
	    why = self.rawDataReceived(data)
	  File "C:\muddev\evenv\Lib\site-packages\twisted\web\http.py", line 706, in rawDataReceived
	    self.handleResponseEnd()
	  File "C:\muddev\evenv\Lib\site-packages\twisted\web\proxy.py", line 82, in handleResponseEnd
	    self.father.finish()
	  File "C:\muddev\evenv\Lib\site-packages\twisted\web\server.py", line 279, in finish
	    return http.Request.finish(self)
	  File "C:\muddev\evenv\Lib\site-packages\twisted\web\http.py", line 1132, in finish
	    "Request.finish called on a request after its connection was lost; "
	builtins.RuntimeError: Request.finish called on a request after its connection was lost; use Request.notifyFinish to keep track of this.
	
22-01-05 19:36:09-08  |Portal| Unhandled Error
	Traceback (most recent call last):
	  File "C:\muddev\evenv\Lib\site-packages\twisted\python\log.py", line 101, in callWithLogger
	    return callWithContext({"system": lp}, func, *args, **kw)
	  File "C:\muddev\evenv\Lib\site-packages\twisted\python\log.py", line 85, in callWithContext
	    return context.call({ILogContext: newCtx}, func, *args, **kw)
	  File "C:\muddev\evenv\Lib\site-packages\twisted\python\context.py", line 118, in callWithContext
	    return self.currentContext().callWithContext(ctx, func, *args, **kw)
	  File "C:\muddev\evenv\Lib\site-packages\twisted\python\context.py", line 83, in callWithContext
	    return func(*args, **kw)
	--- <exception caught here> ---
	  File "C:\muddev\evenv\Lib\site-packages\twisted\internet\selectreactor.py", line 149, in _doReadOrWrite
	    why = getattr(selectable, method)()
	  File "C:\muddev\evenv\Lib\site-packages\twisted\internet\tcp.py", line 247, in doRead
	    return self._dataReceived(data)
	  File "C:\muddev\evenv\Lib\site-packages\twisted\internet\tcp.py", line 252, in _dataReceived
	    rval = self.protocol.dataReceived(data)
	  File "C:\muddev\evenv\Lib\site-packages\twisted\protocols\basic.py", line 554, in dataReceived
	    why = self.rawDataReceived(data)
	  File "C:\muddev\evenv\Lib\site-packages\twisted\web\http.py", line 706, in rawDataReceived
	    self.handleResponseEnd()
	  File "C:\muddev\evenv\Lib\site-packages\twisted\web\proxy.py", line 82, in handleResponseEnd
	    self.father.finish()
	  File "C:\muddev\evenv\Lib\site-packages\twisted\web\server.py", line 279, in finish
	    return http.Request.finish(self)
	  File "C:\muddev\evenv\Lib\site-packages\twisted\web\http.py", line 1132, in finish
	    "Request.finish called on a request after its connection was lost; "
	builtins.RuntimeError: Request.finish called on a request after its connection was lost; use Request.notifyFinish to keep track of this.
	
22-01-05 19:36:09-08  |Portal| Unhandled Error
	Traceback (most recent call last):
	  File "C:\muddev\evenv\Lib\site-packages\twisted\python\log.py", line 101, in callWithLogger
	    return callWithContext({"system": lp}, func, *args, **kw)
	  File "C:\muddev\evenv\Lib\site-packages\twisted\python\log.py", line 85, in callWithContext
	    return context.call({ILogContext: newCtx}, func, *args, **kw)
	  File "C:\muddev\evenv\Lib\site-packages\twisted\python\context.py", line 118, in callWithContext
	    return self.currentContext().callWithContext(ctx, func, *args, **kw)
	  File "C:\muddev\evenv\Lib\site-packages\twisted\python\context.py", line 83, in callWithContext
	    return func(*args, **kw)
	--- <exception caught here> ---
	  File "C:\muddev\evenv\Lib\site-packages\twisted\internet\selectreactor.py", line 149, in _doReadOrWrite
	    why = getattr(selectable, method)()
	  File "C:\muddev\evenv\Lib\site-packages\twisted\internet\tcp.py", line 247, in doRead
	    return self._dataReceived(data)
	  File "C:\muddev\evenv\Lib\site-packages\twisted\internet\tcp.py", line 252, in _dataReceived
	    rval = self.protocol.dataReceived(data)
	  File "C:\muddev\evenv\Lib\site-packages\twisted\protocols\basic.py", line 554, in dataReceived
	    why = self.rawDataReceived(data)
	  File "C:\muddev\evenv\Lib\site-packages\twisted\web\http.py", line 706, in rawDataReceived
	    self.handleResponseEnd()
	  File "C:\muddev\evenv\Lib\site-packages\twisted\web\proxy.py", line 82, in handleResponseEnd
	    self.father.finish()
	  File "C:\muddev\evenv\Lib\site-packages\twisted\web\server.py", line 279, in finish
	    return http.Request.finish(self)
	  File "C:\muddev\evenv\Lib\site-packages\twisted\web\http.py", line 1132, in finish
	    "Request.finish called on a request after its connection was lost; "
	builtins.RuntimeError: Request.finish called on a request after its connection was lost; use Request.notifyFinish to keep track of this.
	
22-01-05 19:38:58-08  |Portal| Portal starting server ... 
22-01-05 19:46:30-08  |Portal| Portal starting server ... 
22-01-05 21:58:33-08  |Portal| (TCP Port 4001 Closed)
22-01-05 21:58:33-08  |Portal| (TCP Port 4000 Closed)
22-01-05 21:58:33-08  |Portal| (TCP Port 4002 Closed)
22-01-05 21:58:33-08  |Portal| (TCP Port 4006 Closed)
22-01-05 21:58:33-08  |Portal| Main loop terminated.
22-01-05 21:58:33-08  |Portal| Server Shut Down.
22-01-05 21:58:33-08  |Portal| Server Shut Down.
22-01-06 15:58:47-08  |Portal| Loading c:\muddev\evennia\evennia\server\portal\portal.py...
22-01-06 15:58:48-08  |Portal| Loaded.
22-01-06 15:58:48-08  |Portal| twistd 21.7.0 (c:\muddev\evenv\scripts\python.exe 3.7.0) starting up.
22-01-06 15:58:48-08  |Portal| reactor class: twisted.internet.selectreactor.SelectReactor.
22-01-06 15:58:48-08  |Portal| AMP starting on 4006
22-01-06 15:58:48-08  |Portal| Telnet starting on 4000
22-01-06 15:58:48-08  |Portal| Websocket starting on 4002
22-01-06 15:58:48-08  |Portal| Webserver-proxy starting on 4001
22-01-06 15:58:48-08  |Portal| Portal starting server ... 
22-01-06 15:58:50-08  |Portal| [EE] AMP Error from AdminPortal2Server: Traceback (most recent call last):
22-01-06 15:58:50-08  |Portal| [EE] Failure: builtins.Exception: No module named 'typeclasses.buffticker' (error logged on other side)
22-01-06 15:58:50-08  |Portal| [EE]  No module named 'typeclasses.buffticker' (error logged on other side)
22-01-06 15:58:53-08  |Portal| Unhandled Error
	Traceback (most recent call last):
	  File "C:\muddev\evenv\Lib\site-packages\twisted\python\log.py", line 101, in callWithLogger
	    return callWithContext({"system": lp}, func, *args, **kw)
	  File "C:\muddev\evenv\Lib\site-packages\twisted\python\log.py", line 85, in callWithContext
	    return context.call({ILogContext: newCtx}, func, *args, **kw)
	  File "C:\muddev\evenv\Lib\site-packages\twisted\python\context.py", line 118, in callWithContext
	    return self.currentContext().callWithContext(ctx, func, *args, **kw)
	  File "C:\muddev\evenv\Lib\site-packages\twisted\python\context.py", line 83, in callWithContext
	    return func(*args, **kw)
	--- <exception caught here> ---
	  File "C:\muddev\evenv\Lib\site-packages\twisted\internet\selectreactor.py", line 149, in _doReadOrWrite
	    why = getattr(selectable, method)()
	  File "C:\muddev\evenv\Lib\site-packages\twisted\internet\tcp.py", line 247, in doRead
	    return self._dataReceived(data)
	  File "C:\muddev\evenv\Lib\site-packages\twisted\internet\tcp.py", line 252, in _dataReceived
	    rval = self.protocol.dataReceived(data)
	  File "C:\muddev\evenv\Lib\site-packages\twisted\protocols\basic.py", line 554, in dataReceived
	    why = self.rawDataReceived(data)
	  File "C:\muddev\evenv\Lib\site-packages\twisted\web\http.py", line 706, in rawDataReceived
	    self.handleResponseEnd()
	  File "C:\muddev\evenv\Lib\site-packages\twisted\web\proxy.py", line 82, in handleResponseEnd
	    self.father.finish()
	  File "C:\muddev\evenv\Lib\site-packages\twisted\web\server.py", line 279, in finish
	    return http.Request.finish(self)
	  File "C:\muddev\evenv\Lib\site-packages\twisted\web\http.py", line 1132, in finish
	    "Request.finish called on a request after its connection was lost; "
	builtins.RuntimeError: Request.finish called on a request after its connection was lost; use Request.notifyFinish to keep track of this.
	
22-01-06 15:58:53-08  |Portal| Unhandled Error
	Traceback (most recent call last):
	  File "C:\muddev\evenv\Lib\site-packages\twisted\python\log.py", line 101, in callWithLogger
	    return callWithContext({"system": lp}, func, *args, **kw)
	  File "C:\muddev\evenv\Lib\site-packages\twisted\python\log.py", line 85, in callWithContext
	    return context.call({ILogContext: newCtx}, func, *args, **kw)
	  File "C:\muddev\evenv\Lib\site-packages\twisted\python\context.py", line 118, in callWithContext
	    return self.currentContext().callWithContext(ctx, func, *args, **kw)
	  File "C:\muddev\evenv\Lib\site-packages\twisted\python\context.py", line 83, in callWithContext
	    return func(*args, **kw)
	--- <exception caught here> ---
	  File "C:\muddev\evenv\Lib\site-packages\twisted\internet\selectreactor.py", line 149, in _doReadOrWrite
	    why = getattr(selectable, method)()
	  File "C:\muddev\evenv\Lib\site-packages\twisted\internet\tcp.py", line 247, in doRead
	    return self._dataReceived(data)
	  File "C:\muddev\evenv\Lib\site-packages\twisted\internet\tcp.py", line 252, in _dataReceived
	    rval = self.protocol.dataReceived(data)
	  File "C:\muddev\evenv\Lib\site-packages\twisted\protocols\basic.py", line 554, in dataReceived
	    why = self.rawDataReceived(data)
	  File "C:\muddev\evenv\Lib\site-packages\twisted\web\http.py", line 706, in rawDataReceived
	    self.handleResponseEnd()
	  File "C:\muddev\evenv\Lib\site-packages\twisted\web\proxy.py", line 82, in handleResponseEnd
	    self.father.finish()
	  File "C:\muddev\evenv\Lib\site-packages\twisted\web\server.py", line 279, in finish
	    return http.Request.finish(self)
	  File "C:\muddev\evenv\Lib\site-packages\twisted\web\http.py", line 1132, in finish
	    "Request.finish called on a request after its connection was lost; "
	builtins.RuntimeError: Request.finish called on a request after its connection was lost; use Request.notifyFinish to keep track of this.
	
22-01-06 15:58:53-08  |Portal| Unhandled Error
	Traceback (most recent call last):
	  File "C:\muddev\evenv\Lib\site-packages\twisted\python\log.py", line 101, in callWithLogger
	    return callWithContext({"system": lp}, func, *args, **kw)
	  File "C:\muddev\evenv\Lib\site-packages\twisted\python\log.py", line 85, in callWithContext
	    return context.call({ILogContext: newCtx}, func, *args, **kw)
	  File "C:\muddev\evenv\Lib\site-packages\twisted\python\context.py", line 118, in callWithContext
	    return self.currentContext().callWithContext(ctx, func, *args, **kw)
	  File "C:\muddev\evenv\Lib\site-packages\twisted\python\context.py", line 83, in callWithContext
	    return func(*args, **kw)
	--- <exception caught here> ---
	  File "C:\muddev\evenv\Lib\site-packages\twisted\internet\selectreactor.py", line 149, in _doReadOrWrite
	    why = getattr(selectable, method)()
	  File "C:\muddev\evenv\Lib\site-packages\twisted\internet\tcp.py", line 247, in doRead
	    return self._dataReceived(data)
	  File "C:\muddev\evenv\Lib\site-packages\twisted\internet\tcp.py", line 252, in _dataReceived
	    rval = self.protocol.dataReceived(data)
	  File "C:\muddev\evenv\Lib\site-packages\twisted\protocols\basic.py", line 554, in dataReceived
	    why = self.rawDataReceived(data)
	  File "C:\muddev\evenv\Lib\site-packages\twisted\web\http.py", line 706, in rawDataReceived
	    self.handleResponseEnd()
	  File "C:\muddev\evenv\Lib\site-packages\twisted\web\proxy.py", line 82, in handleResponseEnd
	    self.father.finish()
	  File "C:\muddev\evenv\Lib\site-packages\twisted\web\server.py", line 279, in finish
	    return http.Request.finish(self)
	  File "C:\muddev\evenv\Lib\site-packages\twisted\web\http.py", line 1132, in finish
	    "Request.finish called on a request after its connection was lost; "
	builtins.RuntimeError: Request.finish called on a request after its connection was lost; use Request.notifyFinish to keep track of this.
	
22-01-06 15:58:53-08  |Portal| Unhandled Error
	Traceback (most recent call last):
	  File "C:\muddev\evenv\Lib\site-packages\twisted\python\log.py", line 101, in callWithLogger
	    return callWithContext({"system": lp}, func, *args, **kw)
	  File "C:\muddev\evenv\Lib\site-packages\twisted\python\log.py", line 85, in callWithContext
	    return context.call({ILogContext: newCtx}, func, *args, **kw)
	  File "C:\muddev\evenv\Lib\site-packages\twisted\python\context.py", line 118, in callWithContext
	    return self.currentContext().callWithContext(ctx, func, *args, **kw)
	  File "C:\muddev\evenv\Lib\site-packages\twisted\python\context.py", line 83, in callWithContext
	    return func(*args, **kw)
	--- <exception caught here> ---
	  File "C:\muddev\evenv\Lib\site-packages\twisted\internet\selectreactor.py", line 149, in _doReadOrWrite
	    why = getattr(selectable, method)()
	  File "C:\muddev\evenv\Lib\site-packages\twisted\internet\tcp.py", line 247, in doRead
	    return self._dataReceived(data)
	  File "C:\muddev\evenv\Lib\site-packages\twisted\internet\tcp.py", line 252, in _dataReceived
	    rval = self.protocol.dataReceived(data)
	  File "C:\muddev\evenv\Lib\site-packages\twisted\protocols\basic.py", line 554, in dataReceived
	    why = self.rawDataReceived(data)
	  File "C:\muddev\evenv\Lib\site-packages\twisted\web\http.py", line 706, in rawDataReceived
	    self.handleResponseEnd()
	  File "C:\muddev\evenv\Lib\site-packages\twisted\web\proxy.py", line 82, in handleResponseEnd
	    self.father.finish()
	  File "C:\muddev\evenv\Lib\site-packages\twisted\web\server.py", line 279, in finish
	    return http.Request.finish(self)
	  File "C:\muddev\evenv\Lib\site-packages\twisted\web\http.py", line 1132, in finish
	    "Request.finish called on a request after its connection was lost; "
	builtins.RuntimeError: Request.finish called on a request after its connection was lost; use Request.notifyFinish to keep track of this.
	
22-01-06 15:58:53-08  |Portal| Unhandled Error
	Traceback (most recent call last):
	  File "C:\muddev\evenv\Lib\site-packages\twisted\python\log.py", line 101, in callWithLogger
	    return callWithContext({"system": lp}, func, *args, **kw)
	  File "C:\muddev\evenv\Lib\site-packages\twisted\python\log.py", line 85, in callWithContext
	    return context.call({ILogContext: newCtx}, func, *args, **kw)
	  File "C:\muddev\evenv\Lib\site-packages\twisted\python\context.py", line 118, in callWithContext
	    return self.currentContext().callWithContext(ctx, func, *args, **kw)
	  File "C:\muddev\evenv\Lib\site-packages\twisted\python\context.py", line 83, in callWithContext
	    return func(*args, **kw)
	--- <exception caught here> ---
	  File "C:\muddev\evenv\Lib\site-packages\twisted\internet\selectreactor.py", line 149, in _doReadOrWrite
	    why = getattr(selectable, method)()
	  File "C:\muddev\evenv\Lib\site-packages\twisted\internet\tcp.py", line 247, in doRead
	    return self._dataReceived(data)
	  File "C:\muddev\evenv\Lib\site-packages\twisted\internet\tcp.py", line 252, in _dataReceived
	    rval = self.protocol.dataReceived(data)
	  File "C:\muddev\evenv\Lib\site-packages\twisted\protocols\basic.py", line 554, in dataReceived
	    why = self.rawDataReceived(data)
	  File "C:\muddev\evenv\Lib\site-packages\twisted\web\http.py", line 706, in rawDataReceived
	    self.handleResponseEnd()
	  File "C:\muddev\evenv\Lib\site-packages\twisted\web\proxy.py", line 82, in handleResponseEnd
	    self.father.finish()
	  File "C:\muddev\evenv\Lib\site-packages\twisted\web\server.py", line 279, in finish
	    return http.Request.finish(self)
	  File "C:\muddev\evenv\Lib\site-packages\twisted\web\http.py", line 1132, in finish
	    "Request.finish called on a request after its connection was lost; "
	builtins.RuntimeError: Request.finish called on a request after its connection was lost; use Request.notifyFinish to keep track of this.
	
22-01-06 15:58:53-08  |Portal| Unhandled Error
	Traceback (most recent call last):
	  File "C:\muddev\evenv\Lib\site-packages\twisted\python\log.py", line 101, in callWithLogger
	    return callWithContext({"system": lp}, func, *args, **kw)
	  File "C:\muddev\evenv\Lib\site-packages\twisted\python\log.py", line 85, in callWithContext
	    return context.call({ILogContext: newCtx}, func, *args, **kw)
	  File "C:\muddev\evenv\Lib\site-packages\twisted\python\context.py", line 118, in callWithContext
	    return self.currentContext().callWithContext(ctx, func, *args, **kw)
	  File "C:\muddev\evenv\Lib\site-packages\twisted\python\context.py", line 83, in callWithContext
	    return func(*args, **kw)
	--- <exception caught here> ---
	  File "C:\muddev\evenv\Lib\site-packages\twisted\internet\selectreactor.py", line 149, in _doReadOrWrite
	    why = getattr(selectable, method)()
	  File "C:\muddev\evenv\Lib\site-packages\twisted\internet\tcp.py", line 247, in doRead
	    return self._dataReceived(data)
	  File "C:\muddev\evenv\Lib\site-packages\twisted\internet\tcp.py", line 252, in _dataReceived
	    rval = self.protocol.dataReceived(data)
	  File "C:\muddev\evenv\Lib\site-packages\twisted\protocols\basic.py", line 554, in dataReceived
	    why = self.rawDataReceived(data)
	  File "C:\muddev\evenv\Lib\site-packages\twisted\web\http.py", line 706, in rawDataReceived
	    self.handleResponseEnd()
	  File "C:\muddev\evenv\Lib\site-packages\twisted\web\proxy.py", line 82, in handleResponseEnd
	    self.father.finish()
	  File "C:\muddev\evenv\Lib\site-packages\twisted\web\server.py", line 279, in finish
	    return http.Request.finish(self)
	  File "C:\muddev\evenv\Lib\site-packages\twisted\web\http.py", line 1132, in finish
	    "Request.finish called on a request after its connection was lost; "
	builtins.RuntimeError: Request.finish called on a request after its connection was lost; use Request.notifyFinish to keep track of this.
	
22-01-06 15:58:53-08  |Portal| Unhandled Error
	Traceback (most recent call last):
	  File "C:\muddev\evenv\Lib\site-packages\twisted\python\log.py", line 101, in callWithLogger
	    return callWithContext({"system": lp}, func, *args, **kw)
	  File "C:\muddev\evenv\Lib\site-packages\twisted\python\log.py", line 85, in callWithContext
	    return context.call({ILogContext: newCtx}, func, *args, **kw)
	  File "C:\muddev\evenv\Lib\site-packages\twisted\python\context.py", line 118, in callWithContext
	    return self.currentContext().callWithContext(ctx, func, *args, **kw)
	  File "C:\muddev\evenv\Lib\site-packages\twisted\python\context.py", line 83, in callWithContext
	    return func(*args, **kw)
	--- <exception caught here> ---
	  File "C:\muddev\evenv\Lib\site-packages\twisted\internet\selectreactor.py", line 149, in _doReadOrWrite
	    why = getattr(selectable, method)()
	  File "C:\muddev\evenv\Lib\site-packages\twisted\internet\tcp.py", line 247, in doRead
	    return self._dataReceived(data)
	  File "C:\muddev\evenv\Lib\site-packages\twisted\internet\tcp.py", line 252, in _dataReceived
	    rval = self.protocol.dataReceived(data)
	  File "C:\muddev\evenv\Lib\site-packages\twisted\protocols\basic.py", line 554, in dataReceived
	    why = self.rawDataReceived(data)
	  File "C:\muddev\evenv\Lib\site-packages\twisted\web\http.py", line 706, in rawDataReceived
	    self.handleResponseEnd()
	  File "C:\muddev\evenv\Lib\site-packages\twisted\web\proxy.py", line 82, in handleResponseEnd
	    self.father.finish()
	  File "C:\muddev\evenv\Lib\site-packages\twisted\web\server.py", line 279, in finish
	    return http.Request.finish(self)
	  File "C:\muddev\evenv\Lib\site-packages\twisted\web\http.py", line 1132, in finish
	    "Request.finish called on a request after its connection was lost; "
	builtins.RuntimeError: Request.finish called on a request after its connection was lost; use Request.notifyFinish to keep track of this.
	
22-01-06 15:58:53-08  |Portal| Unhandled Error
	Traceback (most recent call last):
	  File "C:\muddev\evenv\Lib\site-packages\twisted\python\log.py", line 101, in callWithLogger
	    return callWithContext({"system": lp}, func, *args, **kw)
	  File "C:\muddev\evenv\Lib\site-packages\twisted\python\log.py", line 85, in callWithContext
	    return context.call({ILogContext: newCtx}, func, *args, **kw)
	  File "C:\muddev\evenv\Lib\site-packages\twisted\python\context.py", line 118, in callWithContext
	    return self.currentContext().callWithContext(ctx, func, *args, **kw)
	  File "C:\muddev\evenv\Lib\site-packages\twisted\python\context.py", line 83, in callWithContext
	    return func(*args, **kw)
	--- <exception caught here> ---
	  File "C:\muddev\evenv\Lib\site-packages\twisted\internet\selectreactor.py", line 149, in _doReadOrWrite
	    why = getattr(selectable, method)()
	  File "C:\muddev\evenv\Lib\site-packages\twisted\internet\tcp.py", line 247, in doRead
	    return self._dataReceived(data)
	  File "C:\muddev\evenv\Lib\site-packages\twisted\internet\tcp.py", line 252, in _dataReceived
	    rval = self.protocol.dataReceived(data)
	  File "C:\muddev\evenv\Lib\site-packages\twisted\protocols\basic.py", line 554, in dataReceived
	    why = self.rawDataReceived(data)
	  File "C:\muddev\evenv\Lib\site-packages\twisted\web\http.py", line 706, in rawDataReceived
	    self.handleResponseEnd()
	  File "C:\muddev\evenv\Lib\site-packages\twisted\web\proxy.py", line 82, in handleResponseEnd
	    self.father.finish()
	  File "C:\muddev\evenv\Lib\site-packages\twisted\web\server.py", line 279, in finish
	    return http.Request.finish(self)
	  File "C:\muddev\evenv\Lib\site-packages\twisted\web\http.py", line 1132, in finish
	    "Request.finish called on a request after its connection was lost; "
	builtins.RuntimeError: Request.finish called on a request after its connection was lost; use Request.notifyFinish to keep track of this.
	
22-01-06 15:58:53-08  |Portal| Unhandled Error
	Traceback (most recent call last):
	  File "C:\muddev\evenv\Lib\site-packages\twisted\python\log.py", line 101, in callWithLogger
	    return callWithContext({"system": lp}, func, *args, **kw)
	  File "C:\muddev\evenv\Lib\site-packages\twisted\python\log.py", line 85, in callWithContext
	    return context.call({ILogContext: newCtx}, func, *args, **kw)
	  File "C:\muddev\evenv\Lib\site-packages\twisted\python\context.py", line 118, in callWithContext
	    return self.currentContext().callWithContext(ctx, func, *args, **kw)
	  File "C:\muddev\evenv\Lib\site-packages\twisted\python\context.py", line 83, in callWithContext
	    return func(*args, **kw)
	--- <exception caught here> ---
	  File "C:\muddev\evenv\Lib\site-packages\twisted\internet\selectreactor.py", line 149, in _doReadOrWrite
	    why = getattr(selectable, method)()
	  File "C:\muddev\evenv\Lib\site-packages\twisted\internet\tcp.py", line 247, in doRead
	    return self._dataReceived(data)
	  File "C:\muddev\evenv\Lib\site-packages\twisted\internet\tcp.py", line 252, in _dataReceived
	    rval = self.protocol.dataReceived(data)
	  File "C:\muddev\evenv\Lib\site-packages\twisted\protocols\basic.py", line 554, in dataReceived
	    why = self.rawDataReceived(data)
	  File "C:\muddev\evenv\Lib\site-packages\twisted\web\http.py", line 706, in rawDataReceived
	    self.handleResponseEnd()
	  File "C:\muddev\evenv\Lib\site-packages\twisted\web\proxy.py", line 82, in handleResponseEnd
	    self.father.finish()
	  File "C:\muddev\evenv\Lib\site-packages\twisted\web\server.py", line 279, in finish
	    return http.Request.finish(self)
	  File "C:\muddev\evenv\Lib\site-packages\twisted\web\http.py", line 1132, in finish
	    "Request.finish called on a request after its connection was lost; "
	builtins.RuntimeError: Request.finish called on a request after its connection was lost; use Request.notifyFinish to keep track of this.
	
22-01-06 15:58:53-08  |Portal| Unhandled Error
	Traceback (most recent call last):
	  File "C:\muddev\evenv\Lib\site-packages\twisted\python\log.py", line 101, in callWithLogger
	    return callWithContext({"system": lp}, func, *args, **kw)
	  File "C:\muddev\evenv\Lib\site-packages\twisted\python\log.py", line 85, in callWithContext
	    return context.call({ILogContext: newCtx}, func, *args, **kw)
	  File "C:\muddev\evenv\Lib\site-packages\twisted\python\context.py", line 118, in callWithContext
	    return self.currentContext().callWithContext(ctx, func, *args, **kw)
	  File "C:\muddev\evenv\Lib\site-packages\twisted\python\context.py", line 83, in callWithContext
	    return func(*args, **kw)
	--- <exception caught here> ---
	  File "C:\muddev\evenv\Lib\site-packages\twisted\internet\selectreactor.py", line 149, in _doReadOrWrite
	    why = getattr(selectable, method)()
	  File "C:\muddev\evenv\Lib\site-packages\twisted\internet\tcp.py", line 247, in doRead
	    return self._dataReceived(data)
	  File "C:\muddev\evenv\Lib\site-packages\twisted\internet\tcp.py", line 252, in _dataReceived
	    rval = self.protocol.dataReceived(data)
	  File "C:\muddev\evenv\Lib\site-packages\twisted\protocols\basic.py", line 554, in dataReceived
	    why = self.rawDataReceived(data)
	  File "C:\muddev\evenv\Lib\site-packages\twisted\web\http.py", line 706, in rawDataReceived
	    self.handleResponseEnd()
	  File "C:\muddev\evenv\Lib\site-packages\twisted\web\proxy.py", line 82, in handleResponseEnd
	    self.father.finish()
	  File "C:\muddev\evenv\Lib\site-packages\twisted\web\server.py", line 279, in finish
	    return http.Request.finish(self)
	  File "C:\muddev\evenv\Lib\site-packages\twisted\web\http.py", line 1132, in finish
	    "Request.finish called on a request after its connection was lost; "
	builtins.RuntimeError: Request.finish called on a request after its connection was lost; use Request.notifyFinish to keep track of this.
	
22-01-06 15:58:53-08  |Portal| Unhandled Error
	Traceback (most recent call last):
	  File "C:\muddev\evenv\Lib\site-packages\twisted\python\log.py", line 101, in callWithLogger
	    return callWithContext({"system": lp}, func, *args, **kw)
	  File "C:\muddev\evenv\Lib\site-packages\twisted\python\log.py", line 85, in callWithContext
	    return context.call({ILogContext: newCtx}, func, *args, **kw)
	  File "C:\muddev\evenv\Lib\site-packages\twisted\python\context.py", line 118, in callWithContext
	    return self.currentContext().callWithContext(ctx, func, *args, **kw)
	  File "C:\muddev\evenv\Lib\site-packages\twisted\python\context.py", line 83, in callWithContext
	    return func(*args, **kw)
	--- <exception caught here> ---
	  File "C:\muddev\evenv\Lib\site-packages\twisted\internet\selectreactor.py", line 149, in _doReadOrWrite
	    why = getattr(selectable, method)()
	  File "C:\muddev\evenv\Lib\site-packages\twisted\internet\tcp.py", line 247, in doRead
	    return self._dataReceived(data)
	  File "C:\muddev\evenv\Lib\site-packages\twisted\internet\tcp.py", line 252, in _dataReceived
	    rval = self.protocol.dataReceived(data)
	  File "C:\muddev\evenv\Lib\site-packages\twisted\protocols\basic.py", line 554, in dataReceived
	    why = self.rawDataReceived(data)
	  File "C:\muddev\evenv\Lib\site-packages\twisted\web\http.py", line 706, in rawDataReceived
	    self.handleResponseEnd()
	  File "C:\muddev\evenv\Lib\site-packages\twisted\web\proxy.py", line 82, in handleResponseEnd
	    self.father.finish()
	  File "C:\muddev\evenv\Lib\site-packages\twisted\web\server.py", line 279, in finish
	    return http.Request.finish(self)
	  File "C:\muddev\evenv\Lib\site-packages\twisted\web\http.py", line 1132, in finish
	    "Request.finish called on a request after its connection was lost; "
	builtins.RuntimeError: Request.finish called on a request after its connection was lost; use Request.notifyFinish to keep track of this.
	
22-01-06 15:58:53-08  |Portal| Unhandled Error
	Traceback (most recent call last):
	  File "C:\muddev\evenv\Lib\site-packages\twisted\python\log.py", line 101, in callWithLogger
	    return callWithContext({"system": lp}, func, *args, **kw)
	  File "C:\muddev\evenv\Lib\site-packages\twisted\python\log.py", line 85, in callWithContext
	    return context.call({ILogContext: newCtx}, func, *args, **kw)
	  File "C:\muddev\evenv\Lib\site-packages\twisted\python\context.py", line 118, in callWithContext
	    return self.currentContext().callWithContext(ctx, func, *args, **kw)
	  File "C:\muddev\evenv\Lib\site-packages\twisted\python\context.py", line 83, in callWithContext
	    return func(*args, **kw)
	--- <exception caught here> ---
	  File "C:\muddev\evenv\Lib\site-packages\twisted\internet\selectreactor.py", line 149, in _doReadOrWrite
	    why = getattr(selectable, method)()
	  File "C:\muddev\evenv\Lib\site-packages\twisted\internet\tcp.py", line 247, in doRead
	    return self._dataReceived(data)
	  File "C:\muddev\evenv\Lib\site-packages\twisted\internet\tcp.py", line 252, in _dataReceived
	    rval = self.protocol.dataReceived(data)
	  File "C:\muddev\evenv\Lib\site-packages\twisted\protocols\basic.py", line 554, in dataReceived
	    why = self.rawDataReceived(data)
	  File "C:\muddev\evenv\Lib\site-packages\twisted\web\http.py", line 706, in rawDataReceived
	    self.handleResponseEnd()
	  File "C:\muddev\evenv\Lib\site-packages\twisted\web\proxy.py", line 82, in handleResponseEnd
	    self.father.finish()
	  File "C:\muddev\evenv\Lib\site-packages\twisted\web\server.py", line 279, in finish
	    return http.Request.finish(self)
	  File "C:\muddev\evenv\Lib\site-packages\twisted\web\http.py", line 1132, in finish
	    "Request.finish called on a request after its connection was lost; "
	builtins.RuntimeError: Request.finish called on a request after its connection was lost; use Request.notifyFinish to keep track of this.
	
22-01-06 15:58:53-08  |Portal| Unhandled Error
	Traceback (most recent call last):
	  File "C:\muddev\evenv\Lib\site-packages\twisted\python\log.py", line 101, in callWithLogger
	    return callWithContext({"system": lp}, func, *args, **kw)
	  File "C:\muddev\evenv\Lib\site-packages\twisted\python\log.py", line 85, in callWithContext
	    return context.call({ILogContext: newCtx}, func, *args, **kw)
	  File "C:\muddev\evenv\Lib\site-packages\twisted\python\context.py", line 118, in callWithContext
	    return self.currentContext().callWithContext(ctx, func, *args, **kw)
	  File "C:\muddev\evenv\Lib\site-packages\twisted\python\context.py", line 83, in callWithContext
	    return func(*args, **kw)
	--- <exception caught here> ---
	  File "C:\muddev\evenv\Lib\site-packages\twisted\internet\selectreactor.py", line 149, in _doReadOrWrite
	    why = getattr(selectable, method)()
	  File "C:\muddev\evenv\Lib\site-packages\twisted\internet\tcp.py", line 247, in doRead
	    return self._dataReceived(data)
	  File "C:\muddev\evenv\Lib\site-packages\twisted\internet\tcp.py", line 252, in _dataReceived
	    rval = self.protocol.dataReceived(data)
	  File "C:\muddev\evenv\Lib\site-packages\twisted\protocols\basic.py", line 554, in dataReceived
	    why = self.rawDataReceived(data)
	  File "C:\muddev\evenv\Lib\site-packages\twisted\web\http.py", line 706, in rawDataReceived
	    self.handleResponseEnd()
	  File "C:\muddev\evenv\Lib\site-packages\twisted\web\proxy.py", line 82, in handleResponseEnd
	    self.father.finish()
	  File "C:\muddev\evenv\Lib\site-packages\twisted\web\server.py", line 279, in finish
	    return http.Request.finish(self)
	  File "C:\muddev\evenv\Lib\site-packages\twisted\web\http.py", line 1132, in finish
	    "Request.finish called on a request after its connection was lost; "
	builtins.RuntimeError: Request.finish called on a request after its connection was lost; use Request.notifyFinish to keep track of this.
	
22-01-06 15:58:53-08  |Portal| Unhandled Error
	Traceback (most recent call last):
	  File "C:\muddev\evenv\Lib\site-packages\twisted\python\log.py", line 101, in callWithLogger
	    return callWithContext({"system": lp}, func, *args, **kw)
	  File "C:\muddev\evenv\Lib\site-packages\twisted\python\log.py", line 85, in callWithContext
	    return context.call({ILogContext: newCtx}, func, *args, **kw)
	  File "C:\muddev\evenv\Lib\site-packages\twisted\python\context.py", line 118, in callWithContext
	    return self.currentContext().callWithContext(ctx, func, *args, **kw)
	  File "C:\muddev\evenv\Lib\site-packages\twisted\python\context.py", line 83, in callWithContext
	    return func(*args, **kw)
	--- <exception caught here> ---
	  File "C:\muddev\evenv\Lib\site-packages\twisted\internet\selectreactor.py", line 149, in _doReadOrWrite
	    why = getattr(selectable, method)()
	  File "C:\muddev\evenv\Lib\site-packages\twisted\internet\tcp.py", line 247, in doRead
	    return self._dataReceived(data)
	  File "C:\muddev\evenv\Lib\site-packages\twisted\internet\tcp.py", line 252, in _dataReceived
	    rval = self.protocol.dataReceived(data)
	  File "C:\muddev\evenv\Lib\site-packages\twisted\protocols\basic.py", line 554, in dataReceived
	    why = self.rawDataReceived(data)
	  File "C:\muddev\evenv\Lib\site-packages\twisted\web\http.py", line 706, in rawDataReceived
	    self.handleResponseEnd()
	  File "C:\muddev\evenv\Lib\site-packages\twisted\web\proxy.py", line 82, in handleResponseEnd
	    self.father.finish()
	  File "C:\muddev\evenv\Lib\site-packages\twisted\web\server.py", line 279, in finish
	    return http.Request.finish(self)
	  File "C:\muddev\evenv\Lib\site-packages\twisted\web\http.py", line 1132, in finish
	    "Request.finish called on a request after its connection was lost; "
	builtins.RuntimeError: Request.finish called on a request after its connection was lost; use Request.notifyFinish to keep track of this.
	
22-01-06 15:58:53-08  |Portal| Unhandled Error
	Traceback (most recent call last):
	  File "C:\muddev\evenv\Lib\site-packages\twisted\python\log.py", line 101, in callWithLogger
	    return callWithContext({"system": lp}, func, *args, **kw)
	  File "C:\muddev\evenv\Lib\site-packages\twisted\python\log.py", line 85, in callWithContext
	    return context.call({ILogContext: newCtx}, func, *args, **kw)
	  File "C:\muddev\evenv\Lib\site-packages\twisted\python\context.py", line 118, in callWithContext
	    return self.currentContext().callWithContext(ctx, func, *args, **kw)
	  File "C:\muddev\evenv\Lib\site-packages\twisted\python\context.py", line 83, in callWithContext
	    return func(*args, **kw)
	--- <exception caught here> ---
	  File "C:\muddev\evenv\Lib\site-packages\twisted\internet\selectreactor.py", line 149, in _doReadOrWrite
	    why = getattr(selectable, method)()
	  File "C:\muddev\evenv\Lib\site-packages\twisted\internet\tcp.py", line 247, in doRead
	    return self._dataReceived(data)
	  File "C:\muddev\evenv\Lib\site-packages\twisted\internet\tcp.py", line 252, in _dataReceived
	    rval = self.protocol.dataReceived(data)
	  File "C:\muddev\evenv\Lib\site-packages\twisted\protocols\basic.py", line 554, in dataReceived
	    why = self.rawDataReceived(data)
	  File "C:\muddev\evenv\Lib\site-packages\twisted\web\http.py", line 706, in rawDataReceived
	    self.handleResponseEnd()
	  File "C:\muddev\evenv\Lib\site-packages\twisted\web\proxy.py", line 82, in handleResponseEnd
	    self.father.finish()
	  File "C:\muddev\evenv\Lib\site-packages\twisted\web\server.py", line 279, in finish
	    return http.Request.finish(self)
	  File "C:\muddev\evenv\Lib\site-packages\twisted\web\http.py", line 1132, in finish
	    "Request.finish called on a request after its connection was lost; "
	builtins.RuntimeError: Request.finish called on a request after its connection was lost; use Request.notifyFinish to keep track of this.
	
22-01-06 15:58:53-08  |Portal| Unhandled Error
	Traceback (most recent call last):
	  File "C:\muddev\evenv\Lib\site-packages\twisted\python\log.py", line 101, in callWithLogger
	    return callWithContext({"system": lp}, func, *args, **kw)
	  File "C:\muddev\evenv\Lib\site-packages\twisted\python\log.py", line 85, in callWithContext
	    return context.call({ILogContext: newCtx}, func, *args, **kw)
	  File "C:\muddev\evenv\Lib\site-packages\twisted\python\context.py", line 118, in callWithContext
	    return self.currentContext().callWithContext(ctx, func, *args, **kw)
	  File "C:\muddev\evenv\Lib\site-packages\twisted\python\context.py", line 83, in callWithContext
	    return func(*args, **kw)
	--- <exception caught here> ---
	  File "C:\muddev\evenv\Lib\site-packages\twisted\internet\selectreactor.py", line 149, in _doReadOrWrite
	    why = getattr(selectable, method)()
	  File "C:\muddev\evenv\Lib\site-packages\twisted\internet\tcp.py", line 247, in doRead
	    return self._dataReceived(data)
	  File "C:\muddev\evenv\Lib\site-packages\twisted\internet\tcp.py", line 252, in _dataReceived
	    rval = self.protocol.dataReceived(data)
	  File "C:\muddev\evenv\Lib\site-packages\twisted\protocols\basic.py", line 554, in dataReceived
	    why = self.rawDataReceived(data)
	  File "C:\muddev\evenv\Lib\site-packages\twisted\web\http.py", line 706, in rawDataReceived
	    self.handleResponseEnd()
	  File "C:\muddev\evenv\Lib\site-packages\twisted\web\proxy.py", line 82, in handleResponseEnd
	    self.father.finish()
	  File "C:\muddev\evenv\Lib\site-packages\twisted\web\server.py", line 279, in finish
	    return http.Request.finish(self)
	  File "C:\muddev\evenv\Lib\site-packages\twisted\web\http.py", line 1132, in finish
	    "Request.finish called on a request after its connection was lost; "
	builtins.RuntimeError: Request.finish called on a request after its connection was lost; use Request.notifyFinish to keep track of this.
	
22-01-06 15:58:53-08  |Portal| Unhandled Error
	Traceback (most recent call last):
	  File "C:\muddev\evenv\Lib\site-packages\twisted\python\log.py", line 101, in callWithLogger
	    return callWithContext({"system": lp}, func, *args, **kw)
	  File "C:\muddev\evenv\Lib\site-packages\twisted\python\log.py", line 85, in callWithContext
	    return context.call({ILogContext: newCtx}, func, *args, **kw)
	  File "C:\muddev\evenv\Lib\site-packages\twisted\python\context.py", line 118, in callWithContext
	    return self.currentContext().callWithContext(ctx, func, *args, **kw)
	  File "C:\muddev\evenv\Lib\site-packages\twisted\python\context.py", line 83, in callWithContext
	    return func(*args, **kw)
	--- <exception caught here> ---
	  File "C:\muddev\evenv\Lib\site-packages\twisted\internet\selectreactor.py", line 149, in _doReadOrWrite
	    why = getattr(selectable, method)()
	  File "C:\muddev\evenv\Lib\site-packages\twisted\internet\tcp.py", line 247, in doRead
	    return self._dataReceived(data)
	  File "C:\muddev\evenv\Lib\site-packages\twisted\internet\tcp.py", line 252, in _dataReceived
	    rval = self.protocol.dataReceived(data)
	  File "C:\muddev\evenv\Lib\site-packages\twisted\protocols\basic.py", line 554, in dataReceived
	    why = self.rawDataReceived(data)
	  File "C:\muddev\evenv\Lib\site-packages\twisted\web\http.py", line 706, in rawDataReceived
	    self.handleResponseEnd()
	  File "C:\muddev\evenv\Lib\site-packages\twisted\web\proxy.py", line 82, in handleResponseEnd
	    self.father.finish()
	  File "C:\muddev\evenv\Lib\site-packages\twisted\web\server.py", line 279, in finish
	    return http.Request.finish(self)
	  File "C:\muddev\evenv\Lib\site-packages\twisted\web\http.py", line 1132, in finish
	    "Request.finish called on a request after its connection was lost; "
	builtins.RuntimeError: Request.finish called on a request after its connection was lost; use Request.notifyFinish to keep track of this.
	
22-01-06 15:58:53-08  |Portal| Unhandled Error
	Traceback (most recent call last):
	  File "C:\muddev\evenv\Lib\site-packages\twisted\python\log.py", line 101, in callWithLogger
	    return callWithContext({"system": lp}, func, *args, **kw)
	  File "C:\muddev\evenv\Lib\site-packages\twisted\python\log.py", line 85, in callWithContext
	    return context.call({ILogContext: newCtx}, func, *args, **kw)
	  File "C:\muddev\evenv\Lib\site-packages\twisted\python\context.py", line 118, in callWithContext
	    return self.currentContext().callWithContext(ctx, func, *args, **kw)
	  File "C:\muddev\evenv\Lib\site-packages\twisted\python\context.py", line 83, in callWithContext
	    return func(*args, **kw)
	--- <exception caught here> ---
	  File "C:\muddev\evenv\Lib\site-packages\twisted\internet\selectreactor.py", line 149, in _doReadOrWrite
	    why = getattr(selectable, method)()
	  File "C:\muddev\evenv\Lib\site-packages\twisted\internet\tcp.py", line 247, in doRead
	    return self._dataReceived(data)
	  File "C:\muddev\evenv\Lib\site-packages\twisted\internet\tcp.py", line 252, in _dataReceived
	    rval = self.protocol.dataReceived(data)
	  File "C:\muddev\evenv\Lib\site-packages\twisted\protocols\basic.py", line 554, in dataReceived
	    why = self.rawDataReceived(data)
	  File "C:\muddev\evenv\Lib\site-packages\twisted\web\http.py", line 706, in rawDataReceived
	    self.handleResponseEnd()
	  File "C:\muddev\evenv\Lib\site-packages\twisted\web\proxy.py", line 82, in handleResponseEnd
	    self.father.finish()
	  File "C:\muddev\evenv\Lib\site-packages\twisted\web\server.py", line 279, in finish
	    return http.Request.finish(self)
	  File "C:\muddev\evenv\Lib\site-packages\twisted\web\http.py", line 1132, in finish
	    "Request.finish called on a request after its connection was lost; "
	builtins.RuntimeError: Request.finish called on a request after its connection was lost; use Request.notifyFinish to keep track of this.
	
